package microjunk.trees.common.worldgentrees;

import java.util.Random;

import microjunk.trees.common.Trees;
import net.minecraft.block.Block;
import net.minecraft.world.World;
import net.minecraft.world.gen.feature.WorldGenerator;

public class WorldGenGiantTrees extends WorldGenerator
{
	public WorldGenGiantTrees()
    {
		
    }
	public boolean generate(World world, Random rand, int i, int j, int k)
	{
		int j1 = world.getBlockId(i, j - 1, k);
		if(j1 != Block.grass.blockID && j1 != Block.dirt.blockID && j1 != Trees.alphaGrass.blockID || j >= 128 - 12 - 1)
        {
        	return false;
        }
		world.setBlock(i + 0, j + 26, k + 5, Trees.giantLeaves.blockID);
		world.setBlock(i + 0, j + 26, k + 6, Trees.giantLeaves.blockID);
		world.setBlock(i + 0, j + 26, k + 7, Trees.giantLeaves.blockID);
		world.setBlock(i + 0, j + 26, k + 8, Trees.giantLeaves.blockID);
		world.setBlock(i + 1, j + 26, k + 2, Trees.giantLeaves.blockID);
		world.setBlock(i + 1, j + 26, k + 3, Trees.giantLeaves.blockID);
		world.setBlock(i + 1, j + 26, k + 5, Trees.giantLeaves.blockID);
		world.setBlock(i + 1, j + 26, k + 6, Trees.giantLeaves.blockID);
		world.setBlock(i + 1, j + 26, k + 8, Trees.giantLeaves.blockID);
		world.setBlock(i + 1, j + 26, k + 9, Trees.giantLeaves.blockID);
		world.setBlock(i + 1, j + 27, k + 5, Trees.giantLeaves.blockID);
		world.setBlock(i + 1, j + 27, k + 6, Trees.giantLeaves.blockID);
		world.setBlock(i + 1, j + 27, k + 7, Trees.giantLeaves.blockID);
		world.setBlock(i + 2, j + 18, k + 10, Trees.giantLeaves.blockID);
		world.setBlock(i + 2, j + 18, k + 11, Trees.giantLeaves.blockID);
		world.setBlock(i + 2, j + 26, k + 1, Trees.giantLeaves.blockID);
		world.setBlock(i + 2, j + 26, k + 2, Trees.giantLeaves.blockID);
		world.setBlock(i + 2, j + 26, k + 3, Trees.giantLeaves.blockID);
		world.setBlock(i + 2, j + 26, k + 4, Trees.giantLeaves.blockID);
		world.setBlock(i + 2, j + 26, k + 5, Trees.giantLeaves.blockID);
		world.setBlock(i + 2, j + 26, k + 6, Trees.giantLeaves.blockID);
		world.setBlock(i + 2, j + 26, k + 7, Trees.giantLeaves.blockID);
		world.setBlock(i + 2, j + 26, k + 8, Trees.giantLeaves.blockID);
		world.setBlock(i + 2, j + 26, k + 9, Trees.giantLeaves.blockID);
		world.setBlock(i + 2, j + 26, k + 10, Trees.giantLeaves.blockID);
		world.setBlock(i + 2, j + 27, k + 4, Trees.giantLeaves.blockID);
		world.setBlock(i + 2, j + 27, k + 5, Trees.giantLeaves.blockID);
		world.setBlock(i + 2, j + 27, k + 6, Trees.giantLeaves.blockID);
		world.setBlock(i + 2, j + 27, k + 7, Trees.giantLeaves.blockID);
		world.setBlock(i + 2, j + 27, k + 8, Trees.giantLeaves.blockID);
		world.setBlock(i + 2, j + 27, k + 9, Trees.giantLeaves.blockID);
		world.setBlock(i + 2, j + 28, k + 5, Trees.giantLeaves.blockID);
		world.setBlock(i + 2, j + 28, k + 6, Trees.giantLeaves.blockID);
		world.setBlock(i + 2, j + 28, k + 7, Trees.giantLeaves.blockID);
		world.setBlock(i + 3, j + 18, k + 7, Trees.giantLeaves.blockID);
		world.setBlock(i + 3, j + 18, k + 9, Trees.giantLeaves.blockID);
		world.setBlock(i + 3, j + 18, k + 10, Trees.giantLeaves.blockID);
		world.setBlock(i + 3, j + 18, k + 11, Trees.giantLeaves.blockID);
		world.setBlock(i + 3, j + 18, k + 12, Trees.giantLeaves.blockID);
		world.setBlock(i + 3, j + 19, k + 9, Trees.giantLeaves.blockID);
		world.setBlock(i + 3, j + 19, k + 10, Trees.giantLeaves.blockID);
		world.setBlock(i + 3, j + 19, k + 11, Trees.giantLeaves.blockID);
		world.setBlock(i + 3, j + 26, k + 1, Trees.giantLeaves.blockID);
		world.setBlock(i + 3, j + 26, k + 2, Trees.giantLeaves.blockID);
		world.setBlock(i + 3, j + 26, k + 3, Trees.giantLeaves.blockID);
		world.setBlock(i + 3, j + 26, k + 4, Trees.giantLeaves.blockID);
		world.setBlock(i + 3, j + 26, k + 5, Trees.giantLeaves.blockID);
		world.setBlock(i + 3, j + 26, k + 6, Trees.giantLeaves.blockID);
		world.setBlock(i + 3, j + 26, k + 7, Trees.giantLeaves.blockID);
		world.setBlock(i + 3, j + 26, k + 8, Trees.giantLeaves.blockID);
		world.setBlock(i + 3, j + 26, k + 9, Trees.giantLeaves.blockID);
		world.setBlock(i + 3, j + 26, k + 10, Trees.giantLeaves.blockID);
		world.setBlock(i + 3, j + 27, k + 2, Trees.giantLeaves.blockID);
		world.setBlock(i + 3, j + 27, k + 3, Trees.giantLeaves.blockID);
		world.setBlock(i + 3, j + 27, k + 4, Trees.giantLeaves.blockID);
		world.setBlock(i + 3, j + 27, k + 5, Trees.giantLeaves.blockID);
		world.setBlock(i + 3, j + 27, k + 6, Trees.giantLeaves.blockID);
		world.setBlock(i + 3, j + 27, k + 7, Trees.giantLeaves.blockID);
		world.setBlock(i + 3, j + 27, k + 9, Trees.giantLeaves.blockID);
		world.setBlock(i + 3, j + 28, k + 3, Trees.giantLeaves.blockID);
		world.setBlock(i + 3, j + 28, k + 4, Trees.giantLeaves.blockID);
		world.setBlock(i + 3, j + 28, k + 5, Trees.giantLeaves.blockID);
		world.setBlock(i + 3, j + 28, k + 7, Trees.giantLeaves.blockID);
		world.setBlock(i + 4, j + 16, k + 9, Trees.giantLeaves.blockID);
		world.setBlock(i + 4, j + 16, k + 10, Trees.giantLeaves.blockID);
		world.setBlock(i + 4, j + 18, k + 7, Trees.giantLeaves.blockID);
		world.setBlock(i + 4, j + 18, k + 8, Trees.giantLeaves.blockID);
		world.setBlock(i + 4, j + 18, k + 9, Trees.giantLeaves.blockID);
		world.setBlock(i + 4, j + 18, k + 10, Trees.giantLeaves.blockID);
		world.setBlock(i + 4, j + 18, k + 12, Trees.giantLeaves.blockID);
		world.setBlock(i + 4, j + 19, k + 8, Trees.giantLeaves.blockID);
		world.setBlock(i + 4, j + 19, k + 9, Trees.giantLeaves.blockID);
		world.setBlock(i + 4, j + 19, k + 10, Trees.giantLeaves.blockID);
		world.setBlock(i + 4, j + 19, k + 11, Trees.giantLeaves.blockID);
		world.setBlock(i + 4, j + 20, k + 10, Trees.giantLeaves.blockID);
		world.setBlock(i + 4, j + 22, k + 9, Trees.giantLeaves.blockID);
		world.setBlock(i + 4, j + 22, k + 10, Trees.giantLeaves.blockID);
		world.setBlock(i + 4, j + 26, k + 1, Trees.giantLeaves.blockID);
		world.setBlock(i + 4, j + 26, k + 2, Trees.giantLeaves.blockID);
		world.setBlock(i + 4, j + 26, k + 3, Trees.giantLeaves.blockID);
		world.setBlock(i + 4, j + 26, k + 4, Trees.giantLeaves.blockID);
		world.setBlock(i + 4, j + 26, k + 5, Trees.giantLeaves.blockID);
		world.setBlock(i + 4, j + 26, k + 6, Trees.giantLeaves.blockID);
		world.setBlock(i + 4, j + 26, k + 7, Trees.giantLeaves.blockID);
		world.setBlock(i + 4, j + 26, k + 8, Trees.giantLeaves.blockID);
		world.setBlock(i + 4, j + 26, k + 9, Trees.giantLeaves.blockID);
		world.setBlock(i + 4, j + 27, k + 2, Trees.giantLeaves.blockID);
		world.setBlock(i + 4, j + 27, k + 3, Trees.giantLeaves.blockID);
		world.setBlock(i + 4, j + 27, k + 4, Trees.giantLeaves.blockID);
		world.setBlock(i + 4, j + 27, k + 5, Trees.giantLeaves.blockID);
		world.setBlock(i + 4, j + 27, k + 6, Trees.giantLeaves.blockID);
		world.setBlock(i + 4, j + 27, k + 7, Trees.giantLeaves.blockID);
		world.setBlock(i + 4, j + 27, k + 8, Trees.giantLeaves.blockID);
		world.setBlock(i + 4, j + 27, k + 9, Trees.giantLeaves.blockID);
		world.setBlock(i + 4, j + 28, k + 3, Trees.giantLeaves.blockID);
		world.setBlock(i + 4, j + 28, k + 4, Trees.giantLeaves.blockID);
		world.setBlock(i + 4, j + 28, k + 5, Trees.giantLeaves.blockID);
		world.setBlock(i + 4, j + 28, k + 6, Trees.giantLeaves.blockID);
		world.setBlock(i + 4, j + 28, k + 7, Trees.giantLeaves.blockID);
		world.setBlock(i + 4, j + 28, k + 8, Trees.giantLeaves.blockID);
		world.setBlock(i + 5, j + 0, k + 5, Block.dirt.blockID);
		world.setBlock(i + 5, j + 0, k + 6, Block.dirt.blockID);
		world.setBlock(i + 5, j + 1, k + 5, Trees.giantLog.blockID);
		world.setBlock(i + 5, j + 1, k + 6, Trees.giantLog.blockID);
		world.setBlock(i + 5, j + 2, k + 5, Trees.giantLog.blockID);
		world.setBlock(i + 5, j + 2, k + 6, Trees.giantLog.blockID);
		world.setBlock(i + 5, j + 3, k + 5, Trees.giantLog.blockID);
		world.setBlock(i + 5, j + 3, k + 6, Trees.giantLog.blockID);
		world.setBlock(i + 5, j + 4, k + 5, Trees.giantLog.blockID);
		world.setBlock(i + 5, j + 4, k + 6, Trees.giantLog.blockID);
		world.setBlock(i + 5, j + 5, k + 5, Trees.giantLog.blockID);
		world.setBlock(i + 5, j + 5, k + 6, Trees.giantLog.blockID);
		world.setBlock(i + 5, j + 6, k + 5, Trees.giantLog.blockID);
		world.setBlock(i + 5, j + 6, k + 6, Trees.giantLog.blockID);
		world.setBlock(i + 5, j + 7, k + 5, Trees.giantLog.blockID);
		world.setBlock(i + 5, j + 7, k + 6, Trees.giantLog.blockID);
		world.setBlock(i + 5, j + 8, k + 5, Trees.giantLog.blockID);
		world.setBlock(i + 5, j + 8, k + 6, Trees.giantLog.blockID);
		world.setBlock(i + 5, j + 9, k + 5, Trees.giantLog.blockID);
		world.setBlock(i + 5, j + 9, k + 6, Trees.giantLog.blockID);
		world.setBlock(i + 5, j + 10, k + 5, Trees.giantLog.blockID);
		world.setBlock(i + 5, j + 10, k + 6, Trees.giantLog.blockID);
		world.setBlock(i + 5, j + 11, k + 5, Trees.giantLog.blockID);
		world.setBlock(i + 5, j + 11, k + 6, Trees.giantLog.blockID);
		world.setBlock(i + 5, j + 12, k + 5, Trees.giantLog.blockID);
		world.setBlock(i + 5, j + 12, k + 6, Trees.giantLog.blockID);
		world.setBlock(i + 5, j + 13, k + 5, Trees.giantLog.blockID);
		world.setBlock(i + 5, j + 13, k + 6, Trees.giantLog.blockID);
		world.setBlock(i + 5, j + 14, k + 5, Trees.giantLog.blockID);
		world.setBlock(i + 5, j + 14, k + 6, Trees.giantLog.blockID);
		world.setBlock(i + 5, j + 14, k + 8, Trees.giantLeaves.blockID);
		world.setBlock(i + 5, j + 14, k + 10, Trees.giantLeaves.blockID);
		world.setBlock(i + 5, j + 15, k + 5, Trees.giantLog.blockID);
		world.setBlock(i + 5, j + 15, k + 6, Trees.giantLog.blockID);
		world.setBlock(i + 5, j + 16, k + 5, Trees.giantLog.blockID);
		world.setBlock(i + 5, j + 16, k + 6, Trees.giantLog.blockID);
		world.setBlock(i + 5, j + 16, k + 7, Trees.giantLeaves.blockID);
		world.setBlock(i + 5, j + 16, k + 8, Trees.giantLeaves.blockID);
		world.setBlock(i + 5, j + 16, k + 9, Trees.giantLeaves.blockID);
		world.setBlock(i + 5, j + 16, k + 10, Trees.giantLeaves.blockID);
		world.setBlock(i + 5, j + 16, k + 11, Trees.giantLeaves.blockID);
		world.setBlock(i + 5, j + 17, k + 5, Trees.giantLog.blockID);
		world.setBlock(i + 5, j + 17, k + 6, Trees.giantLog.blockID);
		world.setBlock(i + 5, j + 17, k + 8, Trees.giantLeaves.blockID);
		world.setBlock(i + 5, j + 18, k + 5, Trees.giantLog.blockID);
		world.setBlock(i + 5, j + 18, k + 6, Trees.giantLog.blockID);
		world.setBlock(i + 5, j + 18, k + 7, Trees.giantLeaves.blockID);
		world.setBlock(i + 5, j + 18, k + 8, Trees.giantLog.blockID);
		world.setBlock(i + 5, j + 18, k + 9, Trees.giantLog.blockID);
		world.setBlock(i + 5, j + 18, k + 10, Trees.giantLeaves.blockID);
		world.setBlock(i + 5, j + 18, k + 11, Trees.giantLeaves.blockID);
		world.setBlock(i + 5, j + 18, k + 12, Trees.giantLeaves.blockID);
		world.setBlock(i + 5, j + 18, k + 13, Trees.giantLeaves.blockID);
		world.setBlock(i + 5, j + 19, k + 5, Trees.giantLog.blockID);
		world.setBlock(i + 5, j + 19, k + 6, Trees.giantLog.blockID);
		world.setBlock(i + 5, j + 19, k + 7, Trees.giantLeaves.blockID);
		world.setBlock(i + 5, j + 19, k + 8, Trees.giantLeaves.blockID);
		world.setBlock(i + 5, j + 19, k + 9, Trees.giantLeaves.blockID);
		world.setBlock(i + 5, j + 19, k + 10, Trees.giantLog.blockID);
		world.setBlock(i + 5, j + 19, k + 11, Trees.giantLeaves.blockID);
		world.setBlock(i + 5, j + 19, k + 12, Trees.giantLeaves.blockID);
		world.setBlock(i + 5, j + 20, k + 5, Trees.giantLog.blockID);
		world.setBlock(i + 5, j + 20, k + 6, Trees.giantLog.blockID);
		world.setBlock(i + 5, j + 20, k + 9, Trees.giantLeaves.blockID);
		world.setBlock(i + 5, j + 20, k + 10, Trees.giantLeaves.blockID);
		world.setBlock(i + 5, j + 20, k + 11, Trees.giantLeaves.blockID);
		world.setBlock(i + 5, j + 21, k + 5, Trees.giantLog.blockID);
		world.setBlock(i + 5, j + 21, k + 6, Trees.giantLog.blockID);
		world.setBlock(i + 5, j + 22, k + 5, Trees.giantLog.blockID);
		world.setBlock(i + 5, j + 22, k + 6, Trees.giantLog.blockID);
		world.setBlock(i + 5, j + 22, k + 7, Trees.giantLeaves.blockID);
		world.setBlock(i + 5, j + 22, k + 8, Trees.giantLeaves.blockID);
		world.setBlock(i + 5, j + 22, k + 9, Trees.giantLeaves.blockID);
		world.setBlock(i + 5, j + 22, k + 10, Trees.giantLeaves.blockID);
		world.setBlock(i + 5, j + 22, k + 11, Trees.giantLeaves.blockID);
		world.setBlock(i + 5, j + 22, k + 12, Trees.giantLeaves.blockID);
		world.setBlock(i + 5, j + 23, k + 5, Trees.giantLog.blockID);
		world.setBlock(i + 5, j + 23, k + 6, Trees.giantLog.blockID);
		world.setBlock(i + 5, j + 23, k + 9, Trees.giantLeaves.blockID);
		world.setBlock(i + 5, j + 23, k + 10, Trees.giantLeaves.blockID);
		world.setBlock(i + 5, j + 23, k + 11, Trees.giantLeaves.blockID);
		world.setBlock(i + 5, j + 24, k + 5, Trees.giantLog.blockID);
		world.setBlock(i + 5, j + 24, k + 6, Trees.giantLog.blockID);
		world.setBlock(i + 5, j + 25, k + 5, Trees.giantLog.blockID);
		world.setBlock(i + 5, j + 25, k + 6, Trees.giantLog.blockID);
		world.setBlock(i + 5, j + 26, k + 0, Trees.giantLeaves.blockID);
		world.setBlock(i + 5, j + 26, k + 1, Trees.giantLeaves.blockID);
		world.setBlock(i + 5, j + 26, k + 2, Trees.giantLeaves.blockID);
		world.setBlock(i + 5, j + 26, k + 3, Trees.giantLeaves.blockID);
		world.setBlock(i + 5, j + 26, k + 4, Trees.giantLeaves.blockID);
		world.setBlock(i + 5, j + 26, k + 5, Trees.giantLog.blockID);
		world.setBlock(i + 5, j + 26, k + 6, Trees.giantLog.blockID);
		world.setBlock(i + 5, j + 26, k + 7, Trees.giantLeaves.blockID);
		world.setBlock(i + 5, j + 26, k + 8, Trees.giantLeaves.blockID);
		world.setBlock(i + 5, j + 26, k + 9, Trees.giantLeaves.blockID);
		world.setBlock(i + 5, j + 26, k + 10, Trees.giantLeaves.blockID);
		world.setBlock(i + 5, j + 26, k + 11, Trees.giantLeaves.blockID);
		world.setBlock(i + 5, j + 27, k + 2, Trees.giantLeaves.blockID);
		world.setBlock(i + 5, j + 27, k + 3, Trees.giantLeaves.blockID);
		world.setBlock(i + 5, j + 27, k + 4, Trees.giantLeaves.blockID);
		world.setBlock(i + 5, j + 27, k + 5, Trees.giantLog.blockID);
		world.setBlock(i + 5, j + 27, k + 6, Trees.giantLeaves.blockID);
		world.setBlock(i + 5, j + 27, k + 7, Trees.giantLeaves.blockID);
		world.setBlock(i + 5, j + 27, k + 8, Trees.giantLeaves.blockID);
		world.setBlock(i + 5, j + 27, k + 9, Trees.giantLeaves.blockID);
		world.setBlock(i + 5, j + 27, k + 10, Trees.giantLeaves.blockID);
		world.setBlock(i + 5, j + 28, k + 3, Trees.giantLeaves.blockID);
		world.setBlock(i + 5, j + 28, k + 4, Trees.giantLeaves.blockID);
		world.setBlock(i + 5, j + 28, k + 5, Trees.giantLeaves.blockID);
		world.setBlock(i + 5, j + 28, k + 6, Trees.giantLeaves.blockID);
		world.setBlock(i + 5, j + 28, k + 7, Trees.giantLeaves.blockID);
		world.setBlock(i + 5, j + 28, k + 8, Trees.giantLeaves.blockID);
		world.setBlock(i + 5, j + 28, k + 9, Trees.giantLeaves.blockID);
		world.setBlock(i + 6, j + 0, k + 5, Block.dirt.blockID);
		world.setBlock(i + 6, j + 0, k + 6, Block.dirt.blockID);
		world.setBlock(i + 6, j + 1, k + 5, Trees.giantLog.blockID);
		world.setBlock(i + 6, j + 1, k + 6, Trees.giantLog.blockID);
		world.setBlock(i + 6, j + 2, k + 5, Trees.giantLog.blockID);
		world.setBlock(i + 6, j + 2, k + 6, Trees.giantLog.blockID);
		world.setBlock(i + 6, j + 3, k + 5, Trees.giantLog.blockID);
		world.setBlock(i + 6, j + 3, k + 6, Trees.giantLog.blockID);
		world.setBlock(i + 6, j + 4, k + 5, Trees.giantLog.blockID);
		world.setBlock(i + 6, j + 4, k + 6, Trees.giantLog.blockID);
		world.setBlock(i + 6, j + 5, k + 5, Trees.giantLog.blockID);
		world.setBlock(i + 6, j + 5, k + 6, Trees.giantLog.blockID);
		world.setBlock(i + 6, j + 6, k + 5, Trees.giantLog.blockID);
		world.setBlock(i + 6, j + 6, k + 6, Trees.giantLog.blockID);
		world.setBlock(i + 6, j + 7, k + 5, Trees.giantLog.blockID);
		world.setBlock(i + 6, j + 7, k + 6, Trees.giantLog.blockID);
		world.setBlock(i + 6, j + 8, k + 5, Trees.giantLog.blockID);
		world.setBlock(i + 6, j + 8, k + 6, Trees.giantLog.blockID);
		world.setBlock(i + 6, j + 9, k + 5, Trees.giantLog.blockID);
		world.setBlock(i + 6, j + 9, k + 6, Trees.giantLog.blockID);
		world.setBlock(i + 6, j + 10, k + 5, Trees.giantLog.blockID);
		world.setBlock(i + 6, j + 10, k + 6, Trees.giantLog.blockID);
		world.setBlock(i + 6, j + 11, k + 5, Trees.giantLog.blockID);
		world.setBlock(i + 6, j + 11, k + 6, Trees.giantLog.blockID);
		world.setBlock(i + 6, j + 12, k + 5, Trees.giantLog.blockID);
		world.setBlock(i + 6, j + 12, k + 6, Trees.giantLog.blockID);
		world.setBlock(i + 6, j + 13, k + 5, Trees.giantLog.blockID);
		world.setBlock(i + 6, j + 13, k + 6, Trees.giantLog.blockID);
		world.setBlock(i + 6, j + 14, k + 5, Trees.giantLog.blockID);
		world.setBlock(i + 6, j + 14, k + 6, Trees.giantLog.blockID);
		world.setBlock(i + 6, j + 14, k + 7, Trees.giantLeaves.blockID);
		world.setBlock(i + 6, j + 14, k + 8, Trees.giantLeaves.blockID);
		world.setBlock(i + 6, j + 14, k + 9, Trees.giantLeaves.blockID);
		world.setBlock(i + 6, j + 14, k + 10, Trees.giantLeaves.blockID);
		world.setBlock(i + 6, j + 14, k + 11, Trees.giantLeaves.blockID);
		world.setBlock(i + 6, j + 15, k + 5, Trees.giantLog.blockID);
		world.setBlock(i + 6, j + 15, k + 6, Trees.giantLog.blockID);
		world.setBlock(i + 6, j + 15, k + 8, Trees.giantLeaves.blockID);
		world.setBlock(i + 6, j + 15, k + 9, Trees.giantLeaves.blockID);
		world.setBlock(i + 6, j + 15, k + 10, Trees.giantLeaves.blockID);
		world.setBlock(i + 6, j + 16, k + 5, Trees.giantLog.blockID);
		world.setBlock(i + 6, j + 16, k + 6, Trees.giantLog.blockID);
		world.setBlock(i + 6, j + 16, k + 7, Trees.giantLeaves.blockID);
		world.setBlock(i + 6, j + 16, k + 8, Trees.giantLeaves.blockID);
		world.setBlock(i + 6, j + 16, k + 9, Trees.giantLeaves.blockID);
		world.setBlock(i + 6, j + 16, k + 10, Trees.giantLeaves.blockID);
		world.setBlock(i + 6, j + 16, k + 11, Trees.giantLeaves.blockID);
		world.setBlock(i + 6, j + 17, k + 5, Trees.giantLog.blockID);
		world.setBlock(i + 6, j + 17, k + 6, Trees.giantLog.blockID);
		world.setBlock(i + 6, j + 17, k + 7, Trees.giantLog.blockID);
		world.setBlock(i + 6, j + 17, k + 8, Trees.giantLeaves.blockID);
		world.setBlock(i + 6, j + 17, k + 10, Trees.giantLeaves.blockID);
		world.setBlock(i + 6, j + 18, k + 5, Trees.giantLog.blockID);
		world.setBlock(i + 6, j + 18, k + 6, Trees.giantLog.blockID);
		world.setBlock(i + 6, j + 18, k + 7, Trees.giantLeaves.blockID);
		world.setBlock(i + 6, j + 18, k + 8, Trees.giantLeaves.blockID);
		world.setBlock(i + 6, j + 18, k + 9, Trees.giantLeaves.blockID);
		world.setBlock(i + 6, j + 18, k + 10, Trees.giantLeaves.blockID);
		world.setBlock(i + 6, j + 18, k + 12, Trees.giantLeaves.blockID);
		world.setBlock(i + 6, j + 19, k + 5, Trees.giantLog.blockID);
		world.setBlock(i + 6, j + 19, k + 6, Trees.giantLog.blockID);
		world.setBlock(i + 6, j + 19, k + 7, Trees.giantLeaves.blockID);
		world.setBlock(i + 6, j + 19, k + 8, Trees.giantLeaves.blockID);
		world.setBlock(i + 6, j + 19, k + 9, Trees.giantLeaves.blockID);
		world.setBlock(i + 6, j + 19, k + 10, Trees.giantLeaves.blockID);
		world.setBlock(i + 6, j + 20, k + 5, Trees.giantLog.blockID);
		world.setBlock(i + 6, j + 20, k + 6, Trees.giantLog.blockID);
		world.setBlock(i + 6, j + 20, k + 8, Trees.giantLeaves.blockID);
		world.setBlock(i + 6, j + 20, k + 9, Trees.giantLeaves.blockID);
		world.setBlock(i + 6, j + 20, k + 10, Trees.giantLeaves.blockID);
		world.setBlock(i + 6, j + 21, k + 5, Trees.giantLog.blockID);
		world.setBlock(i + 6, j + 21, k + 6, Trees.giantLog.blockID);
		world.setBlock(i + 6, j + 21, k + 7, Trees.giantLog.blockID);
		world.setBlock(i + 6, j + 22, k + 5, Trees.giantLog.blockID);
		world.setBlock(i + 6, j + 22, k + 6, Trees.giantLog.blockID);
		world.setBlock(i + 6, j + 22, k + 7, Trees.giantLeaves.blockID);
		world.setBlock(i + 6, j + 22, k + 8, Trees.giantLeaves.blockID);
		world.setBlock(i + 6, j + 22, k + 9, Trees.giantLeaves.blockID);
		world.setBlock(i + 6, j + 22, k + 10, Trees.giantLeaves.blockID);
		world.setBlock(i + 6, j + 22, k + 11, Trees.giantLeaves.blockID);
		world.setBlock(i + 6, j + 22, k + 12, Trees.giantLeaves.blockID);
		world.setBlock(i + 6, j + 23, k + 5, Trees.giantLog.blockID);
		world.setBlock(i + 6, j + 23, k + 6, Trees.giantLog.blockID);
		world.setBlock(i + 6, j + 23, k + 8, Trees.giantLeaves.blockID);
		world.setBlock(i + 6, j + 23, k + 9, Trees.giantLeaves.blockID);
		world.setBlock(i + 6, j + 23, k + 10, Trees.giantLeaves.blockID);
		world.setBlock(i + 6, j + 23, k + 11, Trees.giantLeaves.blockID);
		world.setBlock(i + 6, j + 24, k + 5, Trees.giantLog.blockID);
		world.setBlock(i + 6, j + 24, k + 6, Trees.giantLog.blockID);
		world.setBlock(i + 6, j + 24, k + 10, Trees.giantLeaves.blockID);
		world.setBlock(i + 6, j + 25, k + 5, Trees.giantLog.blockID);
		world.setBlock(i + 6, j + 25, k + 6, Trees.giantLog.blockID);
		world.setBlock(i + 6, j + 26, k + 0, Trees.giantLeaves.blockID);
		world.setBlock(i + 6, j + 26, k + 2, Trees.giantLeaves.blockID);
		world.setBlock(i + 6, j + 26, k + 3, Trees.giantLeaves.blockID);
		world.setBlock(i + 6, j + 26, k + 4, Trees.giantLeaves.blockID);
		world.setBlock(i + 6, j + 26, k + 5, Trees.giantLog.blockID);
		world.setBlock(i + 6, j + 26, k + 6, Trees.giantLog.blockID);
		world.setBlock(i + 6, j + 26, k + 7, Trees.giantLeaves.blockID);
		world.setBlock(i + 6, j + 26, k + 8, Trees.giantLeaves.blockID);
		world.setBlock(i + 6, j + 26, k + 9, Trees.giantLeaves.blockID);
		world.setBlock(i + 6, j + 26, k + 10, Trees.giantLeaves.blockID);
		world.setBlock(i + 6, j + 27, k + 1, Trees.giantLeaves.blockID);
		world.setBlock(i + 6, j + 27, k + 2, Trees.giantLeaves.blockID);
		world.setBlock(i + 6, j + 27, k + 3, Trees.giantLeaves.blockID);
		world.setBlock(i + 6, j + 27, k + 4, Trees.giantLeaves.blockID);
		world.setBlock(i + 6, j + 27, k + 5, Trees.giantLeaves.blockID);
		world.setBlock(i + 6, j + 27, k + 6, Trees.giantLeaves.blockID);
		world.setBlock(i + 6, j + 27, k + 7, Trees.giantLeaves.blockID);
		world.setBlock(i + 6, j + 27, k + 8, Trees.giantLeaves.blockID);
		world.setBlock(i + 6, j + 27, k + 9, Trees.giantLeaves.blockID);
		world.setBlock(i + 6, j + 28, k + 2, Trees.giantLeaves.blockID);
		world.setBlock(i + 6, j + 28, k + 4, Trees.giantLeaves.blockID);
		world.setBlock(i + 6, j + 28, k + 5, Trees.giantLeaves.blockID);
		world.setBlock(i + 6, j + 28, k + 6, Trees.giantLeaves.blockID);
		world.setBlock(i + 6, j + 28, k + 8, Trees.giantLeaves.blockID);
		world.setBlock(i + 7, j + 13, k + 7, Trees.giantLog.blockID);
		world.setBlock(i + 7, j + 14, k + 6, Trees.giantLeaves.blockID);
		world.setBlock(i + 7, j + 14, k + 7, Trees.giantLog.blockID);
		world.setBlock(i + 7, j + 14, k + 8, Trees.giantLeaves.blockID);
		world.setBlock(i + 7, j + 14, k + 9, Trees.giantLeaves.blockID);
		world.setBlock(i + 7, j + 14, k + 10, Trees.giantLeaves.blockID);
		world.setBlock(i + 7, j + 14, k + 11, Trees.giantLeaves.blockID);
		world.setBlock(i + 7, j + 15, k + 7, Trees.giantLog.blockID);
		world.setBlock(i + 7, j + 15, k + 8, Trees.giantLeaves.blockID);
		world.setBlock(i + 7, j + 15, k + 9, Trees.giantLeaves.blockID);
		world.setBlock(i + 7, j + 16, k + 6, Trees.giantLeaves.blockID);
		world.setBlock(i + 7, j + 16, k + 7, Trees.giantLeaves.blockID);
		world.setBlock(i + 7, j + 16, k + 8, Trees.giantLog.blockID);
		world.setBlock(i + 7, j + 16, k + 9, Trees.giantLeaves.blockID);
		world.setBlock(i + 7, j + 16, k + 10, Trees.giantLeaves.blockID);
		world.setBlock(i + 7, j + 16, k + 11, Trees.giantLeaves.blockID);
		world.setBlock(i + 7, j + 16, k + 12, Trees.giantLeaves.blockID);
		world.setBlock(i + 7, j + 17, k + 6, Trees.giantLeaves.blockID);
		world.setBlock(i + 7, j + 17, k + 7, Trees.giantLeaves.blockID);
		world.setBlock(i + 7, j + 17, k + 8, Trees.giantLeaves.blockID);
		world.setBlock(i + 7, j + 17, k + 9, Trees.giantLeaves.blockID);
		world.setBlock(i + 7, j + 17, k + 10, Trees.giantLeaves.blockID);
		world.setBlock(i + 7, j + 17, k + 11, Trees.giantLeaves.blockID);
		world.setBlock(i + 7, j + 18, k + 6, Trees.giantLeaves.blockID);
		world.setBlock(i + 7, j + 18, k + 7, Trees.giantLeaves.blockID);
		world.setBlock(i + 7, j + 18, k + 8, Trees.giantLeaves.blockID);
		world.setBlock(i + 7, j + 18, k + 9, Trees.giantLeaves.blockID);
		world.setBlock(i + 7, j + 18, k + 10, Trees.giantLeaves.blockID);
		world.setBlock(i + 7, j + 18, k + 11, Trees.giantLeaves.blockID);
		world.setBlock(i + 7, j + 19, k + 7, Trees.giantLeaves.blockID);
		world.setBlock(i + 7, j + 19, k + 8, Trees.giantLeaves.blockID);
		world.setBlock(i + 7, j + 19, k + 10, Trees.giantLeaves.blockID);
		world.setBlock(i + 7, j + 22, k + 7, Trees.giantLeaves.blockID);
		world.setBlock(i + 7, j + 22, k + 8, Trees.giantLog.blockID);
		world.setBlock(i + 7, j + 22, k + 9, Trees.giantLog.blockID);
		world.setBlock(i + 7, j + 22, k + 10, Trees.giantLeaves.blockID);
		world.setBlock(i + 7, j + 22, k + 11, Trees.giantLeaves.blockID);
		world.setBlock(i + 7, j + 22, k + 12, Trees.giantLeaves.blockID);
		world.setBlock(i + 7, j + 22, k + 13, Trees.giantLeaves.blockID);
		world.setBlock(i + 7, j + 23, k + 7, Trees.giantLeaves.blockID);
		world.setBlock(i + 7, j + 23, k + 8, Trees.giantLeaves.blockID);
		world.setBlock(i + 7, j + 23, k + 9, Trees.giantLeaves.blockID);
		world.setBlock(i + 7, j + 23, k + 10, Trees.giantLeaves.blockID);
		world.setBlock(i + 7, j + 23, k + 11, Trees.giantLeaves.blockID);
		world.setBlock(i + 7, j + 23, k + 12, Trees.giantLeaves.blockID);
		world.setBlock(i + 7, j + 24, k + 8, Trees.giantLeaves.blockID);
		world.setBlock(i + 7, j + 24, k + 9, Trees.giantLeaves.blockID);
		world.setBlock(i + 7, j + 24, k + 11, Trees.giantLeaves.blockID);
		world.setBlock(i + 7, j + 26, k + 0, Trees.giantLeaves.blockID);
		world.setBlock(i + 7, j + 26, k + 1, Trees.giantLeaves.blockID);
		world.setBlock(i + 7, j + 26, k + 2, Trees.giantLeaves.blockID);
		world.setBlock(i + 7, j + 26, k + 3, Trees.giantLeaves.blockID);
		world.setBlock(i + 7, j + 26, k + 4, Trees.giantLeaves.blockID);
		world.setBlock(i + 7, j + 26, k + 5, Trees.giantLeaves.blockID);
		world.setBlock(i + 7, j + 26, k + 6, Trees.giantLeaves.blockID);
		world.setBlock(i + 7, j + 26, k + 7, Trees.giantLeaves.blockID);
		world.setBlock(i + 7, j + 26, k + 8, Trees.giantLeaves.blockID);
		world.setBlock(i + 7, j + 26, k + 9, Trees.giantLeaves.blockID);
		world.setBlock(i + 7, j + 26, k + 10, Trees.giantLeaves.blockID);
		world.setBlock(i + 7, j + 27, k + 1, Trees.giantLeaves.blockID);
		world.setBlock(i + 7, j + 27, k + 3, Trees.giantLeaves.blockID);
		world.setBlock(i + 7, j + 27, k + 4, Trees.giantLeaves.blockID);
		world.setBlock(i + 7, j + 27, k + 5, Trees.giantLeaves.blockID);
		world.setBlock(i + 7, j + 27, k + 6, Trees.giantLeaves.blockID);
		world.setBlock(i + 7, j + 27, k + 7, Trees.giantLeaves.blockID);
		world.setBlock(i + 7, j + 27, k + 8, Trees.giantLeaves.blockID);
		world.setBlock(i + 7, j + 27, k + 9, Trees.giantLeaves.blockID);
		world.setBlock(i + 7, j + 28, k + 2, Trees.giantLeaves.blockID);
		world.setBlock(i + 7, j + 28, k + 3, Trees.giantLeaves.blockID);
		world.setBlock(i + 7, j + 28, k + 4, Trees.giantLeaves.blockID);
		world.setBlock(i + 7, j + 28, k + 5, Trees.giantLeaves.blockID);
		world.setBlock(i + 7, j + 28, k + 6, Trees.giantLeaves.blockID);
		world.setBlock(i + 7, j + 28, k + 8, Trees.giantLeaves.blockID);
		world.setBlock(i + 8, j + 14, k + 5, Trees.giantLeaves.blockID);
		world.setBlock(i + 8, j + 14, k + 6, Trees.giantLeaves.blockID);
		world.setBlock(i + 8, j + 14, k + 7, Trees.giantLeaves.blockID);
		world.setBlock(i + 8, j + 14, k + 8, Trees.giantLog.blockID);
		world.setBlock(i + 8, j + 14, k + 9, Trees.giantLeaves.blockID);
		world.setBlock(i + 8, j + 14, k + 10, Trees.giantLeaves.blockID);
		world.setBlock(i + 8, j + 14, k + 11, Trees.giantLeaves.blockID);
		world.setBlock(i + 8, j + 14, k + 12, Trees.giantLeaves.blockID);
		world.setBlock(i + 8, j + 15, k + 6, Trees.giantLeaves.blockID);
		world.setBlock(i + 8, j + 15, k + 7, Trees.giantLeaves.blockID);
		world.setBlock(i + 8, j + 15, k + 8, Trees.giantLeaves.blockID);
		world.setBlock(i + 8, j + 15, k + 9, Trees.giantLeaves.blockID);
		world.setBlock(i + 8, j + 15, k + 10, Trees.giantLeaves.blockID);
		world.setBlock(i + 8, j + 16, k + 5, Trees.giantLeaves.blockID);
		world.setBlock(i + 8, j + 16, k + 7, Trees.giantLeaves.blockID);
		world.setBlock(i + 8, j + 16, k + 8, Trees.giantLeaves.blockID);
		world.setBlock(i + 8, j + 16, k + 9, Trees.giantLog.blockID);
		world.setBlock(i + 8, j + 16, k + 10, Trees.giantLeaves.blockID);
		world.setBlock(i + 8, j + 16, k + 11, Trees.giantLeaves.blockID);
		world.setBlock(i + 8, j + 17, k + 6, Trees.giantLeaves.blockID);
		world.setBlock(i + 8, j + 17, k + 8, Trees.giantLeaves.blockID);
		world.setBlock(i + 8, j + 17, k + 9, Trees.giantLog.blockID);
		world.setBlock(i + 8, j + 17, k + 10, Trees.giantLeaves.blockID);
		world.setBlock(i + 8, j + 18, k + 7, Trees.giantLeaves.blockID);
		world.setBlock(i + 8, j + 18, k + 8, Trees.giantLeaves.blockID);
		world.setBlock(i + 8, j + 18, k + 9, Trees.giantLeaves.blockID);
		world.setBlock(i + 8, j + 18, k + 11, Trees.giantLeaves.blockID);
		world.setBlock(i + 8, j + 19, k + 9, Trees.giantLeaves.blockID);
		world.setBlock(i + 8, j + 22, k + 6, Trees.giantLeaves.blockID);
		world.setBlock(i + 8, j + 22, k + 7, Trees.giantLeaves.blockID);
		world.setBlock(i + 8, j + 22, k + 8, Trees.giantLeaves.blockID);
		world.setBlock(i + 8, j + 22, k + 9, Trees.giantLeaves.blockID);
		world.setBlock(i + 8, j + 22, k + 10, Trees.giantLeaves.blockID);
		world.setBlock(i + 8, j + 22, k + 11, Trees.giantLeaves.blockID);
		world.setBlock(i + 8, j + 22, k + 12, Trees.giantLeaves.blockID);
		world.setBlock(i + 8, j + 23, k + 7, Trees.giantLeaves.blockID);
		world.setBlock(i + 8, j + 23, k + 8, Trees.giantLeaves.blockID);
		world.setBlock(i + 8, j + 23, k + 9, Trees.giantLeaves.blockID);
		world.setBlock(i + 8, j + 23, k + 10, Trees.giantLog.blockID);
		world.setBlock(i + 8, j + 23, k + 11, Trees.giantLeaves.blockID);
		world.setBlock(i + 8, j + 24, k + 8, Trees.giantLeaves.blockID);
		world.setBlock(i + 8, j + 24, k + 9, Trees.giantLeaves.blockID);
		world.setBlock(i + 8, j + 26, k + 0, Trees.giantLeaves.blockID);
		world.setBlock(i + 8, j + 26, k + 2, Trees.giantLeaves.blockID);
		world.setBlock(i + 8, j + 26, k + 3, Trees.giantLeaves.blockID);
		world.setBlock(i + 8, j + 26, k + 4, Trees.giantLeaves.blockID);
		world.setBlock(i + 8, j + 26, k + 5, Trees.giantLeaves.blockID);
		world.setBlock(i + 8, j + 26, k + 6, Trees.giantLeaves.blockID);
		world.setBlock(i + 8, j + 26, k + 7, Trees.giantLeaves.blockID);
		world.setBlock(i + 8, j + 26, k + 8, Trees.giantLeaves.blockID);
		world.setBlock(i + 8, j + 26, k + 10, Trees.giantLeaves.blockID);
		world.setBlock(i + 8, j + 27, k + 1, Trees.giantLeaves.blockID);
		world.setBlock(i + 8, j + 27, k + 2, Trees.giantLeaves.blockID);
		world.setBlock(i + 8, j + 27, k + 4, Trees.giantLeaves.blockID);
		world.setBlock(i + 8, j + 27, k + 5, Trees.giantLeaves.blockID);
		world.setBlock(i + 8, j + 27, k + 6, Trees.giantLeaves.blockID);
		world.setBlock(i + 8, j + 27, k + 7, Trees.giantLeaves.blockID);
		world.setBlock(i + 8, j + 27, k + 9, Trees.giantLeaves.blockID);
		world.setBlock(i + 8, j + 28, k + 4, Trees.giantLeaves.blockID);
		world.setBlock(i + 8, j + 28, k + 5, Trees.giantLeaves.blockID);
		world.setBlock(i + 8, j + 28, k + 6, Trees.giantLeaves.blockID);
		world.setBlock(i + 8, j + 28, k + 7, Trees.giantLeaves.blockID);
		world.setBlock(i + 9, j + 14, k + 5, Trees.giantLeaves.blockID);
		world.setBlock(i + 9, j + 14, k + 7, Trees.giantLeaves.blockID);
		world.setBlock(i + 9, j + 14, k + 8, Trees.giantLeaves.blockID);
		world.setBlock(i + 9, j + 14, k + 9, Trees.giantLeaves.blockID);
		world.setBlock(i + 9, j + 14, k + 10, Trees.giantLeaves.blockID);
		world.setBlock(i + 9, j + 15, k + 6, Trees.giantLeaves.blockID);
		world.setBlock(i + 9, j + 15, k + 7, Trees.giantLeaves.blockID);
		world.setBlock(i + 9, j + 15, k + 8, Trees.giantLeaves.blockID);
		world.setBlock(i + 9, j + 15, k + 9, Trees.giantLog.blockID);
		world.setBlock(i + 9, j + 15, k + 10, Trees.giantLeaves.blockID);
		world.setBlock(i + 9, j + 16, k + 5, Trees.giantLeaves.blockID);
		world.setBlock(i + 9, j + 16, k + 6, Trees.giantLeaves.blockID);
		world.setBlock(i + 9, j + 16, k + 7, Trees.giantLeaves.blockID);
		world.setBlock(i + 9, j + 16, k + 8, Trees.giantLeaves.blockID);
		world.setBlock(i + 9, j + 16, k + 10, Trees.giantLeaves.blockID);
		world.setBlock(i + 9, j + 16, k + 11, Trees.giantLeaves.blockID);
		world.setBlock(i + 9, j + 17, k + 6, Trees.giantLeaves.blockID);
		world.setBlock(i + 9, j + 17, k + 7, Trees.giantLeaves.blockID);
		world.setBlock(i + 9, j + 17, k + 8, Trees.giantLeaves.blockID);
		world.setBlock(i + 9, j + 17, k + 9, Trees.giantLeaves.blockID);
		world.setBlock(i + 9, j + 17, k + 10, Trees.giantLeaves.blockID);
		world.setBlock(i + 9, j + 18, k + 8, Trees.giantLeaves.blockID);
		world.setBlock(i + 9, j + 18, k + 9, Trees.giantLeaves.blockID);
		world.setBlock(i + 9, j + 22, k + 6, Trees.giantLeaves.blockID);
		world.setBlock(i + 9, j + 22, k + 7, Trees.giantLeaves.blockID);
		world.setBlock(i + 9, j + 22, k + 8, Trees.giantLeaves.blockID);
		world.setBlock(i + 9, j + 22, k + 9, Trees.giantLeaves.blockID);
		world.setBlock(i + 9, j + 22, k + 10, Trees.giantLeaves.blockID);
		world.setBlock(i + 9, j + 22, k + 11, Trees.giantLeaves.blockID);
		world.setBlock(i + 9, j + 22, k + 12, Trees.giantLeaves.blockID);
		world.setBlock(i + 9, j + 23, k + 7, Trees.giantLeaves.blockID);
		world.setBlock(i + 9, j + 23, k + 8, Trees.giantLeaves.blockID);
		world.setBlock(i + 9, j + 23, k + 9, Trees.giantLeaves.blockID);
		world.setBlock(i + 9, j + 23, k + 10, Trees.giantLeaves.blockID);
		world.setBlock(i + 9, j + 23, k + 11, Trees.giantLeaves.blockID);
		world.setBlock(i + 9, j + 24, k + 9, Trees.giantLeaves.blockID);
		world.setBlock(i + 9, j + 26, k + 1, Trees.giantLeaves.blockID);
		world.setBlock(i + 9, j + 26, k + 2, Trees.giantLeaves.blockID);
		world.setBlock(i + 9, j + 26, k + 3, Trees.giantLeaves.blockID);
		world.setBlock(i + 9, j + 26, k + 4, Trees.giantLeaves.blockID);
		world.setBlock(i + 9, j + 26, k + 5, Trees.giantLeaves.blockID);
		world.setBlock(i + 9, j + 26, k + 7, Trees.giantLeaves.blockID);
		world.setBlock(i + 9, j + 26, k + 8, Trees.giantLeaves.blockID);
		world.setBlock(i + 9, j + 26, k + 9, Trees.giantLeaves.blockID);
		world.setBlock(i + 9, j + 27, k + 2, Trees.giantLeaves.blockID);
		world.setBlock(i + 9, j + 27, k + 3, Trees.giantLeaves.blockID);
		world.setBlock(i + 9, j + 27, k + 4, Trees.giantLeaves.blockID);
		world.setBlock(i + 9, j + 27, k + 5, Trees.giantLeaves.blockID);
		world.setBlock(i + 9, j + 27, k + 6, Trees.giantLeaves.blockID);
		world.setBlock(i + 9, j + 27, k + 7, Trees.giantLeaves.blockID);
		world.setBlock(i + 9, j + 27, k + 8, Trees.giantLeaves.blockID);
		world.setBlock(i + 9, j + 28, k + 5, Trees.giantLeaves.blockID);
		world.setBlock(i + 10, j + 14, k + 5, Trees.giantLeaves.blockID);
		world.setBlock(i + 10, j + 14, k + 6, Trees.giantLeaves.blockID);
		world.setBlock(i + 10, j + 14, k + 7, Trees.giantLeaves.blockID);
		world.setBlock(i + 10, j + 14, k + 8, Trees.giantLeaves.blockID);
		world.setBlock(i + 10, j + 14, k + 9, Trees.giantLeaves.blockID);
		world.setBlock(i + 10, j + 14, k + 10, Trees.giantLeaves.blockID);
		world.setBlock(i + 10, j + 14, k + 11, Trees.giantLeaves.blockID);
		world.setBlock(i + 10, j + 15, k + 6, Trees.giantLeaves.blockID);
		world.setBlock(i + 10, j + 15, k + 7, Trees.giantLeaves.blockID);
		world.setBlock(i + 10, j + 15, k + 8, Trees.giantLeaves.blockID);
		world.setBlock(i + 10, j + 15, k + 9, Trees.giantLeaves.blockID);
		world.setBlock(i + 10, j + 15, k + 10, Trees.giantLeaves.blockID);
		world.setBlock(i + 10, j + 16, k + 7, Trees.giantLeaves.blockID);
		world.setBlock(i + 10, j + 16, k + 8, Trees.giantLeaves.blockID);
		world.setBlock(i + 10, j + 16, k + 9, Trees.giantLeaves.blockID);
		world.setBlock(i + 10, j + 16, k + 10, Trees.giantLeaves.blockID);
		world.setBlock(i + 10, j + 17, k + 8, Trees.giantLeaves.blockID);
		world.setBlock(i + 10, j + 22, k + 7, Trees.giantLeaves.blockID);
		world.setBlock(i + 10, j + 22, k + 9, Trees.giantLeaves.blockID);
		world.setBlock(i + 10, j + 22, k + 10, Trees.giantLeaves.blockID);
		world.setBlock(i + 10, j + 22, k + 11, Trees.giantLeaves.blockID);
		world.setBlock(i + 10, j + 23, k + 9, Trees.giantLeaves.blockID);
		world.setBlock(i + 10, j + 26, k + 4, Trees.giantLeaves.blockID);
		world.setBlock(i + 10, j + 26, k + 7, Trees.giantLeaves.blockID);
		world.setBlock(i + 10, j + 27, k + 5, Trees.giantLeaves.blockID);
		world.setBlock(i + 11, j + 14, k + 6, Trees.giantLeaves.blockID);
		world.setBlock(i + 11, j + 14, k + 7, Trees.giantLeaves.blockID);
		world.setBlock(i + 11, j + 14, k + 8, Trees.giantLeaves.blockID);
		world.setBlock(i + 11, j + 14, k + 9, Trees.giantLeaves.blockID);
		world.setBlock(i + 11, j + 14, k + 10, Trees.giantLeaves.blockID);
		world.setBlock(i + 11, j + 15, k + 8, Trees.giantLeaves.blockID);
		world.setBlock(i + 11, j + 16, k + 8, Trees.giantLeaves.blockID);
		world.setBlock(i + 11, j + 22, k + 9, Trees.giantLeaves.blockID);
		world.setBlock(i + 11, j + 26, k + 5, Trees.giantLeaves.blockID);
		world.setBlock(i + 12, j + 14, k + 8, Trees.giantLeaves.blockID);
		world.setBlockAndMetadataWithNotify(i + 4, j + 2, k + 5, Block.vine.blockID, 8);
		world.setBlockAndMetadataWithNotify(i + 4, j + 3, k + 6, Block.vine.blockID, 8);
		world.setBlockAndMetadataWithNotify(i + 4, j + 4, k + 5, Block.vine.blockID, 8);
		world.setBlockAndMetadataWithNotify(i + 4, j + 4, k + 6, Block.vine.blockID, 8);
		world.setBlockAndMetadataWithNotify(i + 4, j + 5, k + 6, Block.vine.blockID, 8);
		world.setBlockAndMetadataWithNotify(i + 4, j + 6, k + 5, Block.vine.blockID, 8);
		world.setBlockAndMetadataWithNotify(i + 4, j + 6, k + 6, Block.vine.blockID, 8);
		world.setBlockAndMetadataWithNotify(i + 4, j + 7, k + 5, Block.vine.blockID, 8);
		world.setBlockAndMetadataWithNotify(i + 4, j + 9, k + 5, Block.vine.blockID, 8);
		world.setBlockAndMetadataWithNotify(i + 4, j + 10, k + 5, Block.vine.blockID, 8);
		world.setBlockAndMetadataWithNotify(i + 4, j + 10, k + 6, Block.vine.blockID, 8);
		world.setBlockAndMetadataWithNotify(i + 4, j + 11, k + 5, Block.vine.blockID, 8);
		world.setBlockAndMetadataWithNotify(i + 4, j + 11, k + 6, Block.vine.blockID, 8);
		world.setBlockAndMetadataWithNotify(i + 4, j + 12, k + 6, Block.vine.blockID, 8);
		world.setBlockAndMetadataWithNotify(i + 4, j + 14, k + 5, Block.vine.blockID, 8);
		world.setBlockAndMetadataWithNotify(i + 4, j + 14, k + 6, Block.vine.blockID, 8);
		world.setBlockAndMetadataWithNotify(i + 4, j + 16, k + 5, Block.vine.blockID, 8);
		world.setBlockAndMetadataWithNotify(i + 4, j + 16, k + 6, Block.vine.blockID, 8);
		world.setBlockAndMetadataWithNotify(i + 4, j + 17, k + 5, Block.vine.blockID, 8);
		world.setBlockAndMetadataWithNotify(i + 4, j + 17, k + 6, Block.vine.blockID, 8);
		world.setBlockAndMetadataWithNotify(i + 4, j + 18, k + 5, Block.vine.blockID, 8);
		world.setBlockAndMetadataWithNotify(i + 4, j + 19, k + 6, Block.vine.blockID, 8);
		world.setBlockAndMetadataWithNotify(i + 4, j + 20, k + 5, Block.vine.blockID, 8);
		world.setBlockAndMetadataWithNotify(i + 4, j + 21, k + 6, Block.vine.blockID, 8);
		world.setBlockAndMetadataWithNotify(i + 4, j + 22, k + 5, Block.vine.blockID, 8);
		world.setBlockAndMetadataWithNotify(i + 4, j + 24, k + 6, Block.vine.blockID, 8);
		world.setBlockAndMetadataWithNotify(i + 4, j + 25, k + 6, Block.vine.blockID, 8);
		world.setBlockAndMetadataWithNotify(i + 5, j + 2, k + 4, Block.vine.blockID, 1);
		world.setBlockAndMetadataWithNotify(i + 5, j + 2, k + 7, Block.vine.blockID, 4);
		world.setBlockAndMetadataWithNotify(i + 5, j + 4, k + 4, Block.vine.blockID, 1);
		world.setBlockAndMetadataWithNotify(i + 5, j + 4, k + 7, Block.vine.blockID, 4);
		world.setBlockAndMetadataWithNotify(i + 5, j + 5, k + 7, Block.vine.blockID, 4);
		world.setBlockAndMetadataWithNotify(i + 5, j + 6, k + 4, Block.vine.blockID, 1);
		world.setBlockAndMetadataWithNotify(i + 5, j + 6, k + 7, Block.vine.blockID, 4);
		world.setBlockAndMetadataWithNotify(i + 5, j + 7, k + 4, Block.vine.blockID, 1);
		world.setBlockAndMetadataWithNotify(i + 5, j + 7, k + 7, Block.vine.blockID, 4);
		world.setBlockAndMetadataWithNotify(i + 5, j + 8, k + 4, Block.vine.blockID, 1);
		world.setBlockAndMetadataWithNotify(i + 5, j + 8, k + 7, Block.vine.blockID, 4);
		world.setBlockAndMetadataWithNotify(i + 5, j + 9, k + 4, Block.vine.blockID, 1);
		world.setBlockAndMetadataWithNotify(i + 5, j + 9, k + 7, Block.vine.blockID, 4);
		world.setBlockAndMetadataWithNotify(i + 5, j + 10, k + 4, Block.vine.blockID, 1);
		world.setBlockAndMetadataWithNotify(i + 5, j + 10, k + 7, Block.vine.blockID, 4);
		world.setBlockAndMetadataWithNotify(i + 5, j + 11, k + 7, Block.vine.blockID, 4);
		world.setBlockAndMetadataWithNotify(i + 5, j + 12, k + 4, Block.vine.blockID, 1);
		world.setBlockAndMetadataWithNotify(i + 5, j + 13, k + 4, Block.vine.blockID, 1);
		world.setBlockAndMetadataWithNotify(i + 5, j + 14, k + 7, Block.vine.blockID, 4);
		world.setBlockAndMetadataWithNotify(i + 5, j + 15, k + 4, Block.vine.blockID, 1);
		world.setBlockAndMetadataWithNotify(i + 5, j + 15, k + 7, Block.vine.blockID, 4);
		world.setBlockAndMetadataWithNotify(i + 5, j + 16, k + 4, Block.vine.blockID, 1);
		world.setBlockAndMetadataWithNotify(i + 5, j + 17, k + 4, Block.vine.blockID, 1);
		world.setBlockAndMetadataWithNotify(i + 5, j + 17, k + 7, Block.vine.blockID, 4);
		world.setBlockAndMetadataWithNotify(i + 5, j + 18, k + 4, Block.vine.blockID, 1);
		world.setBlockAndMetadataWithNotify(i + 5, j + 20, k + 4, Block.vine.blockID, 1);
		world.setBlockAndMetadataWithNotify(i + 5, j + 20, k + 7, Block.vine.blockID, 4);
		world.setBlockAndMetadataWithNotify(i + 5, j + 21, k + 4, Block.vine.blockID, 1);
		world.setBlockAndMetadataWithNotify(i + 5, j + 22, k + 4, Block.vine.blockID, 1);
		world.setBlockAndMetadataWithNotify(i + 5, j + 23, k + 7, Block.vine.blockID, 4);
		world.setBlockAndMetadataWithNotify(i + 5, j + 24, k + 7, Block.vine.blockID, 4);
		world.setBlockAndMetadataWithNotify(i + 5, j + 25, k + 4, Block.vine.blockID, 1);
		world.setBlockAndMetadataWithNotify(i + 5, j + 25, k + 7, Block.vine.blockID, 4);
		world.setBlockAndMetadataWithNotify(i + 6, j + 2, k + 7, Block.vine.blockID, 4);
		world.setBlockAndMetadataWithNotify(i + 6, j + 3, k + 7, Block.vine.blockID, 4);
		world.setBlockAndMetadataWithNotify(i + 6, j + 4, k + 7, Block.vine.blockID, 4);
		world.setBlockAndMetadataWithNotify(i + 6, j + 5, k + 4, Block.vine.blockID, 1);
		world.setBlockAndMetadataWithNotify(i + 6, j + 6, k + 4, Block.vine.blockID, 1);
		world.setBlockAndMetadataWithNotify(i + 6, j + 7, k + 4, Block.vine.blockID, 1);
		world.setBlockAndMetadataWithNotify(i + 6, j + 7, k + 7, Block.vine.blockID, 4);
		world.setBlockAndMetadataWithNotify(i + 6, j + 8, k + 7, Block.vine.blockID, 4);
		world.setBlockAndMetadataWithNotify(i + 6, j + 10, k + 4, Block.vine.blockID, 1);
		world.setBlockAndMetadataWithNotify(i + 6, j + 10, k + 7, Block.vine.blockID, 4);
		world.setBlockAndMetadataWithNotify(i + 6, j + 11, k + 4, Block.vine.blockID, 1);
		world.setBlockAndMetadataWithNotify(i + 6, j + 11, k + 7, Block.vine.blockID, 4);
		world.setBlockAndMetadataWithNotify(i + 6, j + 12, k + 4, Block.vine.blockID, 1);
		world.setBlockAndMetadataWithNotify(i + 6, j + 12, k + 7, Block.vine.blockID, 4);
		world.setBlockAndMetadataWithNotify(i + 6, j + 13, k + 4, Block.vine.blockID, 1);
		world.setBlockAndMetadataWithNotify(i + 6, j + 14, k + 4, Block.vine.blockID, 1);
		world.setBlockAndMetadataWithNotify(i + 6, j + 15, k + 4, Block.vine.blockID, 1);
		world.setBlockAndMetadataWithNotify(i + 6, j + 19, k + 4, Block.vine.blockID, 1);
		world.setBlockAndMetadataWithNotify(i + 6, j + 20, k + 4, Block.vine.blockID, 1);
		world.setBlockAndMetadataWithNotify(i + 6, j + 20, k + 7, Block.vine.blockID, 4);
		world.setBlockAndMetadataWithNotify(i + 6, j + 21, k + 4, Block.vine.blockID, 1);
		world.setBlockAndMetadataWithNotify(i + 6, j + 22, k + 4, Block.vine.blockID, 1);
		world.setBlockAndMetadataWithNotify(i + 6, j + 23, k + 4, Block.vine.blockID, 1);
		world.setBlockAndMetadataWithNotify(i + 6, j + 23, k + 7, Block.vine.blockID, 4);
		world.setBlockAndMetadataWithNotify(i + 6, j + 24, k + 4, Block.vine.blockID, 1);
		world.setBlockAndMetadataWithNotify(i + 6, j + 24, k + 7, Block.vine.blockID, 4);
		world.setBlockAndMetadataWithNotify(i + 6, j + 25, k + 4, Block.vine.blockID, 1);
		world.setBlockAndMetadataWithNotify(i + 7, j + 2, k + 5, Block.vine.blockID, 2);
		world.setBlockAndMetadataWithNotify(i + 7, j + 2, k + 6, Block.vine.blockID, 2);
		world.setBlockAndMetadataWithNotify(i + 7, j + 3, k + 6, Block.vine.blockID, 2);
		world.setBlockAndMetadataWithNotify(i + 7, j + 4, k + 5, Block.vine.blockID, 2);
		world.setBlockAndMetadataWithNotify(i + 7, j + 4, k + 6, Block.vine.blockID, 2);
		world.setBlockAndMetadataWithNotify(i + 7, j + 5, k + 6, Block.vine.blockID, 2);
		world.setBlockAndMetadataWithNotify(i + 7, j + 6, k + 5, Block.vine.blockID, 2);
		world.setBlockAndMetadataWithNotify(i + 7, j + 7, k + 5, Block.vine.blockID, 2);
		world.setBlockAndMetadataWithNotify(i + 7, j + 7, k + 6, Block.vine.blockID, 2);
		world.setBlockAndMetadataWithNotify(i + 7, j + 8, k + 5, Block.vine.blockID, 2);
		world.setBlockAndMetadataWithNotify(i + 7, j + 9, k + 5, Block.vine.blockID, 2);
		world.setBlockAndMetadataWithNotify(i + 7, j + 9, k + 6, Block.vine.blockID, 2);
		world.setBlockAndMetadataWithNotify(i + 7, j + 11, k + 5, Block.vine.blockID, 2);
		world.setBlockAndMetadataWithNotify(i + 7, j + 11, k + 6, Block.vine.blockID, 2);
		world.setBlockAndMetadataWithNotify(i + 7, j + 12, k + 6, Block.vine.blockID, 2);
		world.setBlockAndMetadataWithNotify(i + 7, j + 14, k + 5, Block.vine.blockID, 2);
		world.setBlockAndMetadataWithNotify(i + 7, j + 15, k + 5, Block.vine.blockID, 2);
		world.setBlockAndMetadataWithNotify(i + 7, j + 16, k + 5, Block.vine.blockID, 2);
		world.setBlockAndMetadataWithNotify(i + 7, j + 17, k + 5, Block.vine.blockID, 2);
		world.setBlockAndMetadataWithNotify(i + 7, j + 18, k + 5, Block.vine.blockID, 2);
		world.setBlockAndMetadataWithNotify(i + 7, j + 19, k + 6, Block.vine.blockID, 2);
		world.setBlockAndMetadataWithNotify(i + 7, j + 20, k + 5, Block.vine.blockID, 2);
		world.setBlockAndMetadataWithNotify(i + 7, j + 20, k + 6, Block.vine.blockID, 2);
		world.setBlockAndMetadataWithNotify(i + 7, j + 21, k + 5, Block.vine.blockID, 2);
		world.setBlockAndMetadataWithNotify(i + 7, j + 22, k + 5, Block.vine.blockID, 2);
		world.setBlockAndMetadataWithNotify(i + 7, j + 23, k + 5, Block.vine.blockID, 2);
		world.setBlockAndMetadataWithNotify(i + 7, j + 23, k + 6, Block.vine.blockID, 2);
		world.setBlockAndMetadataWithNotify(i + 7, j + 24, k + 6, Block.vine.blockID, 2);
		world.setBlockAndMetadataWithNotify(i + 7, j + 25, k + 6, Block.vine.blockID, 2);

		return true;
	}
}