package microjunk.trees.common.worldgentrees;

import java.util.Random;

import microjunk.trees.common.Trees;
import net.minecraft.block.Block;
import net.minecraft.world.World;
import net.minecraft.world.gen.feature.WorldGenerator;

public class WorldGenRedwoodTrees extends WorldGenerator
{
	public WorldGenRedwoodTrees()
    {
		
    }
	public boolean generate(World world, Random rand, int i, int j, int k)
	{
		int j1 = world.getBlockId(i, j - 1, k);
		if(j1 != Block.grass.blockID && j1 != Block.dirt.blockID || j >= 128 - 12 - 1)
        {
        	return false;
        }
         int x = i-3;
         int z = k - 3;
         world.setBlock(x + 3, j + -1, z + 3, Block.dirt.blockID);// keep this
         world.setBlock(x + 3, j + 0, z + 3, Trees.redwoodLog.blockID);///This sets what your tree will look like
         world.setBlock(x + 3, j + 1, z + 3, Trees.redwoodLog.blockID);// You should make your own version
         world.setBlock(x + 3, j + 2, z + 3, Trees.redwoodLog.blockID);
         world.setBlock(x + 3, j + 3, z + 3, Trees.redwoodLog.blockID);
         world.setBlock(x + 3, j + 4, z + 3, Trees.redwoodLog.blockID);
         world.setBlock(x + 3, j + 5, z + 3, Trees.redwoodLog.blockID);
         world.setBlock(x + 3, j + 6, z + 3, Trees.redwoodLog.blockID);
         world.setBlock(x + 2, j + 6, z + 3, Trees.redwoodLeaves.blockID);
         world.setBlock(x + 3, j + 6, z + 3, Trees.redwoodLog.blockID);
         world.setBlock(x + 4, j + 6, z + 3, Trees.redwoodLeaves.blockID);
         world.setBlock(x + 3, j + 7, z + 3, Trees.redwoodLog.blockID);
         world.setBlock(x + 1, j + 7, z + 4, Trees.redwoodLeaves.blockID);
         world.setBlock(x + 1, j + 7, z + 3, Trees.redwoodLeaves.blockID);
         world.setBlock(x + 2, j + 7, z + 4, Trees.redwoodLeaves.blockID);
         world.setBlock(x + 2, j + 7, z + 3, Trees.redwoodLog.blockID);
         world.setBlock(x + 2, j + 7, z + 2, Trees.redwoodLeaves.blockID);
         world.setBlock(x + 3, j + 7, z + 4, Trees.redwoodLeaves.blockID);
         world.setBlock(x + 3, j + 7, z + 3, Trees.redwoodLog.blockID);
         world.setBlock(x + 4, j + 7, z + 4, Trees.redwoodLeaves.blockID);
         world.setBlock(x + 4, j + 7, z + 3, Trees.redwoodLog.blockID);
         world.setBlock(x + 4, j + 7, z + 2, Trees.redwoodLeaves.blockID);
         world.setBlock(x + 5, j + 7, z + 3, Trees.redwoodLeaves.blockID);
         world.setBlock(x + 3, j + 8, z + 3, Trees.redwoodLog.blockID);
         world.setBlock(x + 0, j + 8, z + 5, Trees.redwoodLeaves.blockID);
         world.setBlock(x + 1, j + 8, z + 6, Trees.redwoodLeaves.blockID);
         world.setBlock(x + 1, j + 8, z + 5, Trees.redwoodLog.blockID);
         world.setBlock(x + 1, j + 8, z + 4, Trees.redwoodLog.blockID);
         world.setBlock(x + 1, j + 8, z + 3, Trees.redwoodLeaves.blockID);
         world.setBlock(x + 2, j + 8, z + 5, Trees.redwoodLeaves.blockID);
         world.setBlock(x + 2, j + 8, z + 4, Trees.redwoodLog.blockID);
         world.setBlock(x + 2, j + 8, z + 3, Trees.redwoodLeaves.blockID);
         world.setBlock(x + 2, j + 8, z + 2, Trees.redwoodLeaves.blockID);
         world.setBlock(x + 3, j + 8, z + 5, Trees.redwoodLeaves.blockID);
         world.setBlock(x + 3, j + 8, z + 4, Trees.redwoodLeaves.blockID);
         world.setBlock(x + 3, j + 8, z + 3, Trees.redwoodLeaves.blockID);
         world.setBlock(x + 3, j + 8, z + 2, Trees.redwoodLeaves.blockID);
         world.setBlock(x + 3, j + 8, z + 1, Trees.redwoodLeaves.blockID);
         world.setBlock(x + 4, j + 8, z + 5, Trees.redwoodLeaves.blockID);
         world.setBlock(x + 4, j + 8, z + 4, Trees.redwoodLog.blockID);
         world.setBlock(x + 4, j + 8, z + 3, Trees.redwoodLog.blockID);
         world.setBlock(x + 4, j + 8, z + 2, Trees.redwoodLeaves.blockID);
         world.setBlock(x + 5, j + 8, z + 5, Trees.redwoodLeaves.blockID);
         world.setBlock(x + 5, j + 8, z + 4, Trees.redwoodLeaves.blockID);
         world.setBlock(x + 5, j + 8, z + 3, Trees.redwoodLeaves.blockID);
         world.setBlock(x + 5, j + 8, z + 2, Trees.redwoodLeaves.blockID);
         world.setBlock(x + 3, j + 9, z + 3, Trees.redwoodLog.blockID);
         world.setBlock(x + 0, j + 9, z + 6, Trees.redwoodLeaves.blockID);
         world.setBlock(x + 0, j + 9, z + 2, Trees.redwoodLeaves.blockID);
         world.setBlock(x + 1, j + 9, z + 7, Trees.redwoodLeaves.blockID);
         world.setBlock(x + 1, j + 9, z + 6, Trees.redwoodLog.blockID);
         world.setBlock(x + 1, j + 9, z + 5, Trees.redwoodLeaves.blockID);
         world.setBlock(x + 1, j + 9, z + 4, Trees.redwoodLeaves.blockID);
         world.setBlock(x + 1, j + 9, z + 3, Trees.redwoodLeaves.blockID);
         world.setBlock(x + 1, j + 9, z + 2, Trees.redwoodLog.blockID);
         world.setBlock(x + 1, j + 9, z + 1, Trees.redwoodLeaves.blockID);
         world.setBlock(x + 2, j + 9, z + 6, Trees.redwoodLeaves.blockID);
         world.setBlock(x + 2, j + 9, z + 5, Trees.redwoodLeaves.blockID);
         world.setBlock(x + 2, j + 9, z + 4, Trees.redwoodLeaves.blockID);
         world.setBlock(x + 2, j + 9, z + 3, Trees.redwoodLog.blockID);
         world.setBlock(x + 2, j + 9, z + 2, Trees.redwoodLeaves.blockID);
         world.setBlock(x + 3, j + 9, z + 4, Trees.redwoodLeaves.blockID);
         world.setBlock(x + 3, j + 9, z + 2, Trees.redwoodLeaves.blockID);
         world.setBlock(x + 3, j + 9, z + 1, Trees.redwoodLeaves.blockID);
         world.setBlock(x + 4, j + 9, z + 5, Trees.redwoodLeaves.blockID);
         world.setBlock(x + 4, j + 9, z + 4, Trees.redwoodLeaves.blockID);
         world.setBlock(x + 4, j + 9, z + 3, Trees.redwoodLeaves.blockID);
         world.setBlock(x + 4, j + 9, z + 2, Trees.redwoodLog.blockID);
         world.setBlock(x + 4, j + 9, z + 1, Trees.redwoodLeaves.blockID);
         world.setBlock(x + 5, j + 9, z + 6, Trees.redwoodLeaves.blockID);
         world.setBlock(x + 5, j + 9, z + 5, Trees.redwoodLog.blockID);
         world.setBlock(x + 5, j + 9, z + 4, Trees.redwoodLeaves.blockID);
         world.setBlock(x + 5, j + 9, z + 3, Trees.redwoodLeaves.blockID);
         world.setBlock(x + 5, j + 9, z + 2, Trees.redwoodLog.blockID);
         world.setBlock(x + 5, j + 9, z + 1, Trees.redwoodLeaves.blockID);
         world.setBlock(x + 6, j + 9, z + 5, Trees.redwoodLeaves.blockID);
         world.setBlock(x + 6, j + 9, z + 2, Trees.redwoodLeaves.blockID);
         world.setBlock(x + 3, j + 10, z + 3, Trees.redwoodLog.blockID);
         world.setBlock(x + 0, j + 10, z + 7, Trees.redwoodLeaves.blockID);
         world.setBlock(x + 0, j + 10, z + 6, Trees.redwoodLeaves.blockID);
         world.setBlock(x + 0, j + 10, z + 3, Trees.redwoodLeaves.blockID);
         world.setBlock(x + 0, j + 10, z + 2, Trees.redwoodLeaves.blockID);
         world.setBlock(x + 0, j + 10, z + 1, Trees.redwoodLeaves.blockID);
         world.setBlock(x + 1, j + 10, z + 6, Trees.redwoodLeaves.blockID);
         world.setBlock(x + 1, j + 10, z + 3, Trees.redwoodLeaves.blockID);
         world.setBlock(x + 1, j + 10, z + 2, Trees.redwoodLog.blockID);
         world.setBlock(x + 1, j + 10, z + 1, Trees.redwoodLog.blockID);
         world.setBlock(x + 1, j + 10, z + 0, Trees.redwoodLeaves.blockID);
         world.setBlock(x + 2, j + 10, z + 3, Trees.redwoodLeaves.blockID);
         world.setBlock(x + 2, j + 10, z + 2, Trees.redwoodLeaves.blockID);
         world.setBlock(x + 3, j + 10, z + 3, Trees.redwoodLeaves.blockID);
         world.setBlock(x + 4, j + 10, z + 2, Trees.redwoodLeaves.blockID);
         world.setBlock(x + 5, j + 10, z + 5, Trees.redwoodLeaves.blockID);
         world.setBlock(x + 5, j + 10, z + 4, Trees.redwoodLeaves.blockID);
         world.setBlock(x + 5, j + 10, z + 2, Trees.redwoodLeaves.blockID);
         world.setBlock(x + 5, j + 10, z + 1, Trees.redwoodLeaves.blockID);
         world.setBlock(x + 6, j + 10, z + 6, Trees.redwoodLeaves.blockID);
         world.setBlock(x + 6, j + 10, z + 5, Trees.redwoodLeaves.blockID);
         world.setBlock(x + 6, j + 10, z + 4, Trees.redwoodLeaves.blockID);
         world.setBlock(x + 6, j + 10, z + 1, Trees.redwoodLeaves.blockID);
         world.setBlock(x + 1, j + 11, z + 2, Trees.redwoodLeaves.blockID);
         world.setBlock(x + 1, j + 11, z + 2, Trees.redwoodLeaves.blockID);
         world.setBlock(x + 1, j + 11, z + 1, Trees.redwoodLeaves.blockID);
         world.setBlock(x + 6, j + 11, z + 6, Trees.redwoodLeaves.blockID);
         world.setBlock(x + 3, j + 11, z + 3, Trees.redwoodLog.blockID);
         world.setBlock(x + 3, j + 12, z + 3, Trees.redwoodLog.blockID);///This sets what your tree will look like
         world.setBlock(x + 3, j + 13, z + 3, Trees.redwoodLog.blockID);// You should make your own version
         world.setBlock(x + 3, j + 14, z + 3, Trees.redwoodLog.blockID);
         world.setBlock(x + 3, j + 15, z + 3, Trees.redwoodLog.blockID);
         world.setBlock(x + 3, j + 16, z + 3, Trees.redwoodLog.blockID);
         world.setBlock(x + 3, j + 17, z + 3, Trees.redwoodLog.blockID);
         world.setBlock(x + 2, j + 18, z + 3, Trees.redwoodLeaves.blockID);
         world.setBlock(x + 3, j + 18, z + 3, Trees.redwoodLog.blockID);
         world.setBlock(x + 4, j + 18, z + 3, Trees.redwoodLeaves.blockID);
         world.setBlock(x + 1, j + 19, z + 4, Trees.redwoodLeaves.blockID);
         world.setBlock(x + 1, j + 19, z + 3, Trees.redwoodLeaves.blockID);
         world.setBlock(x + 2, j + 19, z + 4, Trees.redwoodLeaves.blockID);
         world.setBlock(x + 2, j + 19, z + 3, Trees.redwoodLog.blockID);
         world.setBlock(x + 2, j + 19, z + 2, Trees.redwoodLeaves.blockID);
         world.setBlock(x + 3, j + 19, z + 4, Trees.redwoodLeaves.blockID);
         world.setBlock(x + 3, j + 19, z + 3, Trees.redwoodLog.blockID);
         world.setBlock(x + 4, j + 19, z + 4, Trees.redwoodLeaves.blockID);
         world.setBlock(x + 4, j + 19, z + 3, Trees.redwoodLog.blockID);
         world.setBlock(x + 4, j + 19, z + 2, Trees.redwoodLeaves.blockID);
         world.setBlock(x + 5, j + 19, z + 3, Trees.redwoodLeaves.blockID);
         world.setBlock(x + 0, j + 20, z + 5, Trees.redwoodLeaves.blockID);
         world.setBlock(x + 1, j + 20, z + 6, Trees.redwoodLeaves.blockID);
         world.setBlock(x + 1, j + 20, z + 5, Trees.redwoodLog.blockID);
         world.setBlock(x + 1, j + 20, z + 4, Trees.redwoodLog.blockID);
         world.setBlock(x + 1, j + 20, z + 3, Trees.redwoodLeaves.blockID);
         world.setBlock(x + 2, j + 20, z + 5, Trees.redwoodLeaves.blockID);
         world.setBlock(x + 2, j + 20, z + 4, Trees.redwoodLog.blockID);
         world.setBlock(x + 2, j + 20, z + 3, Trees.redwoodLeaves.blockID);
         world.setBlock(x + 2, j + 20, z + 2, Trees.redwoodLeaves.blockID);
         world.setBlock(x + 3, j + 20, z + 5, Trees.redwoodLeaves.blockID);
         world.setBlock(x + 3, j + 20, z + 4, Trees.redwoodLeaves.blockID);
         world.setBlock(x + 3, j + 20, z + 3, Trees.redwoodLeaves.blockID);
         world.setBlock(x + 3, j + 20, z + 2, Trees.redwoodLeaves.blockID);
         world.setBlock(x + 3, j + 20, z + 1, Trees.redwoodLeaves.blockID);
         world.setBlock(x + 4, j + 20, z + 5, Trees.redwoodLeaves.blockID);
         world.setBlock(x + 4, j + 20, z + 4, Trees.redwoodLog.blockID);
         world.setBlock(x + 4, j + 20, z + 3, Trees.redwoodLog.blockID);
         world.setBlock(x + 4, j + 20, z + 2, Trees.redwoodLeaves.blockID);
         world.setBlock(x + 5, j + 20, z + 5, Trees.redwoodLeaves.blockID);
         world.setBlock(x + 5, j + 20, z + 4, Trees.redwoodLeaves.blockID);
         world.setBlock(x + 5, j + 20, z + 3, Trees.redwoodLeaves.blockID);
         world.setBlock(x + 5, j + 20, z + 2, Trees.redwoodLeaves.blockID);
         world.setBlock(x + 3, j + 21, z + 3, Trees.redwoodLog.blockID);
         world.setBlock(x + 0, j + 21, z + 6, Trees.redwoodLeaves.blockID);
         world.setBlock(x + 0, j + 21, z + 2, Trees.redwoodLeaves.blockID);
         world.setBlock(x + 1, j + 21, z + 7, Trees.redwoodLeaves.blockID);
         world.setBlock(x + 1, j + 21, z + 6, Trees.redwoodLog.blockID);
         world.setBlock(x + 1, j + 21, z + 5, Trees.redwoodLeaves.blockID);
         world.setBlock(x + 1, j + 21, z + 4, Trees.redwoodLeaves.blockID);
         world.setBlock(x + 1, j + 21, z + 3, Trees.redwoodLeaves.blockID);
         world.setBlock(x + 1, j + 21, z + 2, Trees.redwoodLog.blockID);
         world.setBlock(x + 1, j + 21, z + 1, Trees.redwoodLeaves.blockID);
         world.setBlock(x + 2, j + 21, z + 6, Trees.redwoodLeaves.blockID);
         world.setBlock(x + 2, j + 21, z + 5, Trees.redwoodLeaves.blockID);
         world.setBlock(x + 2, j + 21, z + 4, Trees.redwoodLeaves.blockID);
         world.setBlock(x + 2, j + 21, z + 3, Trees.redwoodLog.blockID);
         world.setBlock(x + 2, j + 21, z + 2, Trees.redwoodLeaves.blockID);
         world.setBlock(x + 3, j + 21, z + 4, Trees.redwoodLeaves.blockID);
         world.setBlock(x + 3, j + 21, z + 2, Trees.redwoodLeaves.blockID);
         world.setBlock(x + 3, j + 21, z + 1, Trees.redwoodLeaves.blockID);
         world.setBlock(x + 4, j + 21, z + 5, Trees.redwoodLeaves.blockID);
         world.setBlock(x + 4, j + 21, z + 4, Trees.redwoodLeaves.blockID);
         world.setBlock(x + 4, j + 21, z + 3, Trees.redwoodLeaves.blockID);
         world.setBlock(x + 4, j + 21, z + 2, Trees.redwoodLog.blockID);
         world.setBlock(x + 4, j + 21, z + 1, Trees.redwoodLeaves.blockID);
         world.setBlock(x + 5, j + 21, z + 6, Trees.redwoodLeaves.blockID);
         world.setBlock(x + 5, j + 21, z + 5, Trees.redwoodLog.blockID);
         world.setBlock(x + 5, j + 21, z + 4, Trees.redwoodLeaves.blockID);
         world.setBlock(x + 5, j + 21, z + 3, Trees.redwoodLeaves.blockID);
         world.setBlock(x + 5, j + 21, z + 2, Trees.redwoodLog.blockID);
         world.setBlock(x + 5, j + 21, z + 1, Trees.redwoodLeaves.blockID);
         world.setBlock(x + 6, j + 21, z + 5, Trees.redwoodLeaves.blockID);
         world.setBlock(x + 6, j + 21, z + 2, Trees.redwoodLeaves.blockID);
         world.setBlock(x + 3, j + 22, z + 3, Trees.redwoodLog.blockID);
         world.setBlock(x + 0, j + 22, z + 7, Trees.redwoodLeaves.blockID);
         world.setBlock(x + 0, j + 22, z + 6, Trees.redwoodLeaves.blockID);
         world.setBlock(x + 0, j + 22, z + 3, Trees.redwoodLeaves.blockID);
         world.setBlock(x + 0, j + 22, z + 2, Trees.redwoodLeaves.blockID);
         world.setBlock(x + 0, j + 22, z + 1, Trees.redwoodLeaves.blockID);
         world.setBlock(x + 1, j + 22, z + 6, Trees.redwoodLeaves.blockID);
         world.setBlock(x + 1, j + 22, z + 3, Trees.redwoodLeaves.blockID);
         world.setBlock(x + 1, j + 22, z + 2, Trees.redwoodLog.blockID);
         world.setBlock(x + 1, j + 22, z + 1, Trees.redwoodLog.blockID);
         world.setBlock(x + 1, j + 22, z + 0, Trees.redwoodLeaves.blockID);
         world.setBlock(x + 2, j + 22, z + 3, Trees.redwoodLeaves.blockID);
         world.setBlock(x + 2, j + 22, z + 2, Trees.redwoodLeaves.blockID);
         world.setBlock(x + 3, j + 22, z + 3, Trees.redwoodLeaves.blockID);
         world.setBlock(x + 4, j + 22, z + 2, Trees.redwoodLeaves.blockID);
         world.setBlock(x + 5, j + 22, z + 5, Trees.redwoodLeaves.blockID);
         world.setBlock(x + 5, j + 22, z + 4, Trees.redwoodLeaves.blockID);
         world.setBlock(x + 5, j + 22, z + 2, Trees.redwoodLeaves.blockID);
         world.setBlock(x + 5, j + 22, z + 1, Trees.redwoodLeaves.blockID);
         world.setBlock(x + 6, j + 22, z + 6, Trees.redwoodLeaves.blockID);
         world.setBlock(x + 6, j + 22, z + 5, Trees.redwoodLeaves.blockID);
         world.setBlock(x + 6, j + 22, z + 4, Trees.redwoodLeaves.blockID);
         world.setBlock(x + 6, j + 22, z + 1, Trees.redwoodLeaves.blockID);
         world.setBlock(x + 3, j + 23, z + 3, Trees.redwoodLog.blockID);
         world.setBlock(x + 1, j + 23, z + 2, Trees.redwoodLeaves.blockID);
         world.setBlock(x + 1, j + 23, z + 1, Trees.redwoodLeaves.blockID);
         world.setBlock(x + 6, j + 23, z + 6, Trees.redwoodLeaves.blockID);
         world.setBlock(x + 3, j + 24, z + 3, Trees.redwoodLog.blockID);// keep this
         world.setBlock(x + 3, j + 25, z + 3, Trees.redwoodLog.blockID);///This sets what your tree will look like
         world.setBlock(x + 3, j + 26, z + 3, Trees.redwoodLog.blockID);// You should make your own version
         world.setBlock(x + 3, j + 27, z + 3, Trees.redwoodLog.blockID);
         world.setBlock(x + 3, j + 28, z + 3, Trees.redwoodLog.blockID);
         world.setBlock(x + 3, j + 29, z + 3, Trees.redwoodLog.blockID);
         world.setBlock(x + 3, j + 30, z + 3, Trees.redwoodLog.blockID);
         world.setBlock(x + 3, j + 31, z + 3, Trees.redwoodLog.blockID);
         world.setBlock(x + 2, j + 32, z + 3, Trees.redwoodLeaves.blockID);
         world.setBlock(x + 3, j + 32, z + 3, Trees.redwoodLog.blockID);
         world.setBlock(x + 4, j + 32, z + 3, Trees.redwoodLeaves.blockID);
         world.setBlock(x + 3, j + 33, z + 3, Trees.redwoodLog.blockID);
         world.setBlock(x + 1, j + 33, z + 4, Trees.redwoodLeaves.blockID);
         world.setBlock(x + 1, j + 33, z + 3, Trees.redwoodLeaves.blockID);
         world.setBlock(x + 2, j + 33, z + 4, Trees.redwoodLeaves.blockID);
         world.setBlock(x + 2, j + 33, z + 3, Trees.redwoodLog.blockID);
         world.setBlock(x + 2, j + 33, z + 2, Trees.redwoodLeaves.blockID);
         world.setBlock(x + 3, j + 33, z + 4, Trees.redwoodLeaves.blockID);
         world.setBlock(x + 3, j + 33, z + 3, Trees.redwoodLog.blockID);
         world.setBlock(x + 4, j + 33, z + 4, Trees.redwoodLeaves.blockID);
         world.setBlock(x + 4, j + 33, z + 3, Trees.redwoodLog.blockID);
         world.setBlock(x + 4, j + 33, z + 2, Trees.redwoodLeaves.blockID);
         world.setBlock(x + 5, j + 33, z + 3, Trees.redwoodLeaves.blockID);
         world.setBlock(x + 3, j + 34, z + 3, Trees.redwoodLog.blockID);
         world.setBlock(x + 0, j + 34, z + 5, Trees.redwoodLeaves.blockID);
         world.setBlock(x + 1, j + 34, z + 6, Trees.redwoodLeaves.blockID);
         world.setBlock(x + 1, j + 34, z + 5, Trees.redwoodLog.blockID);
         world.setBlock(x + 1, j + 34, z + 4, Trees.redwoodLog.blockID);
         world.setBlock(x + 1, j + 34, z + 3, Trees.redwoodLeaves.blockID);
         world.setBlock(x + 2, j + 34, z + 5, Trees.redwoodLeaves.blockID);
         world.setBlock(x + 2, j + 34, z + 4, Trees.redwoodLog.blockID);
         world.setBlock(x + 2, j + 34, z + 3, Trees.redwoodLeaves.blockID);
         world.setBlock(x + 2, j + 34, z + 2, Trees.redwoodLeaves.blockID);
         world.setBlock(x + 3, j + 34, z + 5, Trees.redwoodLeaves.blockID);
         world.setBlock(x + 3, j + 34, z + 4, Trees.redwoodLeaves.blockID);
         world.setBlock(x + 3, j + 34, z + 3, Trees.redwoodLeaves.blockID);
         world.setBlock(x + 3, j + 34, z + 2, Trees.redwoodLeaves.blockID);
         world.setBlock(x + 3, j + 34, z + 1, Trees.redwoodLeaves.blockID);
         world.setBlock(x + 4, j + 34, z + 5, Trees.redwoodLeaves.blockID);
         world.setBlock(x + 4, j + 34, z + 4, Trees.redwoodLog.blockID);
         world.setBlock(x + 4, j + 34, z + 3, Trees.redwoodLog.blockID);
         world.setBlock(x + 4, j + 34, z + 2, Trees.redwoodLeaves.blockID);
         world.setBlock(x + 5, j + 34, z + 5, Trees.redwoodLeaves.blockID);
         world.setBlock(x + 5, j + 34, z + 4, Trees.redwoodLeaves.blockID);
         world.setBlock(x + 5, j + 34, z + 3, Trees.redwoodLeaves.blockID);
         world.setBlock(x + 5, j + 34, z + 2, Trees.redwoodLeaves.blockID);
         world.setBlock(x + 3, j + 35, z + 3, Trees.redwoodLog.blockID);
         world.setBlock(x + 0, j + 35, z + 6, Trees.redwoodLeaves.blockID);
         world.setBlock(x + 0, j + 35, z + 2, Trees.redwoodLeaves.blockID);
         world.setBlock(x + 1, j + 35, z + 7, Trees.redwoodLeaves.blockID);
         world.setBlock(x + 1, j + 35, z + 6, Trees.redwoodLog.blockID);
         world.setBlock(x + 1, j + 35, z + 5, Trees.redwoodLeaves.blockID);
         world.setBlock(x + 1, j + 35, z + 4, Trees.redwoodLeaves.blockID);
         world.setBlock(x + 1, j + 35, z + 3, Trees.redwoodLeaves.blockID);
         world.setBlock(x + 1, j + 35, z + 2, Trees.redwoodLog.blockID);
         world.setBlock(x + 1, j + 35, z + 1, Trees.redwoodLeaves.blockID);
         world.setBlock(x + 2, j + 35, z + 6, Trees.redwoodLeaves.blockID);
         world.setBlock(x + 2, j + 35, z + 5, Trees.redwoodLeaves.blockID);
         world.setBlock(x + 2, j + 35, z + 4, Trees.redwoodLeaves.blockID);
         world.setBlock(x + 2, j + 35, z + 3, Trees.redwoodLog.blockID);
         world.setBlock(x + 2, j + 35, z + 2, Trees.redwoodLeaves.blockID);
         world.setBlock(x + 3, j + 35, z + 4, Trees.redwoodLeaves.blockID);
         world.setBlock(x + 3, j + 35, z + 2, Trees.redwoodLeaves.blockID);
         world.setBlock(x + 3, j + 35, z + 1, Trees.redwoodLeaves.blockID);
         world.setBlock(x + 4, j + 35, z + 5, Trees.redwoodLeaves.blockID);
         world.setBlock(x + 4, j + 35, z + 4, Trees.redwoodLeaves.blockID);
         world.setBlock(x + 4, j + 35, z + 3, Trees.redwoodLeaves.blockID);
         world.setBlock(x + 4, j + 35, z + 2, Trees.redwoodLog.blockID);
         world.setBlock(x + 4, j + 35, z + 1, Trees.redwoodLeaves.blockID);
         world.setBlock(x + 5, j + 35, z + 6, Trees.redwoodLeaves.blockID);
         world.setBlock(x + 5, j + 35, z + 5, Trees.redwoodLog.blockID);
         world.setBlock(x + 5, j + 35, z + 4, Trees.redwoodLeaves.blockID);
         world.setBlock(x + 5, j + 35, z + 3, Trees.redwoodLeaves.blockID);
         world.setBlock(x + 5, j + 35, z + 2, Trees.redwoodLog.blockID);
         world.setBlock(x + 5, j + 35, z + 1, Trees.redwoodLeaves.blockID);
         world.setBlock(x + 6, j + 35, z + 5, Trees.redwoodLeaves.blockID);
         world.setBlock(x + 6, j + 35, z + 2, Trees.redwoodLeaves.blockID);
         world.setBlock(x + 3, j + 36, z + 3, Trees.redwoodLog.blockID);
         world.setBlock(x + 0, j + 36, z + 7, Trees.redwoodLeaves.blockID);
         world.setBlock(x + 0, j + 36, z + 6, Trees.redwoodLeaves.blockID);
         world.setBlock(x + 0, j + 36, z + 3, Trees.redwoodLeaves.blockID);
         world.setBlock(x + 0, j + 36, z + 2, Trees.redwoodLeaves.blockID);
         world.setBlock(x + 0, j + 36, z + 1, Trees.redwoodLeaves.blockID);
         world.setBlock(x + 1, j + 36, z + 6, Trees.redwoodLeaves.blockID);
         world.setBlock(x + 1, j + 36, z + 3, Trees.redwoodLeaves.blockID);
         world.setBlock(x + 1, j + 36, z + 2, Trees.redwoodLog.blockID);
         world.setBlock(x + 1, j + 36, z + 1, Trees.redwoodLog.blockID);
         world.setBlock(x + 1, j + 36, z + 0, Trees.redwoodLeaves.blockID);
         world.setBlock(x + 2, j + 36, z + 3, Trees.redwoodLeaves.blockID);
         world.setBlock(x + 2, j + 36, z + 2, Trees.redwoodLeaves.blockID);
         world.setBlock(x + 3, j + 36, z + 3, Trees.redwoodLeaves.blockID);
         world.setBlock(x + 4, j + 36, z + 2, Trees.redwoodLeaves.blockID);
         world.setBlock(x + 5, j + 36, z + 5, Trees.redwoodLeaves.blockID);
         world.setBlock(x + 5, j + 36, z + 4, Trees.redwoodLeaves.blockID);
         world.setBlock(x + 5, j + 36, z + 2, Trees.redwoodLeaves.blockID);
         world.setBlock(x + 5, j + 36, z + 1, Trees.redwoodLeaves.blockID);
         world.setBlock(x + 6, j + 36, z + 6, Trees.redwoodLeaves.blockID);
         world.setBlock(x + 6, j + 36, z + 5, Trees.redwoodLeaves.blockID);
         world.setBlock(x + 6, j + 36, z + 4, Trees.redwoodLeaves.blockID);
         world.setBlock(x + 6, j + 36, z + 1, Trees.redwoodLeaves.blockID);
         world.setBlock(x + 1, j + 37, z + 2, Trees.redwoodLeaves.blockID);
         world.setBlock(x + 1, j + 37, z + 2, Trees.redwoodLeaves.blockID);
         world.setBlock(x + 1, j + 37, z + 1, Trees.redwoodLeaves.blockID);
         world.setBlock(x + 6, j + 37, z + 6, Trees.redwoodLeaves.blockID);
         world.setBlock(x + 3, j + 37, z + 3, Trees.redwoodLog.blockID);
         world.setBlock(x + 3, j + 38, z + 3, Trees.redwoodLog.blockID);///This sets what your tree will look like
         world.setBlock(x + 3, j + 39, z + 3, Trees.redwoodLog.blockID);// You should make your own version
         world.setBlock(x + 3, j + 40, z + 3, Trees.redwoodLog.blockID);
         world.setBlock(x + 3, j + 41, z + 3, Trees.redwoodLog.blockID);
         world.setBlock(x + 3, j + 42, z + 3, Trees.redwoodLog.blockID);
         world.setBlock(x + 3, j + 43, z + 3, Trees.redwoodLog.blockID);
         world.setBlock(x + 2, j + 44, z + 3, Trees.redwoodLeaves.blockID);
         world.setBlock(x + 3, j + 44, z + 3, Trees.redwoodLog.blockID);
         world.setBlock(x + 4, j + 44, z + 3, Trees.redwoodLeaves.blockID);
         world.setBlock(x + 1, j + 45, z + 4, Trees.redwoodLeaves.blockID);
         world.setBlock(x + 1, j + 45, z + 3, Trees.redwoodLeaves.blockID);
         world.setBlock(x + 2, j + 45, z + 4, Trees.redwoodLeaves.blockID);
         world.setBlock(x + 2, j + 45, z + 3, Trees.redwoodLog.blockID);
         world.setBlock(x + 2, j + 45, z + 2, Trees.redwoodLeaves.blockID);
         world.setBlock(x + 3, j + 45, z + 4, Trees.redwoodLeaves.blockID);
         world.setBlock(x + 3, j + 45, z + 3, Trees.redwoodLog.blockID);
         world.setBlock(x + 4, j + 45, z + 4, Trees.redwoodLeaves.blockID);
         world.setBlock(x + 4, j + 45, z + 3, Trees.redwoodLog.blockID);
         world.setBlock(x + 4, j + 45, z + 2, Trees.redwoodLeaves.blockID);
         world.setBlock(x + 5, j + 45, z + 3, Trees.redwoodLeaves.blockID);
         world.setBlock(x + 0, j + 46, z + 5, Trees.redwoodLeaves.blockID);
         world.setBlock(x + 1, j + 46, z + 6, Trees.redwoodLeaves.blockID);
         world.setBlock(x + 1, j + 46, z + 5, Trees.redwoodLog.blockID);
         world.setBlock(x + 1, j + 46, z + 4, Trees.redwoodLog.blockID);
         world.setBlock(x + 1, j + 46, z + 3, Trees.redwoodLeaves.blockID);
         world.setBlock(x + 2, j + 46, z + 5, Trees.redwoodLeaves.blockID);
         world.setBlock(x + 2, j + 46, z + 4, Trees.redwoodLog.blockID);
         world.setBlock(x + 2, j + 46, z + 3, Trees.redwoodLeaves.blockID);
         world.setBlock(x + 2, j + 46, z + 2, Trees.redwoodLeaves.blockID);
         world.setBlock(x + 3, j + 46, z + 5, Trees.redwoodLeaves.blockID);
         world.setBlock(x + 3, j + 46, z + 4, Trees.redwoodLeaves.blockID);
         world.setBlock(x + 3, j + 46, z + 3, Trees.redwoodLeaves.blockID);
         world.setBlock(x + 3, j + 46, z + 2, Trees.redwoodLeaves.blockID);
         world.setBlock(x + 3, j + 46, z + 1, Trees.redwoodLeaves.blockID);
         world.setBlock(x + 4, j + 46, z + 5, Trees.redwoodLeaves.blockID);
         world.setBlock(x + 4, j + 46, z + 4, Trees.redwoodLog.blockID);
         world.setBlock(x + 4, j + 46, z + 3, Trees.redwoodLog.blockID);
         world.setBlock(x + 4, j + 46, z + 2, Trees.redwoodLeaves.blockID);
         world.setBlock(x + 5, j + 46, z + 5, Trees.redwoodLeaves.blockID);
         world.setBlock(x + 5, j + 46, z + 4, Trees.redwoodLeaves.blockID);
         world.setBlock(x + 5, j + 46, z + 3, Trees.redwoodLeaves.blockID);
         world.setBlock(x + 5, j + 46, z + 2, Trees.redwoodLeaves.blockID);
         world.setBlock(x + 0, j + 47, z + 6, Trees.redwoodLeaves.blockID);
         world.setBlock(x + 0, j + 47, z + 2, Trees.redwoodLeaves.blockID);
         world.setBlock(x + 1, j + 47, z + 7, Trees.redwoodLeaves.blockID);
         world.setBlock(x + 1, j + 47, z + 6, Trees.redwoodLog.blockID);
         world.setBlock(x + 1, j + 47, z + 5, Trees.redwoodLeaves.blockID);
         world.setBlock(x + 1, j + 47, z + 4, Trees.redwoodLeaves.blockID);
         world.setBlock(x + 1, j + 47, z + 3, Trees.redwoodLeaves.blockID);
         world.setBlock(x + 1, j + 47, z + 2, Trees.redwoodLog.blockID);
         world.setBlock(x + 1, j + 47, z + 1, Trees.redwoodLeaves.blockID);
         world.setBlock(x + 2, j + 47, z + 6, Trees.redwoodLeaves.blockID);
         world.setBlock(x + 2, j + 47, z + 5, Trees.redwoodLeaves.blockID);
         world.setBlock(x + 2, j + 47, z + 4, Trees.redwoodLeaves.blockID);
         world.setBlock(x + 2, j + 47, z + 3, Trees.redwoodLog.blockID);
         world.setBlock(x + 2, j + 47, z + 2, Trees.redwoodLeaves.blockID);
         world.setBlock(x + 3, j + 47, z + 4, Trees.redwoodLeaves.blockID);
         world.setBlock(x + 3, j + 47, z + 2, Trees.redwoodLeaves.blockID);
         world.setBlock(x + 3, j + 47, z + 1, Trees.redwoodLeaves.blockID);
         world.setBlock(x + 4, j + 47, z + 5, Trees.redwoodLeaves.blockID);
         world.setBlock(x + 4, j + 47, z + 4, Trees.redwoodLeaves.blockID);
         world.setBlock(x + 4, j + 47, z + 3, Trees.redwoodLeaves.blockID);
         world.setBlock(x + 4, j + 47, z + 2, Trees.redwoodLog.blockID);
         world.setBlock(x + 4, j + 47, z + 1, Trees.redwoodLeaves.blockID);
         world.setBlock(x + 5, j + 47, z + 6, Trees.redwoodLeaves.blockID);
         world.setBlock(x + 5, j + 47, z + 5, Trees.redwoodLog.blockID);
         world.setBlock(x + 5, j + 47, z + 4, Trees.redwoodLeaves.blockID);
         world.setBlock(x + 5, j + 47, z + 3, Trees.redwoodLeaves.blockID);
         world.setBlock(x + 5, j + 47, z + 2, Trees.redwoodLog.blockID);
         world.setBlock(x + 5, j + 47, z + 1, Trees.redwoodLeaves.blockID);
         world.setBlock(x + 6, j + 47, z + 5, Trees.redwoodLeaves.blockID);
         world.setBlock(x + 6, j + 47, z + 2, Trees.redwoodLeaves.blockID);
         world.setBlock(x + 0, j + 48, z + 7, Trees.redwoodLeaves.blockID);
         world.setBlock(x + 0, j + 48, z + 6, Trees.redwoodLeaves.blockID);
         world.setBlock(x + 0, j + 48, z + 3, Trees.redwoodLeaves.blockID);
         world.setBlock(x + 0, j + 48, z + 2, Trees.redwoodLeaves.blockID);
         world.setBlock(x + 0, j + 48, z + 1, Trees.redwoodLeaves.blockID);
         world.setBlock(x + 1, j + 48, z + 6, Trees.redwoodLeaves.blockID);
         world.setBlock(x + 1, j + 48, z + 3, Trees.redwoodLeaves.blockID);
         world.setBlock(x + 1, j + 48, z + 2, Trees.redwoodLog.blockID);
         world.setBlock(x + 1, j + 48, z + 1, Trees.redwoodLog.blockID);
         world.setBlock(x + 1, j + 48, z + 0, Trees.redwoodLeaves.blockID);
         world.setBlock(x + 2, j + 48, z + 3, Trees.redwoodLeaves.blockID);
         world.setBlock(x + 2, j + 48, z + 2, Trees.redwoodLeaves.blockID);
         world.setBlock(x + 3, j + 48, z + 3, Trees.redwoodLeaves.blockID);
         world.setBlock(x + 4, j + 48, z + 2, Trees.redwoodLeaves.blockID);
         world.setBlock(x + 5, j + 48, z + 5, Trees.redwoodLeaves.blockID);
         world.setBlock(x + 5, j + 48, z + 4, Trees.redwoodLeaves.blockID);
         world.setBlock(x + 5, j + 48, z + 2, Trees.redwoodLeaves.blockID);
         world.setBlock(x + 5, j + 48, z + 1, Trees.redwoodLeaves.blockID);
         world.setBlock(x + 6, j + 48, z + 6, Trees.redwoodLeaves.blockID);
         world.setBlock(x + 6, j + 48, z + 5, Trees.redwoodLeaves.blockID);
         world.setBlock(x + 6, j + 48, z + 4, Trees.redwoodLeaves.blockID);
         world.setBlock(x + 6, j + 48, z + 1, Trees.redwoodLeaves.blockID);
         world.setBlock(x + 1, j + 49, z + 2, Trees.redwoodLeaves.blockID);
         world.setBlock(x + 1, j + 49, z + 1, Trees.redwoodLeaves.blockID);
         world.setBlock(x + 6, j + 49, z + 6, Trees.redwoodLeaves.blockID);
         return true;
		}
}