package microjunk.trees.common.worldgentrees;

import java.util.Random;

import microjunk.trees.common.Trees;
import net.minecraft.block.Block;
import net.minecraft.world.World;
import net.minecraft.world.gen.feature.WorldGenerator;

public class WorldGenSquashTree extends WorldGenerator
{
    public WorldGenSquashTree()
    {
    }
    public boolean generate(World world, Random rand, int i, int j, int k)
    {
    	int j1 = world.getBlockId(i, j - 1, k);
		if(j1 != Block.grass.blockID && j1 != Block.dirt.blockID && j1 != Trees.alphaGrass.blockID || j >= 128 - 12 - 1)
        {
        	return false;
        }
		world.setBlock(i + 6, j + 0, k + 9, Trees.squashLog.blockID);
        world.setBlock(i + 6, j + 0, k + 8, Trees.squashLog.blockID);
        world.setBlock(i + 7, j + 0, k + 9, Trees.squashLog.blockID);
        world.setBlock(i + 7, j + 0, k + 8, Trees.squashLog.blockID);
        
        world.setBlock(i + 6, j + 1, k + 9, Trees.squashLog.blockID);
        world.setBlock(i + 6, j + 1, k + 8, Trees.squashLog.blockID);
        world.setBlock(i + 7, j + 1, k + 9, Trees.squashLog.blockID);
        world.setBlock(i + 7, j + 1, k + 8, Trees.squashLog.blockID);
        
        
        world.setBlock(i + 6, j + 2, k + 9, Trees.squashLog.blockID);
        world.setBlock(i + 6, j + 2, k + 8, Trees.squashLog.blockID);
        world.setBlock(i + 7, j + 2, k + 9, Trees.squashLog.blockID);
        world.setBlock(i + 7, j + 2, k + 8, Trees.squashLog.blockID);
        
        world.setBlock(i + 6, j + 3, k + 9, Trees.squashLog.blockID);
        world.setBlock(i + 6, j + 3, k + 8, Trees.squashLog.blockID);
        world.setBlock(i + 7, j + 3, k + 9, Trees.squashLog.blockID);
        world.setBlock(i + 7, j + 3, k + 8, Trees.squashLog.blockID);
        world.setBlock(i + 6, j + 4, k + 9, Trees.squashLog.blockID);
        world.setBlock(i + 6, j + 4, k + 8, Trees.squashLog.blockID);
        world.setBlock(i + 7, j + 4, k + 9, Trees.squashLog.blockID);
        world.setBlock(i + 7, j + 4, k + 8, Trees.squashLog.blockID);
        
        world.setBlock(i + 6, j + 5, k + 9, Trees.squashLog.blockID);
        world.setBlock(i + 7, j + 5, k + 9, Trees.squashLog.blockID);
        world.setBlock(i + 8, j + 5, k + 10, Trees.squashLog.blockID);
        world.setBlock(i + 8, j + 5, k + 9, Trees.squashLog.blockID);
        world.setBlock(i + 9, j + 5, k + 11, Trees.squashLeaves.blockID);
        world.setBlock(i + 10, j + 5, k + 11, Trees.squashLeaves.blockID);
        
        world.setBlock(i + 7, j + 6, k + 10, Trees.squashLeaves.blockID);
        world.setBlock(i + 7, j + 6, k + 9, Trees.squashLog.blockID);
        world.setBlock(i + 8, j + 6, k + 11, Trees.squashLeaves.blockID);
        world.setBlock(i + 8, j + 6, k + 10, Trees.squashLog.blockID);
        world.setBlock(i + 8, j + 6, k + 9, Trees.squashLog.blockID);
        world.setBlock(i + 8, j + 6, k + 8, Trees.squashLeaves.blockID);
        world.setBlock(i + 9, j + 6, k + 12, Trees.squashLeaves.blockID);
        world.setBlock(i + 9, j + 6, k + 11, Trees.squashLog.blockID);
        world.setBlock(i + 9, j + 6, k + 10, Trees.squashLog.blockID);
        world.setBlock(i + 9, j + 6, k + 9, Trees.squashLeaves.blockID);
        world.setBlock(i + 10, j + 6, k + 12, Trees.squashLeaves.blockID);
        world.setBlock(i + 10, j + 6, k + 11, Trees.squashLog.blockID);
        world.setBlock(i + 10, j + 6, k + 10, Trees.squashLeaves.blockID);
        world.setBlock(i + 11, j + 6, k + 12, Trees.squashLeaves.blockID);
        world.setBlock(i + 11, j + 6, k + 11, Trees.squashLeaves.blockID);
        
        world.setBlock(i + 3, j + 7, k + 11, Trees.squashLeaves.blockID);
        world.setBlock(i + 4, j + 7, k + 12, Trees.squashLeaves.blockID);
        world.setBlock(i + 4, j + 7, k + 11, Trees.squashLeaves.blockID);
        world.setBlock(i + 4, j + 7, k + 10, Trees.squashLeaves.blockID);
        world.setBlock(i + 5, j + 7, k + 11, Trees.squashLeaves.blockID);
        world.setBlock(i + 5, j + 7, k + 10, Trees.squashLeaves.blockID);
        world.setBlock(i + 5, j + 7, k + 9, Trees.squashLeaves.blockID);
        world.setBlock(i + 6, j + 7, k + 11, Trees.squashLeaves.blockID);
        world.setBlock(i + 6, j + 7, k + 10, Trees.squashLeaves.blockID);
        world.setBlock(i + 6, j + 7, k + 9, Trees.squashLog.blockID);
        world.setBlock(i + 6, j + 7, k + 8, Trees.squashLeaves.blockID);
        world.setBlock(i + 7, j + 7, k + 11, Trees.squashLeaves.blockID);
        world.setBlock(i + 7, j + 7, k + 10, Trees.squashLeaves.blockID);
        world.setBlock(i + 7, j + 7, k + 9, Trees.squashLog.blockID);
        world.setBlock(i + 7, j + 7, k + 8, Trees.squashLeaves.blockID);
        world.setBlock(i + 8, j + 7, k + 12, Trees.squashLeaves.blockID);
        world.setBlock(i + 8, j + 7, k + 11, Trees.squashLeaves.blockID);
        world.setBlock(i + 8, j + 7, k + 10, Trees.squashLeaves.blockID);
        world.setBlock(i + 8, j + 7, k + 9, Trees.squashLeaves.blockID);
        world.setBlock(i + 8, j + 7, k + 8, Trees.squashLeaves.blockID);
        world.setBlock(i + 8, j + 7, k + 7, Trees.squashLeaves.blockID);
        world.setBlock(i + 8, j + 7, k + 6, Trees.squashLeaves.blockID);
        world.setBlock(i + 9, j + 7, k + 13, Trees.squashLeaves.blockID);
        world.setBlock(i + 9, j + 7, k + 12, Trees.squashLeaves.blockID);
        world.setBlock(i + 9, j + 7, k + 11, Trees.squashLeaves.blockID);
        world.setBlock(i + 9, j + 7, k + 10, Trees.squashLeaves.blockID);
        world.setBlock(i + 9, j + 7, k + 9, Trees.squashLeaves.blockID);
        world.setBlock(i + 9, j + 7, k + 8, Trees.squashLeaves.blockID);
        world.setBlock(i + 9, j + 7, k + 7, Trees.squashLeaves.blockID);
        world.setBlock(i + 9, j + 7, k + 6, Trees.squashLeaves.blockID);
        world.setBlock(i + 10, j + 7, k + 13, Trees.squashLeaves.blockID);
        world.setBlock(i + 10, j + 7, k + 12, Trees.squashLog.blockID);
        world.setBlock(i + 10, j + 7, k + 11, Trees.squashLeaves.blockID);
        world.setBlock(i + 10, j + 7, k + 10, Trees.squashLeaves.blockID);
        world.setBlock(i + 10, j + 7, k + 9, Trees.squashLeaves.blockID);
        world.setBlock(i + 11, j + 7, k + 13, Trees.squashLeaves.blockID);
        world.setBlock(i + 11, j + 7, k + 12, Trees.squashLog.blockID);
        world.setBlock(i + 11, j + 7, k + 11, Trees.squashLeaves.blockID);
        world.setBlock(i + 11, j + 7, k + 10, Trees.squashLeaves.blockID);
        world.setBlock(i + 12, j + 7, k + 13, Trees.squashLeaves.blockID);
        world.setBlock(i + 12, j + 7, k + 12, Trees.squashLeaves.blockID);
        world.setBlock(i + 12, j + 7, k + 11, Trees.squashLeaves.blockID);
        
        world.setBlock(i + 2, j + 8, k + 11, Trees.squashLeaves.blockID);
        world.setBlock(i + 2, j + 8, k + 10, Trees.squashLeaves.blockID);
        world.setBlock(i + 3, j + 8, k + 12, Trees.squashLeaves.blockID);
        world.setBlock(i + 3, j + 8, k + 11, Trees.squashLeaves.blockID);
        world.setBlock(i + 3, j + 8, k + 10, Trees.squashLeaves.blockID);
        world.setBlock(i + 3, j + 8, k + 9, Trees.squashLeaves.blockID);
        world.setBlock(i + 4, j + 8, k + 13, Trees.squashLeaves.blockID);
        world.setBlock(i + 4, j + 8, k + 12, Trees.squashLeaves.blockID);
        world.setBlock(i + 4, j + 8, k + 11, Trees.squashLog.blockID);
        world.setBlock(i + 4, j + 8, k + 10, Trees.squashLeaves.blockID);
        world.setBlock(i + 4, j + 8, k + 9, Trees.squashLeaves.blockID);
        world.setBlock(i + 4, j + 8, k + 8, Trees.squashLeaves.blockID);
        world.setBlock(i + 5, j + 8, k + 12, Trees.squashLeaves.blockID);
        world.setBlock(i + 5, j + 8, k + 11, Trees.squashLog.blockID);
        world.setBlock(i + 5, j + 8, k + 10, Trees.squashLog.blockID);
        world.setBlock(i + 5, j + 8, k + 9, Trees.squashLog.blockID);
        world.setBlock(i + 5, j + 8, k + 8, Trees.squashLeaves.blockID);
        world.setBlock(i + 5, j + 8, k + 7, Trees.squashLeaves.blockID);
        world.setBlock(i + 6, j + 8, k + 11, Trees.squashLeaves.blockID);
        world.setBlock(i + 6, j + 8, k + 10, Trees.squashLog.blockID);
        world.setBlock(i + 6, j + 8, k + 9, Trees.squashLog.blockID);
        world.setBlock(i + 6, j + 8, k + 8, Trees.squashLeaves.blockID);
        world.setBlock(i + 6, j + 8, k + 7, Trees.squashLeaves.blockID);
        world.setBlock(i + 7, j + 8, k + 12, Trees.squashLeaves.blockID);
        world.setBlock(i + 7, j + 8, k + 11, Trees.squashLeaves.blockID);
        world.setBlock(i + 7, j + 8, k + 10, Trees.squashLeaves.blockID);
        world.setBlock(i + 7, j + 8, k + 9, Trees.squashLog.blockID);
        world.setBlock(i + 7, j + 8, k + 8, Trees.squashLog.blockID);
        world.setBlock(i + 7, j + 8, k + 7, Trees.squashLeaves.blockID);
        world.setBlock(i + 7, j + 8, k + 6, Trees.squashLeaves.blockID);
        world.setBlock(i + 8, j + 8, k + 13, Trees.squashLeaves.blockID);
        world.setBlock(i + 8, j + 8, k + 12, Trees.squashLeaves.blockID);
        world.setBlock(i + 8, j + 8, k + 11, Trees.squashLeaves.blockID);
        world.setBlock(i + 8, j + 8, k + 10, Trees.squashLeaves.blockID);
        world.setBlock(i + 8, j + 8, k + 9, Trees.squashLeaves.blockID);
        world.setBlock(i + 8, j + 8, k + 8, Trees.squashLog.blockID);
        world.setBlock(i + 8, j + 8, k + 7, Trees.squashLog.blockID);
        world.setBlock(i + 8, j + 8, k + 6, Trees.squashLog.blockID);
        world.setBlock(i + 8, j + 8, k + 5, Trees.squashLeaves.blockID);
        world.setBlock(i + 9, j + 8, k + 14, Trees.squashLeaves.blockID);
        world.setBlock(i + 9, j + 8, k + 13, Trees.squashLeaves.blockID);
        world.setBlock(i + 9, j + 8, k + 12, Trees.squashLeaves.blockID);
        world.setBlock(i + 9, j + 8, k + 11, Trees.squashLeaves.blockID);
        world.setBlock(i + 9, j + 8, k + 9, Trees.squashLeaves.blockID);
        world.setBlock(i + 9, j + 8, k + 8, Trees.squashLeaves.blockID);
        world.setBlock(i + 9, j + 8, k + 7, Trees.squashLeaves.blockID);
        world.setBlock(i + 9, j + 8, k + 6, Trees.squashLeaves.blockID);
        world.setBlock(i + 9, j + 8, k + 5, Trees.squashLeaves.blockID);
        world.setBlock(i + 9, j + 8, k + 4, Trees.squashLeaves.blockID);
        world.setBlock(i + 10, j + 8, k + 14, Trees.squashLeaves.blockID);
        world.setBlock(i + 10, j + 8, k + 13, Trees.squashLeaves.blockID);
        world.setBlock(i + 10, j + 8, k + 12, Trees.squashLeaves.blockID);
        world.setBlock(i + 10, j + 8, k + 11, Trees.squashLeaves.blockID);
        world.setBlock(i + 10, j + 8, k + 10, Trees.squashLeaves.blockID);
        world.setBlock(i + 10, j + 8, k + 9, Trees.squashLeaves.blockID);
        world.setBlock(i + 10, j + 8, k + 8, Trees.squashLeaves.blockID);
        world.setBlock(i + 10, j + 8, k + 7, Trees.squashLeaves.blockID);
        world.setBlock(i + 10, j + 8, k + 6, Trees.squashLeaves.blockID);
        world.setBlock(i + 10, j + 8, k + 5, Trees.squashLeaves.blockID);
        world.setBlock(i + 10, j + 8, k + 4, Trees.squashLeaves.blockID);
        world.setBlock(i + 11, j + 8, k + 14, Trees.squashLeaves.blockID);
        world.setBlock(i + 11, j + 8, k + 13, Trees.squashLeaves.blockID);
        world.setBlock(i + 11, j + 8, k + 12, Trees.squashLeaves.blockID);
        world.setBlock(i + 11, j + 8, k + 11, Trees.squashLeaves.blockID);
        world.setBlock(i + 11, j + 8, k + 10, Trees.squashLeaves.blockID);
        world.setBlock(i + 11, j + 8, k + 9, Trees.squashLeaves.blockID);
        world.setBlock(i + 12, j + 8, k + 13, Trees.squashLeaves.blockID);
        world.setBlock(i + 12, j + 8, k + 12, Trees.squashLeaves.blockID);
        world.setBlock(i + 12, j + 8, k + 11, Trees.squashLeaves.blockID);
        world.setBlock(i + 12, j + 8, k + 10, Trees.squashLeaves.blockID);
        world.setBlock(i + 13, j + 8, k + 12, Trees.squashLeaves.blockID);
        world.setBlock(i + 13, j + 8, k + 11, Trees.squashLeaves.blockID);
        world.setBlock(i + 2, j + 9, k + 12, Trees.squashLeaves.blockID);
        world.setBlock(i + 2, j + 9, k + 11, Trees.squashLeaves.blockID);
        world.setBlock(i + 2, j + 9, k + 10, Trees.squashLeaves.blockID);
        world.setBlock(i + 2, j + 9, k + 9, Trees.squashLeaves.blockID);
        world.setBlock(i + 3, j + 9, k + 13, Trees.squashLeaves.blockID);
        world.setBlock(i + 3, j + 9, k + 12, Trees.squashLeaves.blockID);
        world.setBlock(i + 3, j + 9, k + 11, Trees.squashLog.blockID);
        world.setBlock(i + 3, j + 9, k + 10, Trees.squashLeaves.blockID);
        world.setBlock(i + 3, j + 9, k + 9, Trees.squashLeaves.blockID);
        world.setBlock(i + 3, j + 9, k + 8, Trees.squashLeaves.blockID);
        world.setBlock(i + 4, j + 9, k + 13, Trees.squashLeaves.blockID);
        world.setBlock(i + 4, j + 9, k + 12, Trees.squashLeaves.blockID);
        world.setBlock(i + 4, j + 9, k + 11, Trees.squashLog.blockID);
        world.setBlock(i + 4, j + 9, k + 10, Trees.squashLeaves.blockID);
        world.setBlock(i + 4, j + 9, k + 9, Trees.squashLeaves.blockID);
        world.setBlock(i + 4, j + 9, k + 8, Trees.squashLeaves.blockID);
        world.setBlock(i + 4, j + 9, k + 7, Trees.squashLeaves.blockID);
        world.setBlock(i + 5, j + 9, k + 13, Trees.squashLeaves.blockID);
        world.setBlock(i + 5, j + 9, k + 12, Trees.squashLeaves.blockID);
        world.setBlock(i + 5, j + 9, k + 11, Trees.squashLeaves.blockID);
        world.setBlock(i + 5, j + 9, k + 10, Trees.squashLeaves.blockID);
        world.setBlock(i + 5, j + 9, k + 9, Trees.squashLeaves.blockID);
        world.setBlock(i + 5, j + 9, k + 8, Trees.squashLeaves.blockID);
        world.setBlock(i + 5, j + 9, k + 7, Trees.squashLeaves.blockID);
        world.setBlock(i + 6, j + 9, k + 12, Trees.squashLeaves.blockID);
        world.setBlock(i + 6, j + 9, k + 11, Trees.squashLeaves.blockID);
        world.setBlock(i + 6, j + 9, k + 10, Trees.squashLeaves.blockID);
        world.setBlock(i + 6, j + 9, k + 9, Trees.squashLeaves.blockID);
        world.setBlock(i + 6, j + 9, k + 8, Trees.squashLeaves.blockID);
        world.setBlock(i + 6, j + 9, k + 7, Trees.squashLeaves.blockID);
        world.setBlock(i + 6, j + 9, k + 6, Trees.squashLeaves.blockID);
        world.setBlock(i + 7, j + 9, k + 10, Trees.squashLeaves.blockID);
        world.setBlock(i + 7, j + 9, k + 9, Trees.squashLeaves.blockID);
        world.setBlock(i + 7, j + 9, k + 8, Trees.squashLeaves.blockID);
        world.setBlock(i + 7, j + 9, k + 7, Trees.squashLeaves.blockID);
        world.setBlock(i + 7, j + 9, k + 6, Trees.squashLeaves.blockID);
        world.setBlock(i + 7, j + 9, k + 5, Trees.squashLeaves.blockID);
        world.setBlock(i + 8, j + 9, k + 11, Trees.squashLeaves.blockID);
        world.setBlock(i + 8, j + 9, k + 10, Trees.squashLeaves.blockID);
        world.setBlock(i + 8, j + 9, k + 9, Trees.squashLeaves.blockID);
        world.setBlock(i + 8, j + 9, k + 8, Trees.squashLeaves.blockID);
        world.setBlock(i + 8, j + 9, k + 7, Trees.squashLeaves.blockID);
        world.setBlock(i + 8, j + 9, k + 6, Trees.squashLog.blockID);
        world.setBlock(i + 8, j + 9, k + 5, Trees.squashLeaves.blockID);
        world.setBlock(i + 8, j + 9, k + 4, Trees.squashLeaves.blockID);
        world.setBlock(i + 9, j + 9, k + 12, Trees.squashLeaves.blockID);
        world.setBlock(i + 9, j + 9, k + 11, Trees.squashLeaves.blockID);
        world.setBlock(i + 9, j + 9, k + 10, Trees.squashLeaves.blockID);
        world.setBlock(i + 9, j + 9, k + 9, Trees.squashLeaves.blockID);
        world.setBlock(i + 9, j + 9, k + 8, Trees.squashLeaves.blockID);
        world.setBlock(i + 9, j + 9, k + 7, Trees.squashLeaves.blockID);
        world.setBlock(i + 9, j + 9, k + 6, Trees.squashLog.blockID);
        world.setBlock(i + 9, j + 9, k + 5, Trees.squashLog.blockID);
        world.setBlock(i + 9, j + 9, k + 4, Trees.squashLog.blockID);
        world.setBlock(i + 9, j + 9, k + 3, Trees.squashLeaves.blockID);
        world.setBlock(i + 10, j + 9, k + 13, Trees.squashLeaves.blockID);
        world.setBlock(i + 10, j + 9, k + 12, Trees.squashLeaves.blockID);
        world.setBlock(i + 10, j + 9, k + 11, Trees.squashLeaves.blockID);
        world.setBlock(i + 10, j + 9, k + 10, Trees.squashLeaves.blockID);
        world.setBlock(i + 10, j + 9, k + 9, Trees.squashLeaves.blockID);
        world.setBlock(i + 10, j + 9, k + 8, Trees.squashLeaves.blockID);
        world.setBlock(i + 10, j + 9, k + 6, Trees.squashLeaves.blockID);
        world.setBlock(i + 10, j + 9, k + 5, Trees.squashLeaves.blockID);
        world.setBlock(i + 10, j + 9, k + 4, Trees.squashLog.blockID);
        world.setBlock(i + 10, j + 9, k + 3, Trees.squashLeaves.blockID);
        world.setBlock(i + 11, j + 9, k + 13, Trees.squashLeaves.blockID);
        world.setBlock(i + 11, j + 9, k + 12, Trees.squashLeaves.blockID);
        world.setBlock(i + 11, j + 9, k + 11, Trees.squashLeaves.blockID);
        world.setBlock(i + 11, j + 9, k + 10, Trees.squashLeaves.blockID);
        world.setBlock(i + 11, j + 9, k + 6, Trees.squashLeaves.blockID);
        world.setBlock(i + 11, j + 9, k + 5, Trees.squashLeaves.blockID);
        world.setBlock(i + 11, j + 9, k + 4, Trees.squashLeaves.blockID);
        world.setBlock(i + 12, j + 9, k + 12, Trees.squashLeaves.blockID);
        world.setBlock(i + 12, j + 9, k + 11, Trees.squashLeaves.blockID);
        world.setBlock(i + 3, j + 10, k + 12, Trees.squashLeaves.blockID);
        world.setBlock(i + 3, j + 10, k + 11, Trees.squashLeaves.blockID);
        world.setBlock(i + 4, j + 10, k + 12, Trees.squashLeaves.blockID);
        world.setBlock(i + 4, j + 10, k + 11, Trees.squashLeaves.blockID);
        world.setBlock(i + 4, j + 10, k + 10, Trees.squashLeaves.blockID);
        world.setBlock(i + 4, j + 10, k + 9, Trees.squashLeaves.blockID);
        world.setBlock(i + 5, j + 10, k + 11, Trees.squashLeaves.blockID);
        world.setBlock(i + 5, j + 10, k + 10, Trees.squashLeaves.blockID);
        world.setBlock(i + 5, j + 10, k + 9, Trees.squashLeaves.blockID);
        world.setBlock(i + 5, j + 10, k + 8, Trees.squashLeaves.blockID);
        world.setBlock(i + 6, j + 10, k + 10, Trees.squashLeaves.blockID);
        world.setBlock(i + 6, j + 10, k + 9, Trees.squashLeaves.blockID);
        world.setBlock(i + 6, j + 10, k + 8, Trees.squashLeaves.blockID);
        world.setBlock(i + 6, j + 10, k + 7, Trees.squashLeaves.blockID);
        world.setBlock(i + 7, j + 10, k + 9, Trees.squashLeaves.blockID);
        world.setBlock(i + 7, j + 10, k + 8, Trees.squashLeaves.blockID);
        world.setBlock(i + 7, j + 10, k + 7, Trees.squashLeaves.blockID);
        world.setBlock(i + 7, j + 10, k + 6, Trees.squashLeaves.blockID);
        world.setBlock(i + 8, j + 10, k + 10, Trees.squashLeaves.blockID);
        world.setBlock(i + 8, j + 10, k + 9, Trees.squashLeaves.blockID);
        world.setBlock(i + 8, j + 10, k + 8, Trees.squashLeaves.blockID);
        world.setBlock(i + 8, j + 10, k + 7, Trees.squashLeaves.blockID);
        world.setBlock(i + 8, j + 10, k + 6, Trees.squashLeaves.blockID);
        world.setBlock(i + 8, j + 10, k + 5, Trees.squashLeaves.blockID);
        world.setBlock(i + 9, j + 10, k + 10, Trees.squashLeaves.blockID);
        world.setBlock(i + 9, j + 10, k + 9, Trees.squashLeaves.blockID);
        world.setBlock(i + 9, j + 10, k + 8, Trees.squashLeaves.blockID);
        world.setBlock(i + 9, j + 10, k + 6, Trees.squashLeaves.blockID);
        world.setBlock(i + 9, j + 10, k + 5, Trees.squashLeaves.blockID);
        world.setBlock(i + 9, j + 10, k + 4, Trees.squashLeaves.blockID);
        world.setBlock(i + 10, j + 10, k + 12, Trees.squashLeaves.blockID);
        world.setBlock(i + 10, j + 10, k + 11, Trees.squashLeaves.blockID);
        world.setBlock(i + 10, j + 10, k + 10, Trees.squashLeaves.blockID);
        world.setBlock(i + 10, j + 10, k + 5, Trees.squashLeaves.blockID);
        world.setBlock(i + 10, j + 10, k + 4, Trees.squashLeaves.blockID);
        world.setBlock(i + 11, j + 10, k + 12, Trees.squashLeaves.blockID);
        world.setBlock(i + 11, j + 10, k + 11, Trees.squashLeaves.blockID);
        world.setBlock(i + 5, j + 11, k + 10, Trees.squashLeaves.blockID);
        world.setBlock(i + 5, j + 11, k + 9, Trees.squashLeaves.blockID);
        world.setBlock(i + 6, j + 11, k + 9, Trees.squashLeaves.blockID);
        world.setBlock(i + 6, j + 11, k + 8, Trees.squashLeaves.blockID);
        world.setBlock(i + 7, j + 11, k + 8, Trees.squashLeaves.blockID);
        world.setBlock(i + 7, j + 11, k + 7, Trees.squashLeaves.blockID);
        world.setBlock(i + 8, j + 11, k + 9, Trees.squashLeaves.blockID);
        world.setBlock(i + 8, j + 11, k + 8, Trees.squashLeaves.blockID);
        world.setBlock(i + 8, j + 11, k + 6, Trees.squashLeaves.blockID);
        world.setBlock(i + 9, j + 11, k + 5, Trees.squashLeaves.blockID);

return true;
}
} /*=====End of Code=====*/
