package microjunk.trees.common.worldgentrees;

import java.util.Random;

import microjunk.trees.common.Trees;
import net.minecraft.block.Block;
import net.minecraft.world.World;
import net.minecraft.world.gen.feature.WorldGenerator;

public class WorldGenCantaloupeTree extends WorldGenerator
{
    public WorldGenCantaloupeTree()
    {
    }
    public boolean generate(World world, Random rand, int i, int j, int k)
    {
    	int j1 = world.getBlockId(i, j - 1, k);
		if(j1 != Block.grass.blockID && j1 != Block.dirt.blockID && j1 != Trees.alphaGrass.blockID || j >= 128 - 12 - 1)
        {
        	return false;
        }
		world.setBlock(i + 6, j + 0, k + 4, Trees.cantaloupeLog.blockID);
        world.setBlock(i + 7, j + 0, k + 5, Trees.cantaloupeLog.blockID);
        world.setBlock(i + 7, j + 0, k + 4, Trees.cantaloupeLog.blockID);
        world.setBlock(i + 8, j + 0, k + 6, Trees.cantaloupeLog.blockID);
        world.setBlock(i + 8, j + 0, k + 5, Trees.cantaloupeLog.blockID);
        world.setBlock(i + 8, j + 0, k + 4, Trees.cantaloupeLog.blockID);
        world.setBlock(i + 8, j + 0, k + 3, Trees.cantaloupeLog.blockID);
        world.setBlock(i + 9, j + 0, k + 5, Trees.cantaloupeLog.blockID);
        world.setBlock(i + 9, j + 0, k + 4, Trees.cantaloupeLog.blockID);
        world.setBlock(i + 9, j + 0, k + 3, Trees.cantaloupeLog.blockID);
        world.setBlock(i + 10, j + 0, k + 4, Trees.cantaloupeLog.blockID);
        
        world.setBlock(i + 7, j + 1, k + 4, Trees.cantaloupeLog.blockID);
        world.setBlock(i + 8, j + 1, k + 5, Trees.cantaloupeLog.blockID);
        world.setBlock(i + 8, j + 1, k + 4, Trees.cantaloupeLog.blockID);
        world.setBlock(i + 9, j + 1, k + 4, Trees.cantaloupeLog.blockID);
        
        world.setBlock(i + 8, j + 2, k + 4, Trees.cantaloupeLog.blockID);
        world.setBlock(i + 9, j + 2, k + 4, Trees.cantaloupeLog.blockID);
        
        world.setBlock(i + 8, j + 3, k + 4, Trees.cantaloupeLog.blockID);
        
        world.setBlock(i + 8, j + 4, k + 4, Trees.cantaloupeLog.blockID);
        
        world.setBlock(i + 5, j + 4, k + 8, Trees.cantaloupeLeaves.blockID);
        world.setBlock(i + 6, j + 4, k + 8, Trees.cantaloupeLeaves.blockID);
        world.setBlock(i + 6, j + 4, k + 7, Trees.cantaloupeLeaves.blockID);
        world.setBlock(i + 8, j + 4, k + 4, Trees.cantaloupeLog.blockID);
        world.setBlock(i + 9, j + 4, k + 4, Trees.cantaloupeLog.blockID);
        world.setBlock(i + 10, j + 4, k + 5, Trees.cantaloupeLeaves.blockID);
        world.setBlock(i + 10, j + 4, k + 4, Trees.cantaloupeLog.blockID);
        world.setBlock(i + 11, j + 4, k + 6, Trees.cantaloupeLeaves.blockID);
        world.setBlock(i + 11, j + 4, k + 5, Trees.cantaloupeLog.blockID);
        world.setBlock(i + 11, j + 4, k + 4, Trees.cantaloupeLog.blockID);
        world.setBlock(i + 12, j + 4, k + 6, Trees.cantaloupeLeaves.blockID);
        world.setBlock(i + 12, j + 4, k + 5, Trees.cantaloupeLeaves.blockID);
        
        world.setBlock(i + 3, j + 5, k + 10, Trees.cantaloupeLeaves.blockID);
        world.setBlock(i + 3, j + 5, k + 9, Trees.cantaloupeLeaves.blockID);
        world.setBlock(i + 4, j + 5, k + 10, Trees.cantaloupeLeaves.blockID);
        world.setBlock(i + 4, j + 5, k + 9, Trees.cantaloupeLeaves.blockID);
        world.setBlock(i + 4, j + 5, k + 8, Trees.cantaloupeLeaves.blockID);
        world.setBlock(i + 4, j + 5, k + 7, Trees.cantaloupeLeaves.blockID);
        world.setBlock(i + 5, j + 5, k + 9, Trees.cantaloupeLeaves.blockID);
        world.setBlock(i + 5, j + 5, k + 8, Trees.cantaloupeLog.blockID);
        world.setBlock(i + 5, j + 5, k + 7, Trees.cantaloupeLeaves.blockID);
        world.setBlock(i + 5, j + 5, k + 6, Trees.cantaloupeLeaves.blockID);
        world.setBlock(i + 6, j + 5, k + 9, Trees.cantaloupeLeaves.blockID);
        world.setBlock(i + 6, j + 5, k + 8, Trees.cantaloupeLog.blockID);
        world.setBlock(i + 6, j + 5, k + 7, Trees.cantaloupeLog.blockID);
        world.setBlock(i + 6, j + 5, k + 6, Trees.cantaloupeLeaves.blockID);
        world.setBlock(i + 6, j + 5, k + 5, Trees.cantaloupeLeaves.blockID);
        world.setBlock(i + 6, j + 5, k + 4, Trees.cantaloupeLeaves.blockID);
        world.setBlock(i + 7, j + 5, k + 8, Trees.cantaloupeLeaves.blockID);
        world.setBlock(i + 7, j + 5, k + 7, Trees.cantaloupeLeaves.blockID);
        world.setBlock(i + 7, j + 5, k + 6, Trees.cantaloupeLeaves.blockID);
        world.setBlock(i + 7, j + 5, k + 5, Trees.cantaloupeLog.blockID);
        world.setBlock(i + 7, j + 5, k + 4, Trees.cantaloupeLeaves.blockID);
        world.setBlock(i + 7, j + 5, k + 3, Trees.cantaloupeLeaves.blockID);
        world.setBlock(i + 8, j + 5, k + 5, Trees.cantaloupeLog.blockID);
        world.setBlock(i + 8, j + 5, k + 4, Trees.cantaloupeLog.blockID);
        world.setBlock(i + 8, j + 5, k + 3, Trees.cantaloupeLog.blockID);
        world.setBlock(i + 8, j + 5, k + 2, Trees.cantaloupeLeaves.blockID);
        world.setBlock(i + 9, j + 5, k + 4, Trees.cantaloupeLog.blockID);
        world.setBlock(i + 9, j + 5, k + 3, Trees.cantaloupeLeaves.blockID);
        world.setBlock(i + 10, j + 5, k + 5, Trees.cantaloupeLeaves.blockID);
        world.setBlock(i + 10, j + 5, k + 4, Trees.cantaloupeLeaves.blockID);
        world.setBlock(i + 11, j + 5, k + 7, Trees.cantaloupeLeaves.blockID);
        world.setBlock(i + 11, j + 5, k + 6, Trees.cantaloupeLeaves.blockID);
        world.setBlock(i + 11, j + 5, k + 5, Trees.cantaloupeLog.blockID);
        world.setBlock(i + 11, j + 5, k + 4, Trees.cantaloupeLeaves.blockID);
        world.setBlock(i + 12, j + 5, k + 8, Trees.cantaloupeLeaves.blockID);
        world.setBlock(i + 12, j + 5, k + 7, Trees.cantaloupeLeaves.blockID);
        world.setBlock(i + 12, j + 5, k + 6, Trees.cantaloupeLog.blockID);
        world.setBlock(i + 12, j + 5, k + 5, Trees.cantaloupeLog.blockID);
        world.setBlock(i + 12, j + 5, k + 4, Trees.cantaloupeLeaves.blockID);
        world.setBlock(i + 13, j + 5, k + 7, Trees.cantaloupeLeaves.blockID);
        world.setBlock(i + 13, j + 5, k + 6, Trees.cantaloupeLeaves.blockID);
        world.setBlock(i + 13, j + 5, k + 5, Trees.cantaloupeLeaves.blockID);
        
        world.setBlock(i + 2, j + 6, k + 10, Trees.cantaloupeLeaves.blockID);
        world.setBlock(i + 2, j + 6, k + 9, Trees.cantaloupeLeaves.blockID);
        world.setBlock(i + 3, j + 6, k + 11, Trees.cantaloupeLeaves.blockID);
        world.setBlock(i + 3, j + 6, k + 10, Trees.cantaloupeLeaves.blockID);
        world.setBlock(i + 3, j + 6, k + 9, Trees.cantaloupeLeaves.blockID);
        world.setBlock(i + 3, j + 6, k + 8, Trees.cantaloupeLeaves.blockID);
        world.setBlock(i + 3, j + 6, k + 7, Trees.cantaloupeLeaves.blockID);
        world.setBlock(i + 4, j + 6, k + 10, Trees.cantaloupeLeaves.blockID);
        world.setBlock(i + 4, j + 6, k + 9, Trees.cantaloupeLeaves.blockID);
        world.setBlock(i + 4, j + 6, k + 8, Trees.cantaloupeLeaves.blockID);
        world.setBlock(i + 4, j + 6, k + 7, Trees.cantaloupeLeaves.blockID);
        world.setBlock(i + 4, j + 6, k + 6, Trees.cantaloupeLeaves.blockID);
        world.setBlock(i + 5, j + 6, k + 10, Trees.cantaloupeLeaves.blockID);
        world.setBlock(i + 5, j + 6, k + 9, Trees.cantaloupeLeaves.blockID);
        world.setBlock(i + 5, j + 6, k + 8, Trees.cantaloupeLeaves.blockID);
        world.setBlock(i + 5, j + 6, k + 7, Trees.cantaloupeLeaves.blockID);
        world.setBlock(i + 5, j + 6, k + 6, Trees.cantaloupeLeaves.blockID);
        world.setBlock(i + 5, j + 6, k + 5, Trees.cantaloupeLeaves.blockID);
        world.setBlock(i + 6, j + 6, k + 10, Trees.cantaloupeLeaves.blockID);
        world.setBlock(i + 6, j + 6, k + 9, Trees.cantaloupeLeaves.blockID);
        world.setBlock(i + 6, j + 6, k + 8, Trees.cantaloupeLeaves.blockID);
        world.setBlock(i + 6, j + 6, k + 7, Trees.cantaloupeLog.blockID);
        world.setBlock(i + 6, j + 6, k + 6, Trees.cantaloupeLog.blockID);
        world.setBlock(i + 6, j + 6, k + 5, Trees.cantaloupeLeaves.blockID);
        world.setBlock(i + 6, j + 6, k + 4, Trees.cantaloupeLeaves.blockID);
        world.setBlock(i + 6, j + 6, k + 3, Trees.cantaloupeLeaves.blockID);
        world.setBlock(i + 7, j + 6, k + 9, Trees.cantaloupeLeaves.blockID);
        world.setBlock(i + 7, j + 6, k + 8, Trees.cantaloupeLeaves.blockID);
        world.setBlock(i + 7, j + 6, k + 7, Trees.cantaloupeLeaves.blockID);
        world.setBlock(i + 7, j + 6, k + 6, Trees.cantaloupeLog.blockID);
        world.setBlock(i + 7, j + 6, k + 5, Trees.cantaloupeLog.blockID);
        world.setBlock(i + 7, j + 6, k + 4, Trees.cantaloupeLog.blockID);
        world.setBlock(i + 7, j + 6, k + 3, Trees.cantaloupeLeaves.blockID);
        world.setBlock(i + 7, j + 6, k + 2, Trees.cantaloupeLeaves.blockID);
        world.setBlock(i + 8, j + 6, k + 8, Trees.cantaloupeLeaves.blockID);
        world.setBlock(i + 8, j + 6, k + 7, Trees.cantaloupeLeaves.blockID);
        world.setBlock(i + 8, j + 6, k + 4, Trees.cantaloupeLog.blockID);
        world.setBlock(i + 8, j + 6, k + 3, Trees.cantaloupeLog.blockID);
        world.setBlock(i + 8, j + 6, k + 2, Trees.cantaloupeLog.blockID);
        world.setBlock(i + 8, j + 6, k + 1, Trees.cantaloupeLeaves.blockID);
         world.setBlock(i + 9, j + 6, k + 6, Trees.cantaloupeLeaves.blockID);
        world.setBlock(i + 9, j + 6, k + 5, Trees.cantaloupeLog.blockID);
        world.setBlock(i + 9, j + 6, k + 4, Trees.cantaloupeLeaves.blockID);
        world.setBlock(i + 9, j + 6, k + 3, Trees.cantaloupeLeaves.blockID);
        world.setBlock(i + 9, j + 6, k + 2, Trees.cantaloupeLog.blockID);
        world.setBlock(i + 9, j + 6, k + 1, Trees.cantaloupeLeaves.blockID);
        world.setBlock(i + 10, j + 6, k + 7, Trees.cantaloupeLeaves.blockID);
        world.setBlock(i + 10, j + 6, k + 6, Trees.cantaloupeLeaves.blockID);
        world.setBlock(i + 10, j + 6, k + 4, Trees.cantaloupeLeaves.blockID);
        world.setBlock(i + 10, j + 6, k + 3, Trees.cantaloupeLeaves.blockID);
        world.setBlock(i + 10, j + 6, k + 2, Trees.cantaloupeLeaves.blockID);
        world.setBlock(i + 11, j + 6, k + 8, Trees.cantaloupeLeaves.blockID);
        world.setBlock(i + 11, j + 6, k + 7, Trees.cantaloupeLeaves.blockID);
        world.setBlock(i + 11, j + 6, k + 6, Trees.cantaloupeLeaves.blockID);
        world.setBlock(i + 11, j + 6, k + 5, Trees.cantaloupeLeaves.blockID);
        world.setBlock(i + 11, j + 6, k + 4, Trees.cantaloupeLeaves.blockID);
        world.setBlock(i + 12, j + 6, k + 9, Trees.cantaloupeLeaves.blockID);
        world.setBlock(i + 12, j + 6, k + 8, Trees.cantaloupeLeaves.blockID);
        world.setBlock(i + 12, j + 6, k + 7, Trees.cantaloupeLeaves.blockID);
        world.setBlock(i + 12, j + 6, k + 6, Trees.cantaloupeLeaves.blockID);
        world.setBlock(i + 12, j + 6, k + 5, Trees.cantaloupeLeaves.blockID);
        world.setBlock(i + 13, j + 6, k + 8, Trees.cantaloupeLeaves.blockID);
        world.setBlock(i + 13, j + 6, k + 7, Trees.cantaloupeLeaves.blockID);
        world.setBlock(i + 13, j + 6, k + 6, Trees.cantaloupeLeaves.blockID);
        world.setBlock(i + 3, j + 7, k + 10, Trees.cantaloupeLeaves.blockID);
        world.setBlock(i + 3, j + 7, k + 9, Trees.cantaloupeLeaves.blockID);
        world.setBlock(i + 3, j + 7, k + 8, Trees.cantaloupeLeaves.blockID);
        world.setBlock(i + 4, j + 7, k + 9, Trees.cantaloupeLeaves.blockID);
        world.setBlock(i + 4, j + 7, k + 8, Trees.cantaloupeLeaves.blockID);
        world.setBlock(i + 4, j + 7, k + 7, Trees.cantaloupeLeaves.blockID);
        world.setBlock(i + 4, j + 7, k + 4, Trees.cantaloupeLeaves.blockID);
        world.setBlock(i + 4, j + 7, k + 3, Trees.cantaloupeLeaves.blockID);
        world.setBlock(i + 5, j + 7, k + 9, Trees.cantaloupeLeaves.blockID);
        world.setBlock(i + 5, j + 7, k + 8, Trees.cantaloupeLeaves.blockID);
        world.setBlock(i + 5, j + 7, k + 7, Trees.cantaloupeLeaves.blockID);
        world.setBlock(i + 5, j + 7, k + 5, Trees.cantaloupeLeaves.blockID);
        world.setBlock(i + 5, j + 7, k + 4, Trees.cantaloupeLeaves.blockID);
        world.setBlock(i + 5, j + 7, k + 3, Trees.cantaloupeLeaves.blockID);
        world.setBlock(i + 5, j + 7, k + 2, Trees.cantaloupeLeaves.blockID);
        world.setBlock(i + 6, j + 7, k + 9, Trees.cantaloupeLeaves.blockID);
        world.setBlock(i + 6, j + 7, k + 8, Trees.cantaloupeLeaves.blockID);
        world.setBlock(i + 6, j + 7, k + 7, Trees.cantaloupeLeaves.blockID);
        world.setBlock(i + 6, j + 7, k + 6, Trees.cantaloupeLeaves.blockID);
        world.setBlock(i + 6, j + 7, k + 5, Trees.cantaloupeLeaves.blockID);
        world.setBlock(i + 6, j + 7, k + 4, Trees.cantaloupeLeaves.blockID);
        world.setBlock(i + 6, j + 7, k + 3, Trees.cantaloupeLog.blockID);
        world.setBlock(i + 6, j + 7, k + 2, Trees.cantaloupeLeaves.blockID);
        world.setBlock(i + 7, j + 7, k + 8, Trees.cantaloupeLeaves.blockID);
        world.setBlock(i + 7, j + 7, k + 7, Trees.cantaloupeLeaves.blockID);
        world.setBlock(i + 7, j + 7, k + 6, Trees.cantaloupeLeaves.blockID);
        world.setBlock(i + 7, j + 7, k + 5, Trees.cantaloupeLeaves.blockID);
        world.setBlock(i + 7, j + 7, k + 4, Trees.cantaloupeLog.blockID);
        world.setBlock(i + 7, j + 7, k + 3, Trees.cantaloupeLog.blockID);
        world.setBlock(i + 7, j + 7, k + 2, Trees.cantaloupeLeaves.blockID);
        world.setBlock(i + 7, j + 7, k + 1, Trees.cantaloupeLeaves.blockID);
        world.setBlock(i + 8, j + 7, k + 8, Trees.cantaloupeLeaves.blockID);
        world.setBlock(i + 8, j + 7, k + 7, Trees.cantaloupeLeaves.blockID);
        world.setBlock(i + 8, j + 7, k + 6, Trees.cantaloupeLeaves.blockID);
        world.setBlock(i + 8, j + 7, k + 5, Trees.cantaloupeLeaves.blockID);
        world.setBlock(i + 8, j + 7, k + 4, Trees.cantaloupeLeaves.blockID);
        world.setBlock(i + 8, j + 7, k + 3, Trees.cantaloupeLeaves.blockID);
        world.setBlock(i + 8, j + 7, k + 2, Trees.cantaloupeLeaves.blockID);
        world.setBlock(i + 8, j + 7, k + 1, Trees.cantaloupeLeaves.blockID);
        world.setBlock(i + 8, j + 7, k + 0, Trees.cantaloupeLeaves.blockID);
        world.setBlock(i + 9, j + 7, k + 7, Trees.cantaloupeLeaves.blockID);
        world.setBlock(i + 9, j + 7, k + 6, Trees.cantaloupeLog.blockID);
        world.setBlock(i + 9, j + 7, k + 5, Trees.cantaloupeLog.blockID);
        world.setBlock(i + 9, j + 7, k + 4, Trees.cantaloupeLeaves.blockID);
        world.setBlock(i + 9, j + 7, k + 3, Trees.cantaloupeLeaves.blockID);
        world.setBlock(i + 9, j + 7, k + 2, Trees.cantaloupeLeaves.blockID);
        world.setBlock(i + 9, j + 7, k + 1, Trees.cantaloupeLeaves.blockID);
        world.setBlock(i + 10, j + 7, k + 8, Trees.cantaloupeLeaves.blockID);
        world.setBlock(i + 10, j + 7, k + 7, Trees.cantaloupeLeaves.blockID);
        world.setBlock(i + 10, j + 7, k + 6, Trees.cantaloupeLog.blockID);
        world.setBlock(i + 10, j + 7, k + 5, Trees.cantaloupeLeaves.blockID);
        world.setBlock(i + 10, j + 7, k + 4, Trees.cantaloupeLeaves.blockID);
        world.setBlock(i + 10, j + 7, k + 3, Trees.cantaloupeLeaves.blockID);
        world.setBlock(i + 10, j + 7, k + 2, Trees.cantaloupeLeaves.blockID);
        world.setBlock(i + 10, j + 7, k + 1, Trees.cantaloupeLeaves.blockID);
        world.setBlock(i + 11, j + 7, k + 9, Trees.cantaloupeLeaves.blockID);
        world.setBlock(i + 11, j + 7, k + 8, Trees.cantaloupeLeaves.blockID);
        world.setBlock(i + 11, j + 7, k + 7, Trees.cantaloupeLeaves.blockID);
        world.setBlock(i + 11, j + 7, k + 6, Trees.cantaloupeLeaves.blockID);
        world.setBlock(i + 11, j + 7, k + 5, Trees.cantaloupeLeaves.blockID);
        world.setBlock(i + 11, j + 7, k + 4, Trees.cantaloupeLeaves.blockID);
        world.setBlock(i + 11, j + 7, k + 3, Trees.cantaloupeLeaves.blockID);
        world.setBlock(i + 11, j + 7, k + 2, Trees.cantaloupeLeaves.blockID);
        world.setBlock(i + 12, j + 7, k + 8, Trees.cantaloupeLeaves.blockID);
        world.setBlock(i + 12, j + 7, k + 7, Trees.cantaloupeLeaves.blockID);
        world.setBlock(i + 12, j + 7, k + 6, Trees.cantaloupeLeaves.blockID);
        world.setBlock(i + 12, j + 7, k + 5, Trees.cantaloupeLeaves.blockID);
        world.setBlock(i + 13, j + 7, k + 7, Trees.cantaloupeLeaves.blockID);
        world.setBlock(i + 13, j + 7, k + 6, Trees.cantaloupeLeaves.blockID);
        world.setBlock(i + 4, j + 8, k + 8, Trees.cantaloupeLeaves.blockID);
        world.setBlock(i + 4, j + 8, k + 3, Trees.cantaloupeLeaves.blockID);
        world.setBlock(i + 4, j + 8, k + 2, Trees.cantaloupeLeaves.blockID);
        world.setBlock(i + 5, j + 8, k + 9, Trees.cantaloupeLeaves.blockID);
        world.setBlock(i + 5, j + 8, k + 8, Trees.cantaloupeLeaves.blockID);
        world.setBlock(i + 5, j + 8, k + 4, Trees.cantaloupeLeaves.blockID);
        world.setBlock(i + 5, j + 8, k + 3, Trees.cantaloupeLog.blockID);
        world.setBlock(i + 5, j + 8, k + 2, Trees.cantaloupeLeaves.blockID);
        world.setBlock(i + 6, j + 8, k + 8, Trees.cantaloupeLeaves.blockID);
        world.setBlock(i + 6, j + 8, k + 7, Trees.cantaloupeLeaves.blockID);
        world.setBlock(i + 6, j + 8, k + 5, Trees.cantaloupeLeaves.blockID);
        world.setBlock(i + 6, j + 8, k + 4, Trees.cantaloupeLeaves.blockID);
        world.setBlock(i + 6, j + 8, k + 3, Trees.cantaloupeLog.blockID);
        world.setBlock(i + 6, j + 8, k + 2, Trees.cantaloupeLeaves.blockID);
        world.setBlock(i + 6, j + 8, k + 1, Trees.cantaloupeLeaves.blockID);
        world.setBlock(i + 7, j + 8, k + 7, Trees.cantaloupeLeaves.blockID);
        world.setBlock(i + 7, j + 8, k + 6, Trees.cantaloupeLeaves.blockID);
        world.setBlock(i + 7, j + 8, k + 5, Trees.cantaloupeLeaves.blockID);
        world.setBlock(i + 7, j + 8, k + 4, Trees.cantaloupeLeaves.blockID);
        world.setBlock(i + 7, j + 8, k + 3, Trees.cantaloupeLeaves.blockID);
        world.setBlock(i + 7, j + 8, k + 2, Trees.cantaloupeLeaves.blockID);
        world.setBlock(i + 7, j + 8, k + 1, Trees.cantaloupeLeaves.blockID);
        world.setBlock(i + 7, j + 8, k + 0, Trees.cantaloupeLeaves.blockID);
        world.setBlock(i + 8, j + 8, k + 7, Trees.cantaloupeLeaves.blockID);
        world.setBlock(i + 8, j + 8, k + 6, Trees.cantaloupeLeaves.blockID);
        world.setBlock(i + 8, j + 8, k + 5, Trees.cantaloupeLeaves.blockID);
        world.setBlock(i + 8, j + 8, k + 4, Trees.cantaloupeLeaves.blockID);
        world.setBlock(i + 8, j + 8, k + 3, Trees.cantaloupeLeaves.blockID);
        world.setBlock(i + 8, j + 8, k + 2, Trees.cantaloupeLeaves.blockID);
        world.setBlock(i + 8, j + 8, k + 1, Trees.cantaloupeLeaves.blockID);
        world.setBlock(i + 9, j + 8, k + 6, Trees.cantaloupeLeaves.blockID);
        world.setBlock(i + 9, j + 8, k + 5, Trees.cantaloupeLeaves.blockID);
        world.setBlock(i + 9, j + 8, k + 4, Trees.cantaloupeLeaves.blockID);
        world.setBlock(i + 9, j + 8, k + 3, Trees.cantaloupeLeaves.blockID);
        world.setBlock(i + 9, j + 8, k + 2, Trees.cantaloupeLeaves.blockID);
        world.setBlock(i + 9, j + 8, k + 1, Trees.cantaloupeLeaves.blockID);
        world.setBlock(i + 10, j + 8, k + 7, Trees.cantaloupeLeaves.blockID);
        world.setBlock(i + 10, j + 8, k + 6, Trees.cantaloupeLog.blockID);
        world.setBlock(i + 10, j + 8, k + 5, Trees.cantaloupeLeaves.blockID);
        world.setBlock(i + 10, j + 8, k + 4, Trees.cantaloupeLeaves.blockID);
        world.setBlock(i + 10, j + 8, k + 3, Trees.cantaloupeLeaves.blockID);
        world.setBlock(i + 10, j + 8, k + 2, Trees.cantaloupeLeaves.blockID);
        world.setBlock(i + 11, j + 8, k + 8, Trees.cantaloupeLeaves.blockID);
        world.setBlock(i + 11, j + 8, k + 7, Trees.cantaloupeLeaves.blockID);
        world.setBlock(i + 11, j + 8, k + 6, Trees.cantaloupeLog.blockID);
        world.setBlock(i + 11, j + 8, k + 5, Trees.cantaloupeLeaves.blockID);
        world.setBlock(i + 12, j + 8, k + 7, Trees.cantaloupeLeaves.blockID);
        world.setBlock(i + 12, j + 8, k + 6, Trees.cantaloupeLeaves.blockID);
        world.setBlock(i + 5, j + 9, k + 3, Trees.cantaloupeLeaves.blockID);
        world.setBlock(i + 6, j + 9, k + 4, Trees.cantaloupeLeaves.blockID);
        world.setBlock(i + 6, j + 9, k + 3, Trees.cantaloupeLeaves.blockID);
        world.setBlock(i + 7, j + 9, k + 5, Trees.cantaloupeLeaves.blockID);
        world.setBlock(i + 7, j + 9, k + 4, Trees.cantaloupeLeaves.blockID);
        world.setBlock(i + 7, j + 9, k + 3, Trees.cantaloupeLeaves.blockID);
        world.setBlock(i + 7, j + 9, k + 2, Trees.cantaloupeLeaves.blockID);
        world.setBlock(i + 7, j + 9, k + 1, Trees.cantaloupeLeaves.blockID);
        world.setBlock(i + 8, j + 9, k + 6, Trees.cantaloupeLeaves.blockID);
        world.setBlock(i + 8, j + 9, k + 5, Trees.cantaloupeLeaves.blockID);
        world.setBlock(i + 8, j + 9, k + 4, Trees.cantaloupeLeaves.blockID);
        world.setBlock(i + 8, j + 9, k + 3, Trees.cantaloupeLeaves.blockID);
        world.setBlock(i + 8, j + 9, k + 2, Trees.cantaloupeLeaves.blockID);
        world.setBlock(i + 9, j + 9, k + 5, Trees.cantaloupeLeaves.blockID);
        world.setBlock(i + 9, j + 9, k + 4, Trees.cantaloupeLeaves.blockID);
        world.setBlock(i + 9, j + 9, k + 3, Trees.cantaloupeLeaves.blockID);
        world.setBlock(i + 10, j + 9, k + 6, Trees.cantaloupeLeaves.blockID);
        world.setBlock(i + 10, j + 9, k + 5, Trees.cantaloupeLeaves.blockID);
        world.setBlock(i + 11, j + 9, k + 6, Trees.cantaloupeLeaves.blockID);

return true;
}
} /*=====End of Code=====*/