package microjunk.trees.common.worldgentrees;

import java.util.Random;

import microjunk.trees.common.Trees;
import net.minecraft.block.Block;
import net.minecraft.world.World;
import net.minecraft.world.gen.feature.WorldGenerator;

public class WorldGenTreeHouse extends WorldGenerator
{
	public WorldGenTreeHouse()
    {
		
    }
	public boolean generate(World world, Random rand, int i, int j, int k)
	{
		int j1 = world.getBlockId(i, j - 1, k);
		if(j1 != Block.grass.blockID && j1 != Block.dirt.blockID && j1 != Trees.alphaGrass.blockID || j >= 128 - 12 - 1)
        {
        	return false;
        }
		
		world.setBlock(i + 1, j + 0, k + 33, Block.wood.blockID);
		world.setBlock(i + 2, j + 0, k + 33, Block.wood.blockID);
		world.setBlock(i + 3, j + 0, k + 33, Block.wood.blockID);
		world.setBlock(i + 3, j + 1, k + 33, Block.wood.blockID);
		world.setBlock(i + 3, j + 29, k + 31, Block.leaves.blockID);
		world.setBlock(i + 4, j + 1, k + 33, Block.wood.blockID);
		world.setBlock(i + 4, j + 1, k + 34, Block.wood.blockID);
		world.setBlock(i + 4, j + 2, k + 33, Block.wood.blockID);
		world.setBlock(i + 4, j + 2, k + 34, Block.wood.blockID);
		world.setBlock(i + 4, j + 28, k + 31, Block.leaves.blockID);
		world.setBlock(i + 4, j + 29, k + 30, Block.leaves.blockID);
		world.setBlock(i + 4, j + 29, k + 31, Block.leaves.blockID);
		world.setBlock(i + 4, j + 29, k + 32, Block.leaves.blockID);
		world.setBlock(i + 4, j + 30, k + 31, Block.leaves.blockID);
		world.setBlock(i + 5, j + 2, k + 34, Block.wood.blockID);
		world.setBlock(i + 5, j + 3, k + 34, Block.wood.blockID);
		world.setBlock(i + 5, j + 27, k + 31, Block.leaves.blockID);
		world.setBlock(i + 5, j + 28, k + 30, Block.leaves.blockID);
		world.setBlock(i + 5, j + 28, k + 31, Block.leaves.blockID);
		world.setBlock(i + 5, j + 28, k + 32, Block.leaves.blockID);
		world.setBlock(i + 5, j + 29, k + 29, Block.leaves.blockID);
		world.setBlock(i + 5, j + 29, k + 30, Block.leaves.blockID);
		world.setBlock(i + 5, j + 29, k + 31, Block.wood.blockID);
		world.setBlock(i + 5, j + 29, k + 32, Block.leaves.blockID);
		world.setBlock(i + 5, j + 29, k + 33, Block.leaves.blockID);
		world.setBlock(i + 5, j + 30, k + 30, Block.leaves.blockID);
		world.setBlock(i + 5, j + 30, k + 31, Block.leaves.blockID);
		world.setBlock(i + 5, j + 30, k + 32, Block.leaves.blockID);
		world.setBlock(i + 5, j + 31, k + 28, Block.leaves.blockID);
		world.setBlock(i + 5, j + 31, k + 29, Block.leaves.blockID);
		world.setBlock(i + 5, j + 31, k + 30, Block.leaves.blockID);
		world.setBlock(i + 5, j + 31, k + 31, Block.leaves.blockID);
		world.setBlock(i + 6, j + 3, k + 34, Block.wood.blockID);
		world.setBlock(i + 6, j + 3, k + 35, Block.wood.blockID);
		world.setBlock(i + 6, j + 22, k + 30, Block.leaves.blockID);
		world.setBlock(i + 6, j + 27, k + 31, Block.leaves.blockID);
		world.setBlock(i + 6, j + 28, k + 30, Block.leaves.blockID);
		world.setBlock(i + 6, j + 28, k + 31, Block.leaves.blockID);
		world.setBlock(i + 6, j + 28, k + 32, Block.leaves.blockID);
		world.setBlock(i + 6, j + 29, k + 29, Block.leaves.blockID);
		world.setBlock(i + 6, j + 29, k + 30, Block.wood.blockID);
		world.setBlock(i + 6, j + 29, k + 31, Block.wood.blockID);
		world.setBlock(i + 6, j + 29, k + 32, Block.leaves.blockID);
		world.setBlock(i + 6, j + 29, k + 33, Block.leaves.blockID);
		world.setBlock(i + 6, j + 30, k + 30, Block.leaves.blockID);
		world.setBlock(i + 6, j + 30, k + 31, Block.leaves.blockID);
		world.setBlock(i + 6, j + 30, k + 32, Block.leaves.blockID);
		world.setBlock(i + 6, j + 31, k + 28, Block.leaves.blockID);
		world.setBlock(i + 6, j + 31, k + 29, Block.leaves.blockID);
		world.setBlock(i + 6, j + 31, k + 30, Block.leaves.blockID);
		world.setBlock(i + 6, j + 31, k + 31, Block.leaves.blockID);
		world.setBlock(i + 6, j + 32, k + 29, Block.leaves.blockID);
		world.setBlock(i + 6, j + 32, k + 30, Block.leaves.blockID);
		world.setBlock(i + 6, j + 32, k + 31, Block.leaves.blockID);
		world.setBlock(i + 6, j + 33, k + 30, Block.leaves.blockID);
		world.setBlock(i + 7, j + 3, k + 35, Block.wood.blockID);
		world.setBlock(i + 7, j + 4, k + 35, Block.wood.blockID);
		world.setBlock(i + 7, j + 22, k + 29, Block.leaves.blockID);
		world.setBlock(i + 7, j + 22, k + 30, Block.leaves.blockID);
		world.setBlock(i + 7, j + 22, k + 31, Block.leaves.blockID);
		world.setBlock(i + 7, j + 27, k + 31, Block.leaves.blockID);
		world.setBlock(i + 7, j + 28, k + 29, Block.leaves.blockID);
		world.setBlock(i + 7, j + 28, k + 30, Block.leaves.blockID);
		world.setBlock(i + 7, j + 28, k + 31, Block.leaves.blockID);
		world.setBlock(i + 7, j + 28, k + 32, Block.leaves.blockID);
		world.setBlock(i + 7, j + 29, k + 29, Block.leaves.blockID);
		world.setBlock(i + 7, j + 29, k + 30, Block.wood.blockID);
		world.setBlock(i + 7, j + 29, k + 31, Block.wood.blockID);
		world.setBlock(i + 7, j + 29, k + 32, Block.leaves.blockID);
		world.setBlock(i + 7, j + 29, k + 33, Block.leaves.blockID);
		world.setBlock(i + 7, j + 30, k + 29, Block.leaves.blockID);
		world.setBlock(i + 7, j + 30, k + 30, Block.leaves.blockID);
		world.setBlock(i + 7, j + 30, k + 31, Block.leaves.blockID);
		world.setBlock(i + 7, j + 30, k + 32, Block.leaves.blockID);
		world.setBlock(i + 7, j + 30, k + 33, Block.leaves.blockID);
		world.setBlock(i + 7, j + 31, k + 27, Block.leaves.blockID);
		world.setBlock(i + 7, j + 31, k + 28, Block.leaves.blockID);
		world.setBlock(i + 7, j + 31, k + 29, Block.leaves.blockID);
		world.setBlock(i + 7, j + 31, k + 30, Block.leaves.blockID);
		world.setBlock(i + 7, j + 31, k + 31, Block.leaves.blockID);
		world.setBlock(i + 7, j + 31, k + 32, Block.leaves.blockID);
		world.setBlock(i + 7, j + 32, k + 28, Block.leaves.blockID);
		world.setBlock(i + 7, j + 32, k + 29, Block.leaves.blockID);
		world.setBlock(i + 7, j + 32, k + 30, Block.leaves.blockID);
		world.setBlock(i + 7, j + 32, k + 31, Block.leaves.blockID);
		world.setBlock(i + 7, j + 32, k + 32, Block.leaves.blockID);
		world.setBlock(i + 7, j + 33, k + 30, Block.leaves.blockID);
		world.setBlock(i + 7, j + 33, k + 31, Block.leaves.blockID);
		world.setBlock(i + 7, j + 34, k + 30, Block.leaves.blockID);
		world.setBlock(i + 8, j + 4, k + 35, Block.wood.blockID);
		world.setBlock(i + 8, j + 7, k + 13, Block.leaves.blockID);
		world.setBlock(i + 8, j + 7, k + 14, Block.leaves.blockID);
		world.setBlock(i + 8, j + 7, k + 15, Block.leaves.blockID);
		world.setBlock(i + 8, j + 7, k + 16, Block.leaves.blockID);
		world.setBlock(i + 8, j + 7, k + 17, Block.leaves.blockID);
		world.setBlock(i + 8, j + 8, k + 12, Block.leaves.blockID);
		world.setBlock(i + 8, j + 8, k + 14, Block.leaves.blockID);
		world.setBlock(i + 8, j + 8, k + 15, Block.leaves.blockID);
		world.setBlock(i + 8, j + 8, k + 16, Block.leaves.blockID);
		world.setBlock(i + 8, j + 21, k + 30, Block.leaves.blockID);
		world.setBlock(i + 8, j + 22, k + 28, Block.leaves.blockID);
		world.setBlock(i + 8, j + 22, k + 29, Block.leaves.blockID);
		world.setBlock(i + 8, j + 22, k + 30, Block.wood.blockID);
		world.setBlock(i + 8, j + 22, k + 31, Block.leaves.blockID);
		world.setBlock(i + 8, j + 22, k + 32, Block.leaves.blockID);
		world.setBlock(i + 8, j + 27, k + 29, Block.leaves.blockID);
		world.setBlock(i + 8, j + 27, k + 30, Block.leaves.blockID);
		world.setBlock(i + 8, j + 27, k + 31, Block.leaves.blockID);
		world.setBlock(i + 8, j + 28, k + 28, Block.leaves.blockID);
		world.setBlock(i + 8, j + 28, k + 29, Block.leaves.blockID);
		world.setBlock(i + 8, j + 28, k + 30, Block.leaves.blockID);
		world.setBlock(i + 8, j + 28, k + 31, Block.leaves.blockID);
		world.setBlock(i + 8, j + 28, k + 32, Block.leaves.blockID);
		world.setBlock(i + 8, j + 29, k + 28, Block.leaves.blockID);
		world.setBlock(i + 8, j + 29, k + 29, Block.leaves.blockID);
		world.setBlock(i + 8, j + 29, k + 30, Block.wood.blockID);
		world.setBlock(i + 8, j + 29, k + 31, Block.leaves.blockID);
		world.setBlock(i + 8, j + 29, k + 32, Block.wood.blockID);
		world.setBlock(i + 8, j + 29, k + 33, Block.leaves.blockID);
		world.setBlock(i + 8, j + 30, k + 28, Block.leaves.blockID);
		world.setBlock(i + 8, j + 30, k + 29, Block.leaves.blockID);
		world.setBlock(i + 8, j + 30, k + 30, Block.wood.blockID);
		world.setBlock(i + 8, j + 30, k + 31, Block.leaves.blockID);
		world.setBlock(i + 8, j + 30, k + 32, Block.leaves.blockID);
		world.setBlock(i + 8, j + 30, k + 33, Block.leaves.blockID);
		world.setBlock(i + 8, j + 31, k + 27, Block.leaves.blockID);
		world.setBlock(i + 8, j + 31, k + 28, Block.leaves.blockID);
		world.setBlock(i + 8, j + 31, k + 29, Block.leaves.blockID);
		world.setBlock(i + 8, j + 31, k + 30, Block.leaves.blockID);
		world.setBlock(i + 8, j + 31, k + 31, Block.leaves.blockID);
		world.setBlock(i + 8, j + 31, k + 32, Block.leaves.blockID);
		world.setBlock(i + 8, j + 31, k + 33, Block.leaves.blockID);
		world.setBlock(i + 8, j + 32, k + 27, Block.leaves.blockID);
		world.setBlock(i + 8, j + 32, k + 28, Block.leaves.blockID);
		world.setBlock(i + 8, j + 32, k + 29, Block.leaves.blockID);
		world.setBlock(i + 8, j + 32, k + 30, Block.leaves.blockID);
		world.setBlock(i + 8, j + 32, k + 31, Block.leaves.blockID);
		world.setBlock(i + 8, j + 32, k + 32, Block.leaves.blockID);
		world.setBlock(i + 8, j + 33, k + 28, Block.leaves.blockID);
		world.setBlock(i + 8, j + 33, k + 29, Block.leaves.blockID);
		world.setBlock(i + 8, j + 33, k + 30, Block.leaves.blockID);
		world.setBlock(i + 8, j + 33, k + 31, Block.leaves.blockID);
		world.setBlock(i + 8, j + 34, k + 29, Block.leaves.blockID);
		world.setBlock(i + 8, j + 34, k + 30, Block.leaves.blockID);
		world.setBlock(i + 8, j + 35, k + 30, Block.leaves.blockID);
		world.setBlock(i + 9, j + 3, k + 35, Block.wood.blockID);
		world.setBlock(i + 9, j + 4, k + 35, Block.wood.blockID);
		world.setBlock(i + 9, j + 6, k + 13, Block.leaves.blockID);
		world.setBlock(i + 9, j + 6, k + 14, Block.leaves.blockID);
		world.setBlock(i + 9, j + 6, k + 15, Block.leaves.blockID);
		world.setBlock(i + 9, j + 6, k + 16, Block.leaves.blockID);
		world.setBlock(i + 9, j + 7, k + 11, Block.leaves.blockID);
		world.setBlock(i + 9, j + 7, k + 12, Block.leaves.blockID);
		world.setBlock(i + 9, j + 7, k + 13, Block.leaves.blockID);
		world.setBlock(i + 9, j + 7, k + 14, Block.leaves.blockID);
		world.setBlock(i + 9, j + 7, k + 15, Block.leaves.blockID);
		world.setBlock(i + 9, j + 7, k + 16, Block.leaves.blockID);
		world.setBlock(i + 9, j + 7, k + 17, Block.leaves.blockID);
		world.setBlock(i + 9, j + 7, k + 18, Block.leaves.blockID);
		world.setBlock(i + 9, j + 8, k + 11, Block.leaves.blockID);
		world.setBlock(i + 9, j + 8, k + 12, Block.leaves.blockID);
		world.setBlock(i + 9, j + 8, k + 13, Block.leaves.blockID);
		world.setBlock(i + 9, j + 8, k + 14, Block.leaves.blockID);
		world.setBlock(i + 9, j + 8, k + 15, Block.leaves.blockID);
		world.setBlock(i + 9, j + 8, k + 16, Block.leaves.blockID);
		world.setBlock(i + 9, j + 8, k + 17, Block.leaves.blockID);
		world.setBlock(i + 9, j + 9, k + 12, Block.leaves.blockID);
		world.setBlock(i + 9, j + 9, k + 14, Block.leaves.blockID);
		world.setBlock(i + 9, j + 9, k + 15, Block.leaves.blockID);
		world.setBlock(i + 9, j + 9, k + 16, Block.leaves.blockID);
		world.setBlock(i + 9, j + 21, k + 30, Block.leaves.blockID);
		world.setBlock(i + 9, j + 21, k + 31, Block.leaves.blockID);
		world.setBlock(i + 9, j + 22, k + 28, Block.leaves.blockID);
		world.setBlock(i + 9, j + 22, k + 29, Block.leaves.blockID);
		world.setBlock(i + 9, j + 22, k + 30, Block.wood.blockID);
		world.setBlock(i + 9, j + 22, k + 31, Block.leaves.blockID);
		world.setBlock(i + 9, j + 22, k + 32, Block.leaves.blockID);
		world.setBlock(i + 9, j + 26, k + 29, Block.leaves.blockID);
		world.setBlock(i + 9, j + 26, k + 30, Block.leaves.blockID);
		world.setBlock(i + 9, j + 27, k + 28, Block.leaves.blockID);
		world.setBlock(i + 9, j + 27, k + 29, Block.leaves.blockID);
		world.setBlock(i + 9, j + 27, k + 30, Block.leaves.blockID);
		world.setBlock(i + 9, j + 27, k + 31, Block.leaves.blockID);
		world.setBlock(i + 9, j + 28, k + 28, Block.leaves.blockID);
		world.setBlock(i + 9, j + 28, k + 29, Block.leaves.blockID);
		world.setBlock(i + 9, j + 28, k + 30, Block.leaves.blockID);
		world.setBlock(i + 9, j + 28, k + 31, Block.leaves.blockID);
		world.setBlock(i + 9, j + 28, k + 32, Block.leaves.blockID);
		world.setBlock(i + 9, j + 29, k + 28, Block.leaves.blockID);
		world.setBlock(i + 9, j + 29, k + 29, Block.leaves.blockID);
		world.setBlock(i + 9, j + 29, k + 30, Block.leaves.blockID);
		world.setBlock(i + 9, j + 29, k + 31, Block.leaves.blockID);
		world.setBlock(i + 9, j + 29, k + 32, Block.leaves.blockID);
		world.setBlock(i + 9, j + 29, k + 33, Block.leaves.blockID);
		world.setBlock(i + 9, j + 30, k + 27, Block.leaves.blockID);
		world.setBlock(i + 9, j + 30, k + 28, Block.leaves.blockID);
		world.setBlock(i + 9, j + 30, k + 29, Block.leaves.blockID);
		world.setBlock(i + 9, j + 30, k + 30, Block.wood.blockID);
		world.setBlock(i + 9, j + 30, k + 31, Block.leaves.blockID);
		world.setBlock(i + 9, j + 30, k + 33, Block.leaves.blockID);
		world.setBlock(i + 9, j + 31, k + 27, Block.leaves.blockID);
		world.setBlock(i + 9, j + 31, k + 28, Block.leaves.blockID);
		world.setBlock(i + 9, j + 31, k + 29, Block.leaves.blockID);
		world.setBlock(i + 9, j + 31, k + 30, Block.leaves.blockID);
		world.setBlock(i + 9, j + 31, k + 31, Block.leaves.blockID);
		world.setBlock(i + 9, j + 31, k + 32, Block.leaves.blockID);
		world.setBlock(i + 9, j + 31, k + 33, Block.leaves.blockID);
		world.setBlock(i + 9, j + 32, k + 27, Block.leaves.blockID);
		world.setBlock(i + 9, j + 32, k + 28, Block.leaves.blockID);
		world.setBlock(i + 9, j + 32, k + 29, Block.leaves.blockID);
		world.setBlock(i + 9, j + 32, k + 30, Block.wood.blockID);
		world.setBlock(i + 9, j + 32, k + 31, Block.leaves.blockID);
		world.setBlock(i + 9, j + 32, k + 32, Block.leaves.blockID);
		world.setBlock(i + 9, j + 33, k + 28, Block.leaves.blockID);
		world.setBlock(i + 9, j + 33, k + 29, Block.leaves.blockID);
		world.setBlock(i + 9, j + 33, k + 30, Block.leaves.blockID);
		world.setBlock(i + 9, j + 33, k + 31, Block.leaves.blockID);
		world.setBlock(i + 9, j + 34, k + 29, Block.leaves.blockID);
		world.setBlock(i + 9, j + 34, k + 30, Block.leaves.blockID);
		world.setBlock(i + 9, j + 35, k + 30, Block.leaves.blockID);
		world.setBlock(i + 10, j + 2, k + 34, Block.wood.blockID);
		world.setBlock(i + 10, j + 2, k + 35, Block.wood.blockID);
		world.setBlock(i + 10, j + 3, k + 14, Block.wood.blockID);
		world.setBlock(i + 10, j + 3, k + 35, Block.wood.blockID);
		world.setBlock(i + 10, j + 4, k + 14, Block.wood.blockID);
		world.setBlock(i + 10, j + 5, k + 15, Block.wood.blockID);
		world.setBlock(i + 10, j + 6, k + 12, Block.leaves.blockID);
		world.setBlock(i + 10, j + 6, k + 13, Block.leaves.blockID);
		world.setBlock(i + 10, j + 6, k + 14, Block.leaves.blockID);
		world.setBlock(i + 10, j + 6, k + 15, Block.leaves.blockID);
		world.setBlock(i + 10, j + 6, k + 16, Block.leaves.blockID);
		world.setBlock(i + 10, j + 7, k + 10, Block.leaves.blockID);
		world.setBlock(i + 10, j + 7, k + 11, Block.wood.blockID);
		world.setBlock(i + 10, j + 7, k + 12, Block.leaves.blockID);
		world.setBlock(i + 10, j + 7, k + 13, Block.leaves.blockID);
		world.setBlock(i + 10, j + 7, k + 14, Block.leaves.blockID);
		world.setBlock(i + 10, j + 7, k + 15, Block.leaves.blockID);
		world.setBlock(i + 10, j + 7, k + 16, Block.leaves.blockID);
		world.setBlock(i + 10, j + 7, k + 17, Block.leaves.blockID);
		world.setBlock(i + 10, j + 7, k + 18, Block.leaves.blockID);
		world.setBlock(i + 10, j + 8, k + 10, Block.leaves.blockID);
		world.setBlock(i + 10, j + 8, k + 11, Block.leaves.blockID);
		world.setBlock(i + 10, j + 8, k + 12, Block.leaves.blockID);
		world.setBlock(i + 10, j + 8, k + 13, Block.leaves.blockID);
		world.setBlock(i + 10, j + 8, k + 14, Block.leaves.blockID);
		world.setBlock(i + 10, j + 8, k + 15, Block.leaves.blockID);
		world.setBlock(i + 10, j + 8, k + 16, Block.leaves.blockID);
		world.setBlock(i + 10, j + 8, k + 17, Block.leaves.blockID);
		world.setBlock(i + 10, j + 9, k + 11, Block.leaves.blockID);
		world.setBlock(i + 10, j + 9, k + 12, Block.leaves.blockID);
		world.setBlock(i + 10, j + 9, k + 13, Block.leaves.blockID);
		world.setBlock(i + 10, j + 9, k + 15, Block.leaves.blockID);
		world.setBlock(i + 10, j + 9, k + 16, Block.leaves.blockID);
		world.setBlock(i + 10, j + 10, k + 12, Block.leaves.blockID);
		world.setBlock(i + 10, j + 21, k + 29, Block.leaves.blockID);
		world.setBlock(i + 10, j + 21, k + 30, Block.leaves.blockID);
		world.setBlock(i + 10, j + 21, k + 31, Block.leaves.blockID);
		world.setBlock(i + 10, j + 22, k + 28, Block.leaves.blockID);
		world.setBlock(i + 10, j + 22, k + 29, Block.leaves.blockID);
		world.setBlock(i + 10, j + 22, k + 30, Block.wood.blockID);
		world.setBlock(i + 10, j + 22, k + 31, Block.leaves.blockID);
		world.setBlock(i + 10, j + 22, k + 32, Block.leaves.blockID);
		world.setBlock(i + 10, j + 26, k + 29, Block.leaves.blockID);
		world.setBlock(i + 10, j + 26, k + 30, Block.leaves.blockID);
		world.setBlock(i + 10, j + 27, k + 27, Block.leaves.blockID);
		world.setBlock(i + 10, j + 27, k + 28, Block.leaves.blockID);
		world.setBlock(i + 10, j + 27, k + 29, Block.leaves.blockID);
		world.setBlock(i + 10, j + 27, k + 30, Block.wood.blockID);
		world.setBlock(i + 10, j + 27, k + 31, Block.leaves.blockID);
		world.setBlock(i + 10, j + 28, k + 28, Block.leaves.blockID);
		world.setBlock(i + 10, j + 28, k + 29, Block.leaves.blockID);
		world.setBlock(i + 10, j + 28, k + 30, Block.wood.blockID);
		world.setBlock(i + 10, j + 28, k + 31, Block.leaves.blockID);
		world.setBlock(i + 10, j + 28, k + 32, Block.leaves.blockID);
		world.setBlock(i + 10, j + 29, k + 27, Block.leaves.blockID);
		world.setBlock(i + 10, j + 29, k + 28, Block.leaves.blockID);
		world.setBlock(i + 10, j + 29, k + 29, Block.wood.blockID);
		world.setBlock(i + 10, j + 29, k + 30, Block.wood.blockID);
		world.setBlock(i + 10, j + 29, k + 31, Block.wood.blockID);
		world.setBlock(i + 10, j + 29, k + 32, Block.leaves.blockID);
		world.setBlock(i + 10, j + 29, k + 33, Block.leaves.blockID);
		world.setBlock(i + 10, j + 30, k + 27, Block.leaves.blockID);
		world.setBlock(i + 10, j + 30, k + 28, Block.leaves.blockID);
		world.setBlock(i + 10, j + 30, k + 29, Block.leaves.blockID);
		world.setBlock(i + 10, j + 30, k + 30, Block.wood.blockID);
		world.setBlock(i + 10, j + 30, k + 31, Block.leaves.blockID);
		world.setBlock(i + 10, j + 30, k + 32, Block.leaves.blockID);
		world.setBlock(i + 10, j + 30, k + 33, Block.leaves.blockID);
		world.setBlock(i + 10, j + 31, k + 27, Block.leaves.blockID);
		world.setBlock(i + 10, j + 31, k + 28, Block.leaves.blockID);
		world.setBlock(i + 10, j + 31, k + 29, Block.leaves.blockID);
		world.setBlock(i + 10, j + 31, k + 30, Block.leaves.blockID);
		world.setBlock(i + 10, j + 31, k + 31, Block.leaves.blockID);
		world.setBlock(i + 10, j + 31, k + 32, Block.leaves.blockID);
		world.setBlock(i + 10, j + 31, k + 33, Block.leaves.blockID);
		world.setBlock(i + 10, j + 32, k + 27, Block.leaves.blockID);
		world.setBlock(i + 10, j + 32, k + 28, Block.leaves.blockID);
		world.setBlock(i + 10, j + 32, k + 29, Block.leaves.blockID);
		world.setBlock(i + 10, j + 32, k + 30, Block.leaves.blockID);
		world.setBlock(i + 10, j + 32, k + 31, Block.leaves.blockID);
		world.setBlock(i + 10, j + 32, k + 32, Block.leaves.blockID);
		world.setBlock(i + 10, j + 33, k + 28, Block.leaves.blockID);
		world.setBlock(i + 10, j + 33, k + 29, Block.leaves.blockID);
		world.setBlock(i + 10, j + 33, k + 30, Block.leaves.blockID);
		world.setBlock(i + 10, j + 33, k + 31, Block.leaves.blockID);
		world.setBlock(i + 11, j + 0, k + 14, Block.wood.blockID);
		world.setBlock(i + 11, j + 0, k + 15, Block.wood.blockID);
		world.setBlock(i + 11, j + 0, k + 33, Block.wood.blockID);
		world.setBlock(i + 11, j + 1, k + 14, Block.wood.blockID);
		world.setBlock(i + 11, j + 1, k + 15, Block.wood.blockID);
		world.setBlock(i + 11, j + 1, k + 33, Block.wood.blockID);
		world.setBlock(i + 11, j + 1, k + 34, Block.wood.blockID);
		world.setBlock(i + 11, j + 2, k + 13, Block.wood.blockID);
		world.setBlock(i + 11, j + 2, k + 14, Block.wood.blockID);
		world.setBlock(i + 11, j + 2, k + 15, Block.wood.blockID);
		world.setBlock(i + 11, j + 2, k + 34, Block.wood.blockID);
		world.setBlock(i + 11, j + 3, k + 13, Block.wood.blockID);
		world.setBlock(i + 11, j + 3, k + 14, Block.wood.blockID);
		world.setBlock(i + 11, j + 3, k + 15, Block.wood.blockID);
		world.setBlock(i + 11, j + 3, k + 34, Block.wood.blockID);
		world.setBlock(i + 11, j + 4, k + 14, Block.wood.blockID);
		world.setBlock(i + 11, j + 4, k + 15, Block.wood.blockID);
		world.setBlock(i + 11, j + 5, k + 14, Block.wood.blockID);
		world.setBlock(i + 11, j + 5, k + 15, Block.wood.blockID);
		world.setBlock(i + 11, j + 6, k + 12, Block.wood.blockID);
		world.setBlock(i + 11, j + 6, k + 13, Block.leaves.blockID);
		world.setBlock(i + 11, j + 6, k + 14, Block.wood.blockID);
		world.setBlock(i + 11, j + 6, k + 15, Block.wood.blockID);
		world.setBlock(i + 11, j + 6, k + 16, Block.leaves.blockID);
		world.setBlock(i + 11, j + 6, k + 17, Block.leaves.blockID);
		world.setBlock(i + 11, j + 7, k + 10, Block.leaves.blockID);
		world.setBlock(i + 11, j + 7, k + 11, Block.leaves.blockID);
		world.setBlock(i + 11, j + 7, k + 12, Block.wood.blockID);
		world.setBlock(i + 11, j + 7, k + 13, Block.leaves.blockID);
		world.setBlock(i + 11, j + 7, k + 14, Block.leaves.blockID);
		world.setBlock(i + 11, j + 7, k + 15, Block.leaves.blockID);
		world.setBlock(i + 11, j + 7, k + 16, Block.leaves.blockID);
		world.setBlock(i + 11, j + 7, k + 17, Block.leaves.blockID);
		world.setBlock(i + 11, j + 7, k + 18, Block.leaves.blockID);
		world.setBlock(i + 11, j + 8, k + 10, Block.leaves.blockID);
		world.setBlock(i + 11, j + 8, k + 11, Block.leaves.blockID);
		world.setBlock(i + 11, j + 8, k + 12, Block.leaves.blockID);
		world.setBlock(i + 11, j + 8, k + 13, Block.leaves.blockID);
		world.setBlock(i + 11, j + 8, k + 14, Block.leaves.blockID);
		world.setBlock(i + 11, j + 8, k + 15, Block.leaves.blockID);
		world.setBlock(i + 11, j + 8, k + 16, Block.leaves.blockID);
		world.setBlock(i + 11, j + 8, k + 17, Block.leaves.blockID);
		world.setBlock(i + 11, j + 9, k + 12, Block.leaves.blockID);
		world.setBlock(i + 11, j + 9, k + 13, Block.leaves.blockID);
		world.setBlock(i + 11, j + 9, k + 14, Block.leaves.blockID);
		world.setBlock(i + 11, j + 9, k + 15, Block.leaves.blockID);
		world.setBlock(i + 11, j + 9, k + 16, Block.leaves.blockID);
		world.setBlock(i + 11, j + 10, k + 12, Block.leaves.blockID);
		world.setBlock(i + 11, j + 10, k + 13, Block.leaves.blockID);
		world.setBlock(i + 11, j + 10, k + 14, Block.leaves.blockID);
		world.setBlock(i + 11, j + 21, k + 29, Block.leaves.blockID);
		world.setBlock(i + 11, j + 21, k + 30, Block.leaves.blockID);
		world.setBlock(i + 11, j + 21, k + 31, Block.leaves.blockID);
		world.setBlock(i + 11, j + 22, k + 28, Block.leaves.blockID);
		world.setBlock(i + 11, j + 22, k + 29, Block.wood.blockID);
		world.setBlock(i + 11, j + 22, k + 30, Block.wood.blockID);
		world.setBlock(i + 11, j + 22, k + 31, Block.wood.blockID);
		world.setBlock(i + 11, j + 22, k + 32, Block.leaves.blockID);
		world.setBlock(i + 11, j + 26, k + 29, Block.leaves.blockID);
		world.setBlock(i + 11, j + 26, k + 30, Block.leaves.blockID);
		world.setBlock(i + 11, j + 27, k + 27, Block.leaves.blockID);
		world.setBlock(i + 11, j + 27, k + 28, Block.leaves.blockID);
		world.setBlock(i + 11, j + 27, k + 29, Block.leaves.blockID);
		world.setBlock(i + 11, j + 27, k + 30, Block.leaves.blockID);
		world.setBlock(i + 11, j + 27, k + 31, Block.leaves.blockID);
		world.setBlock(i + 11, j + 28, k + 28, Block.leaves.blockID);
		world.setBlock(i + 11, j + 28, k + 29, Block.leaves.blockID);
		world.setBlock(i + 11, j + 28, k + 30, Block.wood.blockID);
		world.setBlock(i + 11, j + 28, k + 31, Block.leaves.blockID);
		world.setBlock(i + 11, j + 28, k + 32, Block.leaves.blockID);
		world.setBlock(i + 11, j + 29, k + 28, Block.leaves.blockID);
		world.setBlock(i + 11, j + 29, k + 29, Block.leaves.blockID);
		world.setBlock(i + 11, j + 29, k + 30, Block.wood.blockID);
		world.setBlock(i + 11, j + 29, k + 31, Block.leaves.blockID);
		world.setBlock(i + 11, j + 29, k + 32, Block.leaves.blockID);
		world.setBlock(i + 11, j + 29, k + 33, Block.leaves.blockID);
		world.setBlock(i + 11, j + 30, k + 27, Block.leaves.blockID);
		world.setBlock(i + 11, j + 30, k + 28, Block.leaves.blockID);
		world.setBlock(i + 11, j + 30, k + 29, Block.leaves.blockID);
		world.setBlock(i + 11, j + 30, k + 30, Block.leaves.blockID);
		world.setBlock(i + 11, j + 30, k + 31, Block.leaves.blockID);
		world.setBlock(i + 11, j + 30, k + 32, Block.leaves.blockID);
		world.setBlock(i + 11, j + 30, k + 33, Block.leaves.blockID);
		world.setBlock(i + 11, j + 31, k + 28, Block.leaves.blockID);
		world.setBlock(i + 11, j + 31, k + 29, Block.leaves.blockID);
		world.setBlock(i + 11, j + 31, k + 30, Block.leaves.blockID);
		world.setBlock(i + 11, j + 31, k + 31, Block.leaves.blockID);
		world.setBlock(i + 11, j + 31, k + 32, Block.leaves.blockID);
		world.setBlock(i + 11, j + 31, k + 33, Block.leaves.blockID);
		world.setBlock(i + 11, j + 32, k + 28, Block.leaves.blockID);
		world.setBlock(i + 11, j + 32, k + 29, Block.leaves.blockID);
		world.setBlock(i + 11, j + 32, k + 30, Block.leaves.blockID);
		world.setBlock(i + 11, j + 32, k + 31, Block.leaves.blockID);
		world.setBlock(i + 11, j + 32, k + 32, Block.leaves.blockID);
		world.setBlock(i + 11, j + 33, k + 29, Block.leaves.blockID);
		world.setBlock(i + 11, j + 33, k + 30, Block.leaves.blockID);
		world.setBlock(i + 12, j + 0, k + 13, Block.wood.blockID);
		world.setBlock(i + 12, j + 0, k + 14, Block.wood.blockID);
		world.setBlock(i + 12, j + 0, k + 15, Block.wood.blockID);
		world.setBlock(i + 12, j + 0, k + 32, Block.wood.blockID);
		world.setBlock(i + 12, j + 0, k + 33, Block.wood.blockID);
		world.setBlock(i + 12, j + 1, k + 13, Block.wood.blockID);
		world.setBlock(i + 12, j + 1, k + 14, Block.wood.blockID);
		world.setBlock(i + 12, j + 1, k + 15, Block.wood.blockID);
		world.setBlock(i + 12, j + 1, k + 33, Block.wood.blockID);
		world.setBlock(i + 12, j + 2, k + 13, Block.wood.blockID);
		world.setBlock(i + 12, j + 2, k + 14, Block.wood.blockID);
		world.setBlock(i + 12, j + 2, k + 15, Block.wood.blockID);
		world.setBlock(i + 12, j + 3, k + 14, Block.wood.blockID);
		world.setBlock(i + 12, j + 3, k + 15, Block.wood.blockID);
		world.setBlock(i + 12, j + 4, k + 14, Block.wood.blockID);
		world.setBlock(i + 12, j + 4, k + 15, Block.wood.blockID);
		world.setBlock(i + 12, j + 5, k + 14, Block.wood.blockID);
		world.setBlock(i + 12, j + 5, k + 15, Block.wood.blockID);
		world.setBlock(i + 12, j + 6, k + 11, Block.leaves.blockID);
		world.setBlock(i + 12, j + 6, k + 12, Block.wood.blockID);
		world.setBlock(i + 12, j + 6, k + 13, Block.wood.blockID);
		world.setBlock(i + 12, j + 6, k + 14, Block.wood.blockID);
		world.setBlock(i + 12, j + 6, k + 15, Block.wood.blockID);
		world.setBlock(i + 12, j + 6, k + 16, Block.leaves.blockID);
		world.setBlock(i + 12, j + 6, k + 17, Block.leaves.blockID);
		world.setBlock(i + 12, j + 7, k + 11, Block.leaves.blockID);
		world.setBlock(i + 12, j + 7, k + 12, Block.leaves.blockID);
		world.setBlock(i + 12, j + 7, k + 13, Block.leaves.blockID);
		world.setBlock(i + 12, j + 7, k + 14, Block.leaves.blockID);
		world.setBlock(i + 12, j + 7, k + 15, Block.leaves.blockID);
		world.setBlock(i + 12, j + 7, k + 16, Block.leaves.blockID);
		world.setBlock(i + 12, j + 7, k + 17, Block.leaves.blockID);
		world.setBlock(i + 12, j + 7, k + 18, Block.leaves.blockID);
		world.setBlock(i + 12, j + 8, k + 11, Block.leaves.blockID);
		world.setBlock(i + 12, j + 8, k + 12, Block.leaves.blockID);
		world.setBlock(i + 12, j + 8, k + 13, Block.leaves.blockID);
		world.setBlock(i + 12, j + 8, k + 14, Block.leaves.blockID);
		world.setBlock(i + 12, j + 8, k + 15, Block.leaves.blockID);
		world.setBlock(i + 12, j + 8, k + 16, Block.leaves.blockID);
		world.setBlock(i + 12, j + 9, k + 12, Block.leaves.blockID);
		world.setBlock(i + 12, j + 9, k + 13, Block.leaves.blockID);
		world.setBlock(i + 12, j + 9, k + 14, Block.leaves.blockID);
		world.setBlock(i + 12, j + 9, k + 15, Block.leaves.blockID);
		world.setBlock(i + 12, j + 9, k + 16, Block.leaves.blockID);
		world.setBlock(i + 12, j + 10, k + 13, Block.leaves.blockID);
		world.setBlock(i + 12, j + 10, k + 14, Block.leaves.blockID);
		world.setBlock(i + 12, j + 10, k + 15, Block.leaves.blockID);
		world.setBlock(i + 12, j + 20, k + 30, Block.leaves.blockID);
		world.setBlock(i + 12, j + 21, k + 28, Block.leaves.blockID);
		world.setBlock(i + 12, j + 21, k + 29, Block.leaves.blockID);
		world.setBlock(i + 12, j + 21, k + 30, Block.wood.blockID);
		world.setBlock(i + 12, j + 21, k + 31, Block.leaves.blockID);
		world.setBlock(i + 12, j + 21, k + 32, Block.leaves.blockID);
		world.setBlock(i + 12, j + 22, k + 28, Block.leaves.blockID);
		world.setBlock(i + 12, j + 22, k + 29, Block.wood.blockID);
		world.setBlock(i + 12, j + 22, k + 30, Block.wood.blockID);
		world.setBlock(i + 12, j + 22, k + 31, Block.wood.blockID);
		world.setBlock(i + 12, j + 22, k + 32, Block.leaves.blockID);
		world.setBlock(i + 12, j + 26, k + 29, Block.leaves.blockID);
		world.setBlock(i + 12, j + 26, k + 30, Block.leaves.blockID);
		world.setBlock(i + 12, j + 26, k + 31, Block.leaves.blockID);
		world.setBlock(i + 12, j + 27, k + 27, Block.leaves.blockID);
		world.setBlock(i + 12, j + 27, k + 28, Block.leaves.blockID);
		world.setBlock(i + 12, j + 27, k + 29, Block.leaves.blockID);
		world.setBlock(i + 12, j + 27, k + 30, Block.wood.blockID);
		world.setBlock(i + 12, j + 27, k + 31, Block.leaves.blockID);
		world.setBlock(i + 12, j + 28, k + 28, Block.leaves.blockID);
		world.setBlock(i + 12, j + 28, k + 29, Block.leaves.blockID);
		world.setBlock(i + 12, j + 28, k + 30, Block.wood.blockID);
		world.setBlock(i + 12, j + 28, k + 31, Block.leaves.blockID);
		world.setBlock(i + 12, j + 28, k + 32, Block.leaves.blockID);
		world.setBlock(i + 12, j + 29, k + 28, Block.leaves.blockID);
		world.setBlock(i + 12, j + 29, k + 29, Block.leaves.blockID);
		world.setBlock(i + 12, j + 29, k + 30, Block.leaves.blockID);
		world.setBlock(i + 12, j + 29, k + 31, Block.leaves.blockID);
		world.setBlock(i + 12, j + 29, k + 32, Block.leaves.blockID);
		world.setBlock(i + 12, j + 29, k + 33, Block.leaves.blockID);
		world.setBlock(i + 12, j + 30, k + 28, Block.leaves.blockID);
		world.setBlock(i + 12, j + 30, k + 29, Block.leaves.blockID);
		world.setBlock(i + 12, j + 30, k + 30, Block.leaves.blockID);
		world.setBlock(i + 12, j + 30, k + 31, Block.leaves.blockID);
		world.setBlock(i + 12, j + 30, k + 32, Block.leaves.blockID);
		world.setBlock(i + 12, j + 31, k + 29, Block.leaves.blockID);
		world.setBlock(i + 12, j + 31, k + 30, Block.leaves.blockID);
		world.setBlock(i + 12, j + 31, k + 31, Block.leaves.blockID);
		world.setBlock(i + 12, j + 31, k + 32, Block.leaves.blockID);
		world.setBlock(i + 12, j + 32, k + 29, Block.leaves.blockID);
		world.setBlock(i + 12, j + 32, k + 30, Block.leaves.blockID);
		world.setBlock(i + 12, j + 32, k + 31, Block.leaves.blockID);
		world.setBlock(i + 13, j + 0, k + 13, Block.wood.blockID);
		world.setBlock(i + 13, j + 0, k + 14, Block.wood.blockID);
		world.setBlock(i + 13, j + 0, k + 15, Block.wood.blockID);
		world.setBlock(i + 13, j + 0, k + 31, Block.wood.blockID);
		world.setBlock(i + 13, j + 0, k + 32, Block.wood.blockID);
		world.setBlock(i + 13, j + 1, k + 13, Block.wood.blockID);
		world.setBlock(i + 13, j + 1, k + 14, Block.wood.blockID);
		world.setBlock(i + 13, j + 1, k + 15, Block.wood.blockID);
		world.setBlock(i + 13, j + 1, k + 32, Block.wood.blockID);
		world.setBlock(i + 13, j + 2, k + 14, Block.wood.blockID);
		world.setBlock(i + 13, j + 2, k + 15, Block.wood.blockID);
		world.setBlock(i + 13, j + 6, k + 12, Block.leaves.blockID);
		world.setBlock(i + 13, j + 6, k + 13, Block.leaves.blockID);
		world.setBlock(i + 13, j + 6, k + 14, Block.leaves.blockID);
		world.setBlock(i + 13, j + 6, k + 15, Block.leaves.blockID);
		world.setBlock(i + 13, j + 6, k + 16, Block.leaves.blockID);
		world.setBlock(i + 13, j + 6, k + 17, Block.leaves.blockID);
		world.setBlock(i + 13, j + 7, k + 12, Block.leaves.blockID);
		world.setBlock(i + 13, j + 7, k + 13, Block.leaves.blockID);
		world.setBlock(i + 13, j + 7, k + 14, Block.leaves.blockID);
		world.setBlock(i + 13, j + 7, k + 15, Block.leaves.blockID);
		world.setBlock(i + 13, j + 7, k + 16, Block.leaves.blockID);
		world.setBlock(i + 13, j + 7, k + 17, Block.leaves.blockID);
		world.setBlock(i + 13, j + 8, k + 11, Block.leaves.blockID);
		world.setBlock(i + 13, j + 8, k + 12, Block.leaves.blockID);
		world.setBlock(i + 13, j + 8, k + 13, Block.leaves.blockID);
		world.setBlock(i + 13, j + 8, k + 14, Block.leaves.blockID);
		world.setBlock(i + 13, j + 8, k + 15, Block.leaves.blockID);
		world.setBlock(i + 13, j + 8, k + 16, Block.leaves.blockID);
		world.setBlock(i + 13, j + 9, k + 12, Block.leaves.blockID);
		world.setBlock(i + 13, j + 9, k + 13, Block.leaves.blockID);
		world.setBlock(i + 13, j + 9, k + 14, Block.leaves.blockID);
		world.setBlock(i + 13, j + 9, k + 15, Block.leaves.blockID);
		world.setBlock(i + 13, j + 19, k + 30, Block.leaves.blockID);
		world.setBlock(i + 13, j + 20, k + 29, Block.leaves.blockID);
		world.setBlock(i + 13, j + 20, k + 30, Block.leaves.blockID);
		world.setBlock(i + 13, j + 20, k + 31, Block.leaves.blockID);
		world.setBlock(i + 13, j + 21, k + 27, Block.leaves.blockID);
		world.setBlock(i + 13, j + 21, k + 28, Block.leaves.blockID);
		world.setBlock(i + 13, j + 21, k + 29, Block.wood.blockID);
		world.setBlock(i + 13, j + 21, k + 30, Block.wood.blockID);
		world.setBlock(i + 13, j + 21, k + 31, Block.wood.blockID);
		world.setBlock(i + 13, j + 21, k + 32, Block.leaves.blockID);
		world.setBlock(i + 13, j + 22, k + 28, Block.leaves.blockID);
		world.setBlock(i + 13, j + 22, k + 29, Block.wood.blockID);
		world.setBlock(i + 13, j + 22, k + 30, Block.wood.blockID);
		world.setBlock(i + 13, j + 22, k + 31, Block.wood.blockID);
		world.setBlock(i + 13, j + 22, k + 32, Block.leaves.blockID);
		world.setBlock(i + 13, j + 26, k + 29, Block.leaves.blockID);
		world.setBlock(i + 13, j + 26, k + 30, Block.leaves.blockID);
		world.setBlock(i + 13, j + 26, k + 31, Block.leaves.blockID);
		world.setBlock(i + 13, j + 27, k + 27, Block.leaves.blockID);
		world.setBlock(i + 13, j + 27, k + 28, Block.leaves.blockID);
		world.setBlock(i + 13, j + 27, k + 29, Block.leaves.blockID);
		world.setBlock(i + 13, j + 27, k + 30, Block.wood.blockID);
		world.setBlock(i + 13, j + 27, k + 31, Block.leaves.blockID);
		world.setBlock(i + 13, j + 27, k + 32, Block.leaves.blockID);
		world.setBlock(i + 13, j + 28, k + 28, Block.leaves.blockID);
		world.setBlock(i + 13, j + 28, k + 29, Block.leaves.blockID);
		world.setBlock(i + 13, j + 28, k + 30, Block.wood.blockID);
		world.setBlock(i + 13, j + 28, k + 31, Block.leaves.blockID);
		world.setBlock(i + 13, j + 28, k + 32, Block.leaves.blockID);
		world.setBlock(i + 13, j + 28, k + 33, Block.leaves.blockID);
		world.setBlock(i + 13, j + 29, k + 29, Block.leaves.blockID);
		world.setBlock(i + 13, j + 29, k + 30, Block.leaves.blockID);
		world.setBlock(i + 13, j + 29, k + 31, Block.leaves.blockID);
		world.setBlock(i + 13, j + 29, k + 32, Block.leaves.blockID);
		world.setBlock(i + 13, j + 29, k + 33, Block.leaves.blockID);
		world.setBlock(i + 13, j + 30, k + 31, Block.leaves.blockID);
		world.setBlock(i + 13, j + 31, k + 30, Block.leaves.blockID);
		world.setBlock(i + 13, j + 31, k + 31, Block.leaves.blockID);
		world.setBlock(i + 14, j + 0, k + 30, Block.wood.blockID);
		world.setBlock(i + 14, j + 0, k + 31, Block.wood.blockID);
		world.setBlock(i + 14, j + 1, k + 13, Block.wood.blockID);
		world.setBlock(i + 14, j + 1, k + 14, Block.wood.blockID);
		world.setBlock(i + 14, j + 1, k + 31, Block.wood.blockID);
		world.setBlock(i + 14, j + 2, k + 13, Block.wood.blockID);
		world.setBlock(i + 14, j + 2, k + 14, Block.wood.blockID);
		world.setBlock(i + 14, j + 6, k + 17, Block.leaves.blockID);
		world.setBlock(i + 14, j + 7, k + 12, Block.leaves.blockID);
		world.setBlock(i + 14, j + 7, k + 13, Block.leaves.blockID);
		world.setBlock(i + 14, j + 7, k + 14, Block.leaves.blockID);
		world.setBlock(i + 14, j + 7, k + 15, Block.leaves.blockID);
		world.setBlock(i + 14, j + 7, k + 16, Block.leaves.blockID);
		world.setBlock(i + 14, j + 8, k + 12, Block.leaves.blockID);
		world.setBlock(i + 14, j + 8, k + 13, Block.leaves.blockID);
		world.setBlock(i + 14, j + 8, k + 14, Block.leaves.blockID);
		world.setBlock(i + 14, j + 8, k + 15, Block.leaves.blockID);
		world.setBlock(i + 14, j + 19, k + 30, Block.leaves.blockID);
		world.setBlock(i + 14, j + 20, k + 28, Block.leaves.blockID);
		world.setBlock(i + 14, j + 20, k + 29, Block.leaves.blockID);
		world.setBlock(i + 14, j + 20, k + 30, Block.leaves.blockID);
		world.setBlock(i + 14, j + 20, k + 31, Block.leaves.blockID);
		world.setBlock(i + 14, j + 21, k + 27, Block.leaves.blockID);
		world.setBlock(i + 14, j + 21, k + 28, Block.leaves.blockID);
		world.setBlock(i + 14, j + 21, k + 29, Block.wood.blockID);
		world.setBlock(i + 14, j + 21, k + 30, Block.wood.blockID);
		world.setBlock(i + 14, j + 21, k + 31, Block.wood.blockID);
		world.setBlock(i + 14, j + 21, k + 32, Block.leaves.blockID);
		world.setBlock(i + 14, j + 22, k + 28, Block.leaves.blockID);
		world.setBlock(i + 14, j + 22, k + 29, Block.wood.blockID);
		world.setBlock(i + 14, j + 22, k + 30, Block.wood.blockID);
		world.setBlock(i + 14, j + 22, k + 31, Block.wood.blockID);
		world.setBlock(i + 14, j + 22, k + 32, Block.leaves.blockID);
		world.setBlock(i + 14, j + 23, k + 27, Block.leaves.blockID);
		world.setBlock(i + 14, j + 23, k + 28, Block.leaves.blockID);
		world.setBlock(i + 14, j + 23, k + 32, Block.leaves.blockID);
		world.setBlock(i + 14, j + 23, k + 33, Block.leaves.blockID);
		world.setBlock(i + 14, j + 23, k + 34, Block.leaves.blockID);
		world.setBlock(i + 14, j + 24, k + 26, Block.leaves.blockID);
		world.setBlock(i + 14, j + 24, k + 28, Block.leaves.blockID);
		world.setBlock(i + 14, j + 24, k + 32, Block.leaves.blockID);
		world.setBlock(i + 14, j + 24, k + 34, Block.leaves.blockID);
		world.setBlock(i + 14, j + 25, k + 27, Block.leaves.blockID);
		world.setBlock(i + 14, j + 25, k + 28, Block.leaves.blockID);
		world.setBlock(i + 14, j + 25, k + 29, Block.leaves.blockID);
		world.setBlock(i + 14, j + 25, k + 30, Block.leaves.blockID);
		world.setBlock(i + 14, j + 25, k + 31, Block.leaves.blockID);
		world.setBlock(i + 14, j + 25, k + 32, Block.leaves.blockID);
		world.setBlock(i + 14, j + 25, k + 33, Block.leaves.blockID);
		world.setBlock(i + 14, j + 26, k + 29, Block.leaves.blockID);
		world.setBlock(i + 14, j + 26, k + 30, Block.leaves.blockID);
		world.setBlock(i + 14, j + 26, k + 31, Block.leaves.blockID);
		world.setBlock(i + 14, j + 27, k + 27, Block.leaves.blockID);
		world.setBlock(i + 14, j + 27, k + 28, Block.leaves.blockID);
		world.setBlock(i + 14, j + 27, k + 29, Block.leaves.blockID);
		world.setBlock(i + 14, j + 27, k + 30, Block.wood.blockID);
		world.setBlock(i + 14, j + 27, k + 31, Block.leaves.blockID);
		world.setBlock(i + 14, j + 27, k + 32, Block.leaves.blockID);
		world.setBlock(i + 14, j + 28, k + 28, Block.leaves.blockID);
		world.setBlock(i + 14, j + 28, k + 29, Block.leaves.blockID);
		world.setBlock(i + 14, j + 28, k + 30, Block.leaves.blockID);
		world.setBlock(i + 14, j + 28, k + 31, Block.leaves.blockID);
		world.setBlock(i + 14, j + 28, k + 32, Block.leaves.blockID);
		world.setBlock(i + 14, j + 28, k + 33, Block.leaves.blockID);
		world.setBlock(i + 14, j + 29, k + 29, Block.leaves.blockID);
		world.setBlock(i + 14, j + 29, k + 30, Block.leaves.blockID);
		world.setBlock(i + 14, j + 29, k + 31, Block.leaves.blockID);
		world.setBlock(i + 14, j + 29, k + 32, Block.leaves.blockID);
		world.setBlock(i + 14, j + 30, k + 31, Block.leaves.blockID);
		world.setBlock(i + 14, j + 42, k + 23, Block.leaves.blockID);
		world.setBlock(i + 15, j + 0, k + 30, Block.wood.blockID);
		world.setBlock(i + 15, j + 0, k + 31, Block.wood.blockID);
		world.setBlock(i + 15, j + 1, k + 13, Block.wood.blockID);
		world.setBlock(i + 15, j + 1, k + 31, Block.wood.blockID);
		world.setBlock(i + 15, j + 7, k + 14, Block.leaves.blockID);
		world.setBlock(i + 15, j + 7, k + 15, Block.leaves.blockID);
		world.setBlock(i + 15, j + 19, k + 30, Block.leaves.blockID);
		world.setBlock(i + 15, j + 20, k + 28, Block.leaves.blockID);
		world.setBlock(i + 15, j + 20, k + 29, Block.leaves.blockID);
		world.setBlock(i + 15, j + 20, k + 30, Block.leaves.blockID);
		world.setBlock(i + 15, j + 20, k + 31, Block.leaves.blockID);
		world.setBlock(i + 15, j + 21, k + 27, Block.leaves.blockID);
		world.setBlock(i + 15, j + 21, k + 28, Block.leaves.blockID);
		world.setBlock(i + 15, j + 21, k + 29, Block.wood.blockID);
		world.setBlock(i + 15, j + 21, k + 30, Block.wood.blockID);
		world.setBlock(i + 15, j + 21, k + 31, Block.wood.blockID);
		world.setBlock(i + 15, j + 21, k + 32, Block.leaves.blockID);
		world.setBlock(i + 15, j + 22, k + 26, Block.leaves.blockID);
		world.setBlock(i + 15, j + 22, k + 27, Block.leaves.blockID);
		world.setBlock(i + 15, j + 22, k + 28, Block.wood.blockID);
		world.setBlock(i + 15, j + 22, k + 29, Block.wood.blockID);
		world.setBlock(i + 15, j + 22, k + 30, Block.wood.blockID);
		world.setBlock(i + 15, j + 22, k + 31, Block.wood.blockID);
		world.setBlock(i + 15, j + 22, k + 32, Block.wood.blockID);
		world.setBlock(i + 15, j + 22, k + 33, Block.leaves.blockID);
		world.setBlock(i + 15, j + 22, k + 34, Block.leaves.blockID);
		world.setBlock(i + 15, j + 23, k + 25, Block.leaves.blockID);
		world.setBlock(i + 15, j + 23, k + 26, Block.leaves.blockID);
		world.setBlock(i + 15, j + 23, k + 27, Block.leaves.blockID);
		world.setBlock(i + 15, j + 23, k + 28, Block.leaves.blockID);
		world.setBlock(i + 15, j + 23, k + 32, Block.leaves.blockID);
		world.setBlock(i + 15, j + 23, k + 33, Block.leaves.blockID);
		world.setBlock(i + 15, j + 23, k + 34, Block.leaves.blockID);
		world.setBlock(i + 15, j + 23, k + 35, Block.leaves.blockID);
		world.setBlock(i + 15, j + 24, k + 25, Block.leaves.blockID);
		world.setBlock(i + 15, j + 24, k + 26, Block.leaves.blockID);
		world.setBlock(i + 15, j + 24, k + 28, Block.leaves.blockID);
		world.setBlock(i + 15, j + 24, k + 32, Block.leaves.blockID);
		world.setBlock(i + 15, j + 24, k + 34, Block.leaves.blockID);
		world.setBlock(i + 15, j + 24, k + 35, Block.leaves.blockID);
		world.setBlock(i + 15, j + 25, k + 26, Block.leaves.blockID);
		world.setBlock(i + 15, j + 25, k + 27, Block.leaves.blockID);
		world.setBlock(i + 15, j + 25, k + 28, Block.leaves.blockID);
		world.setBlock(i + 15, j + 25, k + 29, Block.leaves.blockID);
		world.setBlock(i + 15, j + 25, k + 30, Block.leaves.blockID);
		world.setBlock(i + 15, j + 25, k + 31, Block.leaves.blockID);
		world.setBlock(i + 15, j + 25, k + 32, Block.leaves.blockID);
		world.setBlock(i + 15, j + 25, k + 33, Block.leaves.blockID);
		world.setBlock(i + 15, j + 25, k + 34, Block.leaves.blockID);
		world.setBlock(i + 15, j + 25, k + 35, Block.leaves.blockID);
		world.setBlock(i + 15, j + 26, k + 29, Block.leaves.blockID);
		world.setBlock(i + 15, j + 26, k + 30, Block.leaves.blockID);
		world.setBlock(i + 15, j + 26, k + 31, Block.leaves.blockID);
		world.setBlock(i + 15, j + 27, k + 27, Block.leaves.blockID);
		world.setBlock(i + 15, j + 27, k + 28, Block.leaves.blockID);
		world.setBlock(i + 15, j + 27, k + 29, Block.leaves.blockID);
		world.setBlock(i + 15, j + 27, k + 30, Block.wood.blockID);
		world.setBlock(i + 15, j + 27, k + 31, Block.leaves.blockID);
		world.setBlock(i + 15, j + 27, k + 32, Block.leaves.blockID);
		world.setBlock(i + 15, j + 28, k + 28, Block.leaves.blockID);
		world.setBlock(i + 15, j + 28, k + 29, Block.leaves.blockID);
		world.setBlock(i + 15, j + 28, k + 30, Block.leaves.blockID);
		world.setBlock(i + 15, j + 28, k + 31, Block.leaves.blockID);
		world.setBlock(i + 15, j + 28, k + 32, Block.leaves.blockID);
		world.setBlock(i + 15, j + 28, k + 33, Block.leaves.blockID);
		world.setBlock(i + 15, j + 29, k + 29, Block.leaves.blockID);
		world.setBlock(i + 15, j + 29, k + 30, Block.leaves.blockID);
		world.setBlock(i + 15, j + 29, k + 31, Block.leaves.blockID);
		world.setBlock(i + 15, j + 29, k + 32, Block.leaves.blockID);
		world.setBlock(i + 15, j + 30, k + 30, Block.leaves.blockID);
		world.setBlock(i + 15, j + 30, k + 31, Block.leaves.blockID);
		world.setBlock(i + 15, j + 36, k + 31, Block.leaves.blockID);
		world.setBlock(i + 15, j + 42, k + 23, Block.leaves.blockID);
		world.setBlock(i + 15, j + 42, k + 24, Block.leaves.blockID);
		world.setBlock(i + 15, j + 43, k + 23, Block.leaves.blockID);
		world.setBlock(i + 16, j + 0, k + 13, Block.wood.blockID);
		world.setBlock(i + 16, j + 1, k + 13, Block.wood.blockID);
		world.setBlock(i + 16, j + 1, k + 30, Block.wood.blockID);
		world.setBlock(i + 16, j + 1, k + 31, Block.wood.blockID);
		world.setBlock(i + 16, j + 2, k + 31, Block.wood.blockID);
		world.setBlock(i + 16, j + 19, k + 29, Block.leaves.blockID);
		world.setBlock(i + 16, j + 19, k + 30, Block.leaves.blockID);
		world.setBlock(i + 16, j + 20, k + 28, Block.leaves.blockID);
		world.setBlock(i + 16, j + 20, k + 29, Block.wood.blockID);
		world.setBlock(i + 16, j + 20, k + 30, Block.wood.blockID);
		world.setBlock(i + 16, j + 20, k + 31, Block.leaves.blockID);
		world.setBlock(i + 16, j + 21, k + 26, Block.leaves.blockID);
		world.setBlock(i + 16, j + 21, k + 27, Block.leaves.blockID);
		world.setBlock(i + 16, j + 21, k + 28, Block.leaves.blockID);
		world.setBlock(i + 16, j + 21, k + 29, Block.wood.blockID);
		world.setBlock(i + 16, j + 21, k + 30, Block.wood.blockID);
		world.setBlock(i + 16, j + 21, k + 31, Block.wood.blockID);
		world.setBlock(i + 16, j + 21, k + 32, Block.leaves.blockID);
		world.setBlock(i + 16, j + 21, k + 33, Block.leaves.blockID);
		world.setBlock(i + 16, j + 21, k + 34, Block.leaves.blockID);
		world.setBlock(i + 16, j + 22, k + 25, Block.leaves.blockID);
		world.setBlock(i + 16, j + 22, k + 26, Block.wood.blockID);
		world.setBlock(i + 16, j + 22, k + 27, Block.wood.blockID);
		world.setBlock(i + 16, j + 22, k + 28, Block.wood.blockID);
		world.setBlock(i + 16, j + 22, k + 29, Block.wood.blockID);
		world.setBlock(i + 16, j + 22, k + 30, Block.wood.blockID);
		world.setBlock(i + 16, j + 22, k + 31, Block.wood.blockID);
		world.setBlock(i + 16, j + 22, k + 32, Block.wood.blockID);
		world.setBlock(i + 16, j + 22, k + 33, Block.wood.blockID);
		world.setBlock(i + 16, j + 22, k + 34, Block.wood.blockID);
		world.setBlock(i + 16, j + 22, k + 35, Block.leaves.blockID);
		world.setBlock(i + 16, j + 23, k + 24, Block.leaves.blockID);
		world.setBlock(i + 16, j + 23, k + 25, Block.leaves.blockID);
		world.setBlock(i + 16, j + 23, k + 26, Block.wood.blockID);
		world.setBlock(i + 16, j + 23, k + 27, Block.wood.blockID);
		world.setBlock(i + 16, j + 23, k + 28, Block.wood.blockID);
		world.setBlock(i + 16, j + 23, k + 32, Block.wood.blockID);
		world.setBlock(i + 16, j + 23, k + 33, Block.wood.blockID);
		world.setBlock(i + 16, j + 23, k + 34, Block.wood.blockID);
		world.setBlock(i + 16, j + 23, k + 35, Block.leaves.blockID);
		world.setBlock(i + 16, j + 23, k + 36, Block.leaves.blockID);
		world.setBlock(i + 16, j + 24, k + 25, Block.leaves.blockID);
		world.setBlock(i + 16, j + 24, k + 26, Block.wood.blockID);
		world.setBlock(i + 16, j + 24, k + 28, Block.wood.blockID);
		world.setBlock(i + 16, j + 24, k + 32, Block.wood.blockID);
		world.setBlock(i + 16, j + 24, k + 34, Block.wood.blockID);
		world.setBlock(i + 16, j + 24, k + 35, Block.leaves.blockID);
		world.setBlock(i + 16, j + 25, k + 25, Block.leaves.blockID);
		world.setBlock(i + 16, j + 25, k + 26, Block.wood.blockID);
		world.setBlock(i + 16, j + 25, k + 27, Block.wood.blockID);
		world.setBlock(i + 16, j + 25, k + 28, Block.wood.blockID);
		world.setBlock(i + 16, j + 25, k + 29, Block.wood.blockID);
		world.setBlock(i + 16, j + 25, k + 30, Block.wood.blockID);
		world.setBlock(i + 16, j + 25, k + 31, Block.wood.blockID);
		world.setBlock(i + 16, j + 25, k + 32, Block.wood.blockID);
		world.setBlock(i + 16, j + 25, k + 33, Block.wood.blockID);
		world.setBlock(i + 16, j + 25, k + 34, Block.wood.blockID);
		world.setBlock(i + 16, j + 25, k + 35, Block.leaves.blockID);
		world.setBlock(i + 16, j + 26, k + 26, Block.leaves.blockID);
		world.setBlock(i + 16, j + 26, k + 27, Block.leaves.blockID);
		world.setBlock(i + 16, j + 26, k + 28, Block.leaves.blockID);
		world.setBlock(i + 16, j + 26, k + 29, Block.leaves.blockID);
		world.setBlock(i + 16, j + 26, k + 30, Block.leaves.blockID);
		world.setBlock(i + 16, j + 26, k + 31, Block.leaves.blockID);
		world.setBlock(i + 16, j + 26, k + 32, Block.leaves.blockID);
		world.setBlock(i + 16, j + 26, k + 33, Block.leaves.blockID);
		world.setBlock(i + 16, j + 26, k + 34, Block.leaves.blockID);
		world.setBlock(i + 16, j + 27, k + 27, Block.leaves.blockID);
		world.setBlock(i + 16, j + 27, k + 28, Block.leaves.blockID);
		world.setBlock(i + 16, j + 27, k + 29, Block.leaves.blockID);
		world.setBlock(i + 16, j + 27, k + 30, Block.wood.blockID);
		world.setBlock(i + 16, j + 27, k + 31, Block.leaves.blockID);
		world.setBlock(i + 16, j + 27, k + 32, Block.leaves.blockID);
		world.setBlock(i + 16, j + 28, k + 28, Block.leaves.blockID);
		world.setBlock(i + 16, j + 28, k + 29, Block.leaves.blockID);
		world.setBlock(i + 16, j + 28, k + 30, Block.wood.blockID);
		world.setBlock(i + 16, j + 28, k + 31, Block.leaves.blockID);
		world.setBlock(i + 16, j + 28, k + 32, Block.leaves.blockID);
		world.setBlock(i + 16, j + 28, k + 33, Block.leaves.blockID);
		world.setBlock(i + 16, j + 29, k + 29, Block.leaves.blockID);
		world.setBlock(i + 16, j + 29, k + 30, Block.leaves.blockID);
		world.setBlock(i + 16, j + 29, k + 31, Block.leaves.blockID);
		world.setBlock(i + 16, j + 29, k + 32, Block.leaves.blockID);
		world.setBlock(i + 16, j + 30, k + 30, Block.leaves.blockID);
		world.setBlock(i + 16, j + 30, k + 31, Block.leaves.blockID);
		world.setBlock(i + 16, j + 34, k + 31, Block.leaves.blockID);
		world.setBlock(i + 16, j + 36, k + 30, Block.leaves.blockID);
		world.setBlock(i + 16, j + 36, k + 31, Block.leaves.blockID);
		world.setBlock(i + 16, j + 37, k + 31, Block.leaves.blockID);
		world.setBlock(i + 16, j + 40, k + 24, Block.leaves.blockID);
		world.setBlock(i + 16, j + 41, k + 23, Block.leaves.blockID);
		world.setBlock(i + 16, j + 41, k + 24, Block.leaves.blockID);
		world.setBlock(i + 16, j + 42, k + 22, Block.leaves.blockID);
		world.setBlock(i + 16, j + 42, k + 23, Block.leaves.blockID);
		world.setBlock(i + 16, j + 42, k + 24, Block.leaves.blockID);
		world.setBlock(i + 16, j + 42, k + 25, Block.leaves.blockID);
		world.setBlock(i + 16, j + 43, k + 23, Block.leaves.blockID);
		world.setBlock(i + 16, j + 43, k + 24, Block.leaves.blockID);
		world.setBlock(i + 17, j + 0, k + 14, Block.wood.blockID);
		world.setBlock(i + 17, j + 0, k + 28, Block.dirt.blockID);
		world.setBlock(i + 17, j + 1, k + 14, Block.wood.blockID);
		world.setBlock(i + 17, j + 2, k + 29, Block.wood.blockID);
		world.setBlock(i + 17, j + 2, k + 30, Block.wood.blockID);
		world.setBlock(i + 17, j + 2, k + 31, Block.wood.blockID);
		world.setBlock(i + 17, j + 3, k + 30, Block.wood.blockID);
		world.setBlock(i + 17, j + 3, k + 31, Block.wood.blockID);
		world.setBlock(i + 17, j + 19, k + 29, Block.leaves.blockID);
		world.setBlock(i + 17, j + 19, k + 30, Block.leaves.blockID);
		world.setBlock(i + 17, j + 20, k + 27, Block.leaves.blockID);
		world.setBlock(i + 17, j + 20, k + 28, Block.leaves.blockID);
		world.setBlock(i + 17, j + 20, k + 29, Block.wood.blockID);
		world.setBlock(i + 17, j + 20, k + 30, Block.wood.blockID);
		world.setBlock(i + 17, j + 20, k + 31, Block.leaves.blockID);
		world.setBlock(i + 17, j + 20, k + 32, Block.leaves.blockID);
		world.setBlock(i + 17, j + 21, k + 26, Block.leaves.blockID);
		world.setBlock(i + 17, j + 21, k + 27, Block.wood.blockID);
		world.setBlock(i + 17, j + 21, k + 28, Block.wood.blockID);
		world.setBlock(i + 17, j + 21, k + 29, Block.wood.blockID);
		world.setBlock(i + 17, j + 21, k + 30, Block.wood.blockID);
		world.setBlock(i + 17, j + 21, k + 31, Block.wood.blockID);
		world.setBlock(i + 17, j + 21, k + 32, Block.wood.blockID);
		world.setBlock(i + 17, j + 21, k + 33, Block.leaves.blockID);
		world.setBlock(i + 17, j + 21, k + 34, Block.leaves.blockID);
		world.setBlock(i + 17, j + 22, k + 24, Block.leaves.blockID);
		world.setBlock(i + 17, j + 22, k + 25, Block.leaves.blockID);
		world.setBlock(i + 17, j + 22, k + 26, Block.wood.blockID);
		world.setBlock(i + 17, j + 22, k + 27, Block.wood.blockID);
		world.setBlock(i + 17, j + 22, k + 28, Block.wood.blockID);
		world.setBlock(i + 17, j + 22, k + 29, Block.wood.blockID);
		world.setBlock(i + 17, j + 22, k + 30, Block.wood.blockID);
		world.setBlock(i + 17, j + 22, k + 31, Block.wood.blockID);
		world.setBlock(i + 17, j + 22, k + 32, Block.wood.blockID);
		world.setBlock(i + 17, j + 22, k + 33, Block.wood.blockID);
		world.setBlock(i + 17, j + 22, k + 34, Block.wood.blockID);
		world.setBlock(i + 17, j + 22, k + 35, Block.leaves.blockID);
		world.setBlock(i + 17, j + 23, k + 25, Block.leaves.blockID);
		world.setBlock(i + 17, j + 23, k + 26, Block.wood.blockID);
		world.setBlock(i + 17, j + 23, k + 27, Block.chest.blockID);
		world.setBlockAndMetadata(i + 17, j + 23, k + 33, Block.stoneOvenIdle.blockID, 2);
		world.setBlock(i + 17, j + 23, k + 34, Block.wood.blockID);
		world.setBlock(i + 17, j + 23, k + 35, Block.leaves.blockID);
		world.setBlock(i + 17, j + 23, k + 36, Block.leaves.blockID);
		world.setBlock(i + 17, j + 25, k + 25, Block.leaves.blockID);
		world.setBlock(i + 17, j + 25, k + 26, Block.wood.blockID);
		world.setBlock(i + 17, j + 25, k + 34, Block.wood.blockID);
		world.setBlock(i + 17, j + 25, k + 35, Block.leaves.blockID);
		world.setBlock(i + 17, j + 26, k + 26, Block.leaves.blockID);
		world.setBlock(i + 17, j + 26, k + 27, Block.wood.blockID);
		world.setBlock(i + 17, j + 26, k + 28, Block.wood.blockID);
		world.setBlock(i + 17, j + 26, k + 29, Block.wood.blockID);
		world.setBlock(i + 17, j + 26, k + 30, Block.wood.blockID);
		world.setBlock(i + 17, j + 26, k + 31, Block.wood.blockID);
		world.setBlock(i + 17, j + 26, k + 32, Block.wood.blockID);
		world.setBlock(i + 17, j + 26, k + 33, Block.wood.blockID);
		world.setBlock(i + 17, j + 26, k + 34, Block.leaves.blockID);
		world.setBlock(i + 17, j + 27, k + 27, Block.leaves.blockID);
		world.setBlock(i + 17, j + 27, k + 28, Block.leaves.blockID);
		world.setBlock(i + 17, j + 27, k + 29, Block.wood.blockID);
		world.setBlock(i + 17, j + 27, k + 30, Block.wood.blockID);
		world.setBlock(i + 17, j + 27, k + 31, Block.wood.blockID);
		world.setBlock(i + 17, j + 27, k + 32, Block.leaves.blockID);
		world.setBlock(i + 17, j + 27, k + 33, Block.leaves.blockID);
		world.setBlock(i + 17, j + 28, k + 28, Block.leaves.blockID);
		world.setBlock(i + 17, j + 28, k + 29, Block.leaves.blockID);
		world.setBlock(i + 17, j + 28, k + 30, Block.wood.blockID);
		world.setBlock(i + 17, j + 28, k + 31, Block.leaves.blockID);
		world.setBlock(i + 17, j + 28, k + 32, Block.leaves.blockID);
		world.setBlock(i + 17, j + 28, k + 33, Block.leaves.blockID);
		world.setBlock(i + 17, j + 29, k + 29, Block.leaves.blockID);
		world.setBlock(i + 17, j + 29, k + 30, Block.leaves.blockID);
		world.setBlock(i + 17, j + 29, k + 31, Block.leaves.blockID);
		world.setBlock(i + 17, j + 29, k + 32, Block.leaves.blockID);
		world.setBlock(i + 17, j + 30, k + 30, Block.leaves.blockID);
		world.setBlock(i + 17, j + 30, k + 31, Block.leaves.blockID);
		world.setBlock(i + 17, j + 31, k + 35, Block.leaves.blockID);
		world.setBlock(i + 17, j + 33, k + 21, Block.leaves.blockID);
		world.setBlock(i + 17, j + 34, k + 20, Block.leaves.blockID);
		world.setBlock(i + 17, j + 34, k + 21, Block.leaves.blockID);
		world.setBlock(i + 17, j + 34, k + 22, Block.leaves.blockID);
		world.setBlock(i + 17, j + 34, k + 31, Block.leaves.blockID);
		world.setBlock(i + 17, j + 35, k + 30, Block.leaves.blockID);
		world.setBlock(i + 17, j + 35, k + 31, Block.leaves.blockID);
		world.setBlock(i + 17, j + 36, k + 29, Block.leaves.blockID);
		world.setBlock(i + 17, j + 36, k + 30, Block.leaves.blockID);
		world.setBlock(i + 17, j + 36, k + 31, Block.wood.blockID);
		world.setBlock(i + 17, j + 36, k + 32, Block.leaves.blockID);
		world.setBlock(i + 17, j + 37, k + 30, Block.leaves.blockID);
		world.setBlock(i + 17, j + 37, k + 31, Block.leaves.blockID);
		world.setBlock(i + 17, j + 39, k + 23, Block.leaves.blockID);
		world.setBlock(i + 17, j + 39, k + 25, Block.leaves.blockID);
		world.setBlock(i + 17, j + 40, k + 22, Block.leaves.blockID);
		world.setBlock(i + 17, j + 40, k + 23, Block.leaves.blockID);
		world.setBlock(i + 17, j + 40, k + 24, Block.leaves.blockID);
		world.setBlock(i + 17, j + 40, k + 25, Block.leaves.blockID);
		world.setBlock(i + 17, j + 41, k + 22, Block.leaves.blockID);
		world.setBlock(i + 17, j + 41, k + 23, Block.wood.blockID);
		world.setBlock(i + 17, j + 41, k + 24, Block.leaves.blockID);
		world.setBlock(i + 17, j + 42, k + 22, Block.leaves.blockID);
		world.setBlock(i + 17, j + 42, k + 23, Block.leaves.blockID);
		world.setBlock(i + 17, j + 42, k + 24, Block.leaves.blockID);
		world.setBlock(i + 17, j + 42, k + 25, Block.leaves.blockID);
		world.setBlock(i + 17, j + 43, k + 22, Block.leaves.blockID);
		world.setBlock(i + 17, j + 43, k + 23, Block.leaves.blockID);
		world.setBlock(i + 17, j + 43, k + 24, Block.leaves.blockID);
		world.setBlock(i + 17, j + 44, k + 23, Block.leaves.blockID);
		world.setBlock(i + 18, j + 0, k + 14, Block.wood.blockID);
		world.setBlock(i + 18, j + 0, k + 15, Block.wood.blockID);
		world.setBlock(i + 18, j + 0, k + 16, Block.wood.blockID);
		world.setBlock(i + 18, j + 3, k + 29, Block.wood.blockID);
		world.setBlock(i + 18, j + 3, k + 30, Block.wood.blockID);
		world.setBlock(i + 18, j + 3, k + 31, Block.wood.blockID);
		world.setBlock(i + 18, j + 4, k + 30, Block.wood.blockID);
		world.setBlock(i + 18, j + 19, k + 29, Block.leaves.blockID);
		world.setBlock(i + 18, j + 19, k + 30, Block.leaves.blockID);
		world.setBlock(i + 18, j + 20, k + 27, Block.leaves.blockID);
		world.setBlock(i + 18, j + 20, k + 28, Block.leaves.blockID);
		world.setBlock(i + 18, j + 20, k + 29, Block.wood.blockID);
		world.setBlock(i + 18, j + 20, k + 30, Block.wood.blockID);
		world.setBlock(i + 18, j + 20, k + 31, Block.leaves.blockID);
		world.setBlock(i + 18, j + 20, k + 32, Block.leaves.blockID);
		world.setBlock(i + 18, j + 20, k + 33, Block.leaves.blockID);
		world.setBlock(i + 18, j + 21, k + 26, Block.leaves.blockID);
		world.setBlock(i + 18, j + 21, k + 27, Block.wood.blockID);
		world.setBlock(i + 18, j + 21, k + 29, Block.wood.blockID);
		world.setBlock(i + 18, j + 21, k + 30, Block.wood.blockID);
		world.setBlock(i + 18, j + 21, k + 31, Block.leaves.blockID);
		world.setBlock(i + 18, j + 21, k + 32, Block.wood.blockID);
		world.setBlock(i + 18, j + 21, k + 33, Block.wood.blockID);
		world.setBlock(i + 18, j + 21, k + 34, Block.leaves.blockID);
		world.setBlock(i + 18, j + 22, k + 25, Block.leaves.blockID);
		world.setBlock(i + 18, j + 22, k + 26, Block.wood.blockID);
		world.setBlock(i + 18, j + 22, k + 27, Block.wood.blockID);
		world.setBlock(i + 18, j + 22, k + 28, Block.wood.blockID);
		world.setBlock(i + 18, j + 22, k + 29, Block.wood.blockID);
		world.setBlock(i + 18, j + 22, k + 30, Block.wood.blockID);
		world.setBlock(i + 18, j + 22, k + 31, Block.wood.blockID);
		world.setBlock(i + 18, j + 22, k + 32, Block.wood.blockID);
		world.setBlock(i + 18, j + 22, k + 33, Block.wood.blockID);
		world.setBlock(i + 18, j + 22, k + 34, Block.wood.blockID);
		world.setBlock(i + 18, j + 22, k + 35, Block.leaves.blockID);
		world.setBlock(i + 18, j + 23, k + 24, Block.leaves.blockID);
		world.setBlock(i + 18, j + 23, k + 25, Block.leaves.blockID);
		world.setBlock(i + 18, j + 23, k + 26, Block.wood.blockID);
		world.setBlockAndMetadata(i + 18, j + 23, k + 27, Block.stairCompactPlanks.blockID, 3);
		world.setBlock(i + 18, j + 23, k + 29, Block.stoneSingleSlab.blockID);
		world.setBlock(i + 18, j + 23, k + 32, Block.bed.blockID);
		world.setBlockAndMetadata(i + 18, j + 23, k + 33, Block.bed.blockID, 8);
		world.setBlock(i + 18, j + 23, k + 34, Block.wood.blockID);
		world.setBlock(i + 18, j + 23, k + 35, Block.leaves.blockID);
		world.setBlock(i + 18, j + 23, k + 36, Block.leaves.blockID);
		world.setBlock(i + 18, j + 25, k + 25, Block.leaves.blockID);
		world.setBlock(i + 18, j + 25, k + 26, Block.wood.blockID);
		world.setBlock(i + 18, j + 25, k + 34, Block.wood.blockID);
		world.setBlock(i + 18, j + 25, k + 35, Block.leaves.blockID);
		world.setBlock(i + 18, j + 26, k + 26, Block.leaves.blockID);
		world.setBlock(i + 18, j + 26, k + 27, Block.wood.blockID);
		world.setBlock(i + 18, j + 26, k + 33, Block.wood.blockID);
		world.setBlock(i + 18, j + 26, k + 34, Block.leaves.blockID);
		world.setBlock(i + 18, j + 27, k + 26, Block.leaves.blockID);
		world.setBlock(i + 18, j + 27, k + 27, Block.leaves.blockID);
		world.setBlock(i + 18, j + 27, k + 28, Block.wood.blockID);
		world.setBlock(i + 18, j + 27, k + 29, Block.wood.blockID);
		world.setBlock(i + 18, j + 27, k + 30, Block.wood.blockID);
		world.setBlock(i + 18, j + 27, k + 31, Block.wood.blockID);
		world.setBlock(i + 18, j + 27, k + 32, Block.wood.blockID);
		world.setBlock(i + 18, j + 27, k + 33, Block.leaves.blockID);
		world.setBlock(i + 18, j + 28, k + 28, Block.leaves.blockID);
		world.setBlock(i + 18, j + 28, k + 29, Block.leaves.blockID);
		world.setBlock(i + 18, j + 28, k + 30, Block.wood.blockID);
		world.setBlock(i + 18, j + 28, k + 31, Block.leaves.blockID);
		world.setBlock(i + 18, j + 28, k + 32, Block.leaves.blockID);
		world.setBlock(i + 18, j + 28, k + 33, Block.leaves.blockID);
		world.setBlock(i + 18, j + 29, k + 29, Block.leaves.blockID);
		world.setBlock(i + 18, j + 29, k + 30, Block.wood.blockID);
		world.setBlock(i + 18, j + 29, k + 31, Block.leaves.blockID);
		world.setBlock(i + 18, j + 29, k + 32, Block.leaves.blockID);
		world.setBlock(i + 18, j + 29, k + 33, Block.leaves.blockID);
		world.setBlock(i + 18, j + 29, k + 34, Block.leaves.blockID);
		world.setBlock(i + 18, j + 30, k + 30, Block.leaves.blockID);
		world.setBlock(i + 18, j + 30, k + 31, Block.leaves.blockID);
		world.setBlock(i + 18, j + 30, k + 32, Block.leaves.blockID);
		world.setBlock(i + 18, j + 30, k + 33, Block.leaves.blockID);
		world.setBlock(i + 18, j + 30, k + 34, Block.leaves.blockID);
		world.setBlock(i + 18, j + 30, k + 35, Block.leaves.blockID);
		world.setBlock(i + 18, j + 31, k + 34, Block.leaves.blockID);
		world.setBlock(i + 18, j + 31, k + 35, Block.leaves.blockID);
		world.setBlock(i + 18, j + 31, k + 36, Block.leaves.blockID);
		world.setBlock(i + 18, j + 32, k + 22, Block.leaves.blockID);
		world.setBlock(i + 18, j + 32, k + 33, Block.leaves.blockID);
		world.setBlock(i + 18, j + 32, k + 34, Block.leaves.blockID);
		world.setBlock(i + 18, j + 32, k + 35, Block.leaves.blockID);
		world.setBlock(i + 18, j + 33, k + 20, Block.leaves.blockID);
		world.setBlock(i + 18, j + 33, k + 21, Block.leaves.blockID);
		world.setBlock(i + 18, j + 33, k + 22, Block.leaves.blockID);
		world.setBlock(i + 18, j + 33, k + 33, Block.leaves.blockID);
		world.setBlock(i + 18, j + 33, k + 34, Block.leaves.blockID);
		world.setBlock(i + 18, j + 34, k + 20, Block.leaves.blockID);
		world.setBlock(i + 18, j + 34, k + 21, Block.leaves.blockID);
		world.setBlock(i + 18, j + 34, k + 22, Block.leaves.blockID);
		world.setBlock(i + 18, j + 34, k + 23, Block.leaves.blockID);
		world.setBlock(i + 18, j + 34, k + 30, Block.leaves.blockID);
		world.setBlock(i + 18, j + 34, k + 32, Block.leaves.blockID);
		world.setBlock(i + 18, j + 34, k + 33, Block.leaves.blockID);
		world.setBlock(i + 18, j + 35, k + 21, Block.leaves.blockID);
		world.setBlock(i + 18, j + 35, k + 22, Block.leaves.blockID);
		world.setBlock(i + 18, j + 35, k + 30, Block.leaves.blockID);
		world.setBlock(i + 18, j + 35, k + 31, Block.leaves.blockID);
		world.setBlock(i + 18, j + 35, k + 32, Block.leaves.blockID);
		world.setBlock(i + 18, j + 36, k + 29, Block.leaves.blockID);
		world.setBlock(i + 18, j + 36, k + 30, Block.leaves.blockID);
		world.setBlock(i + 18, j + 36, k + 31, Block.wood.blockID);
		world.setBlock(i + 18, j + 36, k + 32, Block.leaves.blockID);
		world.setBlock(i + 18, j + 37, k + 30, Block.leaves.blockID);
		world.setBlock(i + 18, j + 37, k + 31, Block.leaves.blockID);
		world.setBlock(i + 18, j + 38, k + 35, Block.leaves.blockID);
		world.setBlock(i + 18, j + 38, k + 36, Block.leaves.blockID);
		world.setBlock(i + 18, j + 39, k + 23, Block.leaves.blockID);
		world.setBlock(i + 18, j + 40, k + 22, Block.leaves.blockID);
		world.setBlock(i + 18, j + 40, k + 23, Block.leaves.blockID);
		world.setBlock(i + 18, j + 40, k + 24, Block.leaves.blockID);
		world.setBlock(i + 18, j + 40, k + 25, Block.leaves.blockID);
		world.setBlock(i + 18, j + 41, k + 22, Block.leaves.blockID);
		world.setBlock(i + 18, j + 41, k + 23, Block.wood.blockID);
		world.setBlock(i + 18, j + 41, k + 24, Block.leaves.blockID);
		world.setBlock(i + 18, j + 42, k + 22, Block.leaves.blockID);
		world.setBlock(i + 18, j + 42, k + 23, Block.leaves.blockID);
		world.setBlock(i + 18, j + 42, k + 24, Block.leaves.blockID);
		world.setBlock(i + 18, j + 42, k + 25, Block.leaves.blockID);
		world.setBlock(i + 18, j + 42, k + 26, Block.leaves.blockID);
		world.setBlock(i + 18, j + 43, k + 22, Block.leaves.blockID);
		world.setBlock(i + 18, j + 43, k + 24, Block.leaves.blockID);
		world.setBlock(i + 18, j + 43, k + 25, Block.leaves.blockID);
		world.setBlock(i + 18, j + 43, k + 26, Block.leaves.blockID);
		world.setBlock(i + 18, j + 44, k + 24, Block.leaves.blockID);
		world.setBlock(i + 18, j + 44, k + 25, Block.leaves.blockID);
		world.setBlock(i + 19, j + 0, k + 15, Block.wood.blockID);
		world.setBlock(i + 19, j + 0, k + 16, Block.wood.blockID);
		world.setBlock(i + 19, j + 0, k + 17, Block.wood.blockID);
		world.setBlock(i + 19, j + 3, k + 31, Block.wood.blockID);
		world.setBlock(i + 19, j + 4, k + 28, Block.wood.blockID);
		world.setBlock(i + 19, j + 4, k + 29, Block.wood.blockID);
		world.setBlock(i + 19, j + 4, k + 30, Block.wood.blockID);
		world.setBlock(i + 19, j + 19, k + 29, Block.leaves.blockID);
		world.setBlock(i + 19, j + 19, k + 30, Block.leaves.blockID);
		world.setBlock(i + 19, j + 20, k + 27, Block.leaves.blockID);
		world.setBlock(i + 19, j + 20, k + 28, Block.leaves.blockID);
		world.setBlock(i + 19, j + 20, k + 29, Block.wood.blockID);
		world.setBlock(i + 19, j + 20, k + 30, Block.wood.blockID);
		world.setBlock(i + 19, j + 20, k + 31, Block.leaves.blockID);
		world.setBlock(i + 19, j + 20, k + 32, Block.leaves.blockID);
		world.setBlock(i + 19, j + 20, k + 33, Block.leaves.blockID);
		world.setBlock(i + 19, j + 21, k + 26, Block.leaves.blockID);
		world.setBlock(i + 19, j + 21, k + 27, Block.wood.blockID);
		world.setBlock(i + 19, j + 21, k + 28, Block.leaves.blockID);
		world.setBlock(i + 19, j + 21, k + 29, Block.wood.blockID);
		world.setBlock(i + 19, j + 21, k + 30, Block.wood.blockID);
		world.setBlock(i + 19, j + 21, k + 31, Block.leaves.blockID);
		world.setBlock(i + 19, j + 21, k + 32, Block.wood.blockID);
		world.setBlock(i + 19, j + 21, k + 33, Block.wood.blockID);
		world.setBlock(i + 19, j + 21, k + 34, Block.leaves.blockID);
		world.setBlock(i + 19, j + 22, k + 25, Block.leaves.blockID);
		world.setBlock(i + 19, j + 22, k + 26, Block.wood.blockID);
		world.setBlock(i + 19, j + 22, k + 27, Block.wood.blockID);
		world.setBlock(i + 19, j + 22, k + 28, Block.wood.blockID);
		world.setBlock(i + 19, j + 22, k + 29, Block.wood.blockID);
		world.setBlock(i + 19, j + 22, k + 30, Block.wood.blockID);
		world.setBlock(i + 19, j + 22, k + 31, Block.wood.blockID);
		world.setBlock(i + 19, j + 22, k + 32, Block.wood.blockID);
		world.setBlock(i + 19, j + 22, k + 33, Block.wood.blockID);
		world.setBlock(i + 19, j + 22, k + 34, Block.wood.blockID);
		world.setBlock(i + 19, j + 22, k + 35, Block.leaves.blockID);
		world.setBlock(i + 19, j + 23, k + 23, Block.leaves.blockID);
		world.setBlock(i + 19, j + 23, k + 24, Block.leaves.blockID);
		world.setBlock(i + 19, j + 23, k + 25, Block.leaves.blockID);
		world.setBlock(i + 19, j + 23, k + 26, Block.wood.blockID);
		world.setBlockAndMetadata(i + 19, j + 23, k + 27, Block.stairCompactPlanks.blockID, 3);
		world.setBlock(i + 19, j + 23, k + 29, Block.stoneSingleSlab.blockID);
		world.setBlock(i + 19, j + 23, k + 32, Block.bed.blockID);
		world.setBlockAndMetadata(i + 19, j + 23, k + 33, Block.bed.blockID, 8);
		world.setBlock(i + 19, j + 23, k + 34, Block.wood.blockID);
		world.setBlock(i + 19, j + 23, k + 35, Block.leaves.blockID);
		world.setBlock(i + 19, j + 23, k + 36, Block.leaves.blockID);
		world.setBlock(i + 19, j + 25, k + 25, Block.leaves.blockID);
		world.setBlock(i + 19, j + 25, k + 26, Block.wood.blockID);
		world.setBlock(i + 19, j + 25, k + 34, Block.wood.blockID);
		world.setBlock(i + 19, j + 25, k + 35, Block.leaves.blockID);
		world.setBlock(i + 19, j + 26, k + 25, Block.leaves.blockID);
		world.setBlock(i + 19, j + 26, k + 26, Block.leaves.blockID);
		world.setBlock(i + 19, j + 26, k + 27, Block.wood.blockID);
		world.setBlock(i + 19, j + 26, k + 33, Block.wood.blockID);
		world.setBlock(i + 19, j + 26, k + 34, Block.leaves.blockID);
		world.setBlock(i + 19, j + 27, k + 26, Block.leaves.blockID);
		world.setBlock(i + 19, j + 27, k + 27, Block.leaves.blockID);
		world.setBlock(i + 19, j + 27, k + 28, Block.wood.blockID);
		world.setBlock(i + 19, j + 27, k + 29, Block.wood.blockID);
		world.setBlock(i + 19, j + 27, k + 30, Block.wood.blockID);
		world.setBlock(i + 19, j + 27, k + 31, Block.wood.blockID);
		world.setBlock(i + 19, j + 27, k + 32, Block.wood.blockID);
		world.setBlock(i + 19, j + 27, k + 33, Block.leaves.blockID);
		world.setBlock(i + 19, j + 28, k + 28, Block.leaves.blockID);
		world.setBlock(i + 19, j + 28, k + 29, Block.wood.blockID);
		world.setBlock(i + 19, j + 28, k + 30, Block.wood.blockID);
		world.setBlock(i + 19, j + 28, k + 31, Block.wood.blockID);
		world.setBlock(i + 19, j + 28, k + 32, Block.wood.blockID);
		world.setBlock(i + 19, j + 28, k + 33, Block.wood.blockID);
		world.setBlock(i + 19, j + 28, k + 34, Block.leaves.blockID);
		world.setBlock(i + 19, j + 29, k + 29, Block.leaves.blockID);
		world.setBlock(i + 19, j + 29, k + 30, Block.wood.blockID);
		world.setBlock(i + 19, j + 29, k + 31, Block.leaves.blockID);
		world.setBlock(i + 19, j + 29, k + 32, Block.leaves.blockID);
		world.setBlock(i + 19, j + 29, k + 33, Block.wood.blockID);
		world.setBlock(i + 19, j + 29, k + 34, Block.wood.blockID);
		world.setBlock(i + 19, j + 29, k + 35, Block.leaves.blockID);
		world.setBlock(i + 19, j + 30, k + 29, Block.leaves.blockID);
		world.setBlock(i + 19, j + 30, k + 30, Block.leaves.blockID);
		world.setBlock(i + 19, j + 30, k + 31, Block.leaves.blockID);
		world.setBlock(i + 19, j + 30, k + 32, Block.leaves.blockID);
		world.setBlock(i + 19, j + 30, k + 33, Block.leaves.blockID);
		world.setBlock(i + 19, j + 30, k + 34, Block.wood.blockID);
		world.setBlock(i + 19, j + 30, k + 35, Block.wood.blockID);
		world.setBlock(i + 19, j + 30, k + 36, Block.leaves.blockID);
		world.setBlock(i + 19, j + 31, k + 33, Block.leaves.blockID);
		world.setBlock(i + 19, j + 31, k + 34, Block.leaves.blockID);
		world.setBlock(i + 19, j + 31, k + 35, Block.wood.blockID);
		world.setBlock(i + 19, j + 31, k + 36, Block.leaves.blockID);
		world.setBlock(i + 19, j + 31, k + 37, Block.leaves.blockID);
		world.setBlock(i + 19, j + 32, k + 20, Block.leaves.blockID);
		world.setBlock(i + 19, j + 32, k + 21, Block.leaves.blockID);
		world.setBlock(i + 19, j + 32, k + 22, Block.leaves.blockID);
		world.setBlock(i + 19, j + 32, k + 33, Block.leaves.blockID);
		world.setBlock(i + 19, j + 32, k + 34, Block.leaves.blockID);
		world.setBlock(i + 19, j + 32, k + 35, Block.leaves.blockID);
		world.setBlock(i + 19, j + 32, k + 36, Block.leaves.blockID);
		world.setBlock(i + 19, j + 33, k + 20, Block.leaves.blockID);
		world.setBlock(i + 19, j + 33, k + 21, Block.leaves.blockID);
		world.setBlock(i + 19, j + 33, k + 22, Block.leaves.blockID);
		world.setBlock(i + 19, j + 33, k + 23, Block.leaves.blockID);
		world.setBlock(i + 19, j + 33, k + 33, Block.leaves.blockID);
		world.setBlock(i + 19, j + 33, k + 34, Block.leaves.blockID);
		world.setBlock(i + 19, j + 33, k + 35, Block.leaves.blockID);
		world.setBlock(i + 19, j + 33, k + 36, Block.leaves.blockID);
		world.setBlock(i + 19, j + 34, k + 19, Block.leaves.blockID);
		world.setBlock(i + 19, j + 34, k + 20, Block.leaves.blockID);
		world.setBlock(i + 19, j + 34, k + 21, Block.leaves.blockID);
		world.setBlock(i + 19, j + 34, k + 22, Block.wood.blockID);
		world.setBlock(i + 19, j + 34, k + 23, Block.leaves.blockID);
		world.setBlock(i + 19, j + 34, k + 31, Block.leaves.blockID);
		world.setBlock(i + 19, j + 34, k + 33, Block.leaves.blockID);
		world.setBlock(i + 19, j + 34, k + 35, Block.leaves.blockID);
		world.setBlock(i + 19, j + 35, k + 20, Block.leaves.blockID);
		world.setBlock(i + 19, j + 35, k + 21, Block.leaves.blockID);
		world.setBlock(i + 19, j + 35, k + 22, Block.leaves.blockID);
		world.setBlock(i + 19, j + 35, k + 23, Block.leaves.blockID);
		world.setBlock(i + 19, j + 35, k + 31, Block.leaves.blockID);
		world.setBlock(i + 19, j + 35, k + 32, Block.leaves.blockID);
		world.setBlock(i + 19, j + 35, k + 34, Block.leaves.blockID);
		world.setBlock(i + 19, j + 35, k + 35, Block.leaves.blockID);
		world.setBlock(i + 19, j + 36, k + 20, Block.leaves.blockID);
		world.setBlock(i + 19, j + 36, k + 22, Block.leaves.blockID);
		world.setBlock(i + 19, j + 36, k + 28, Block.leaves.blockID);
		world.setBlock(i + 19, j + 36, k + 29, Block.leaves.blockID);
		world.setBlock(i + 19, j + 36, k + 30, Block.leaves.blockID);
		world.setBlock(i + 19, j + 36, k + 31, Block.wood.blockID);
		world.setBlock(i + 19, j + 36, k + 32, Block.leaves.blockID);
		world.setBlock(i + 19, j + 36, k + 33, Block.leaves.blockID);
		world.setBlock(i + 19, j + 36, k + 34, Block.leaves.blockID);
		world.setBlock(i + 19, j + 36, k + 35, Block.leaves.blockID);
		world.setBlock(i + 19, j + 37, k + 27, Block.leaves.blockID);
		world.setBlock(i + 19, j + 37, k + 28, Block.leaves.blockID);
		world.setBlock(i + 19, j + 37, k + 29, Block.leaves.blockID);
		world.setBlock(i + 19, j + 37, k + 30, Block.leaves.blockID);
		world.setBlock(i + 19, j + 37, k + 31, Block.leaves.blockID);
		world.setBlock(i + 19, j + 37, k + 34, Block.leaves.blockID);
		world.setBlock(i + 19, j + 37, k + 35, Block.leaves.blockID);
		world.setBlock(i + 19, j + 38, k + 34, Block.leaves.blockID);
		world.setBlock(i + 19, j + 38, k + 35, Block.leaves.blockID);
		world.setBlock(i + 19, j + 38, k + 36, Block.leaves.blockID);
		world.setBlock(i + 19, j + 39, k + 26, Block.leaves.blockID);
		world.setBlock(i + 19, j + 39, k + 27, Block.leaves.blockID);
		world.setBlock(i + 19, j + 39, k + 28, Block.leaves.blockID);
		world.setBlock(i + 19, j + 39, k + 29, Block.leaves.blockID);
		world.setBlock(i + 19, j + 39, k + 35, Block.leaves.blockID);
		world.setBlock(i + 19, j + 40, k + 23, Block.leaves.blockID);
		world.setBlock(i + 19, j + 40, k + 24, Block.leaves.blockID);
		world.setBlock(i + 19, j + 40, k + 25, Block.leaves.blockID);
		world.setBlock(i + 19, j + 40, k + 26, Block.leaves.blockID);
		world.setBlock(i + 19, j + 40, k + 27, Block.leaves.blockID);
		world.setBlock(i + 19, j + 40, k + 28, Block.leaves.blockID);
		world.setBlock(i + 19, j + 40, k + 29, Block.leaves.blockID);
		world.setBlock(i + 19, j + 41, k + 22, Block.leaves.blockID);
		world.setBlock(i + 19, j + 41, k + 23, Block.wood.blockID);
		world.setBlock(i + 19, j + 41, k + 24, Block.wood.blockID);
		world.setBlock(i + 19, j + 41, k + 25, Block.leaves.blockID);
		world.setBlock(i + 19, j + 41, k + 26, Block.leaves.blockID);
		world.setBlock(i + 19, j + 42, k + 23, Block.leaves.blockID);
		world.setBlock(i + 19, j + 42, k + 24, Block.leaves.blockID);
		world.setBlock(i + 19, j + 42, k + 25, Block.leaves.blockID);
		world.setBlock(i + 19, j + 42, k + 26, Block.leaves.blockID);
		world.setBlock(i + 19, j + 43, k + 23, Block.leaves.blockID);
		world.setBlock(i + 19, j + 43, k + 25, Block.leaves.blockID);
		world.setBlock(i + 19, j + 44, k + 25, Block.leaves.blockID);
		world.setBlock(i + 20, j + 0, k + 14, Block.wood.blockID);
		world.setBlock(i + 20, j + 0, k + 17, Block.wood.blockID);
		world.setBlock(i + 20, j + 0, k + 18, Block.wood.blockID);
		world.setBlock(i + 20, j + 0, k + 19, Block.wood.blockID);
		world.setBlock(i + 20, j + 0, k + 29, Block.sandStone.blockID);
		world.setBlock(i + 20, j + 0, k + 30, Block.sandStone.blockID);
		world.setBlock(i + 20, j + 4, k + 27, Block.wood.blockID);
		world.setBlock(i + 20, j + 5, k + 28, Block.wood.blockID);
		world.setBlock(i + 20, j + 5, k + 29, Block.wood.blockID);
		world.setBlock(i + 20, j + 20, k + 27, Block.leaves.blockID);
		world.setBlock(i + 20, j + 20, k + 28, Block.leaves.blockID);
		world.setBlock(i + 20, j + 20, k + 29, Block.leaves.blockID);
		world.setBlock(i + 20, j + 20, k + 30, Block.leaves.blockID);
		world.setBlock(i + 20, j + 20, k + 31, Block.leaves.blockID);
		world.setBlock(i + 20, j + 20, k + 32, Block.leaves.blockID);
		world.setBlock(i + 20, j + 21, k + 26, Block.leaves.blockID);
		world.setBlock(i + 20, j + 21, k + 27, Block.wood.blockID);
		world.setBlock(i + 20, j + 21, k + 28, Block.leaves.blockID);
		world.setBlock(i + 20, j + 21, k + 29, Block.wood.blockID);
		world.setBlock(i + 20, j + 21, k + 30, Block.wood.blockID);
		world.setBlock(i + 20, j + 21, k + 31, Block.leaves.blockID);
		world.setBlock(i + 20, j + 21, k + 32, Block.wood.blockID);
		world.setBlock(i + 20, j + 21, k + 33, Block.leaves.blockID);
		world.setBlock(i + 20, j + 21, k + 34, Block.leaves.blockID);
		world.setBlock(i + 20, j + 21, k + 35, Block.leaves.blockID);
		world.setBlock(i + 20, j + 22, k + 25, Block.leaves.blockID);
		world.setBlock(i + 20, j + 22, k + 26, Block.wood.blockID);
		world.setBlock(i + 20, j + 22, k + 27, Block.wood.blockID);
		world.setBlock(i + 20, j + 22, k + 28, Block.wood.blockID);
		world.setBlock(i + 20, j + 22, k + 29, Block.wood.blockID);
		world.setBlock(i + 20, j + 22, k + 30, Block.wood.blockID);
		world.setBlock(i + 20, j + 22, k + 31, Block.wood.blockID);
		world.setBlock(i + 20, j + 22, k + 32, Block.wood.blockID);
		world.setBlock(i + 20, j + 22, k + 33, Block.wood.blockID);
		world.setBlock(i + 20, j + 22, k + 34, Block.wood.blockID);
		world.setBlock(i + 20, j + 22, k + 35, Block.leaves.blockID);
		world.setBlock(i + 20, j + 23, k + 24, Block.leaves.blockID);
		world.setBlock(i + 20, j + 23, k + 25, Block.leaves.blockID);
		world.setBlock(i + 20, j + 23, k + 26, Block.wood.blockID);
		world.setBlockAndMetadata(i + 20, j + 23, k + 27, Block.stairCompactPlanks.blockID, 3);
		world.setBlock(i + 20, j + 23, k + 29, Block.stoneSingleSlab.blockID);
		world.setBlock(i + 20, j + 23, k + 32, Block.bed.blockID);
		world.setBlockAndMetadata(i + 20, j + 23, k + 33, Block.bed.blockID, 8);
		world.setBlock(i + 20, j + 23, k + 34, Block.wood.blockID);
		world.setBlock(i + 20, j + 23, k + 35, Block.leaves.blockID);
		world.setBlock(i + 20, j + 23, k + 36, Block.leaves.blockID);
		world.setBlock(i + 20, j + 25, k + 25, Block.leaves.blockID);
		world.setBlock(i + 20, j + 25, k + 26, Block.wood.blockID);
		world.setBlock(i + 20, j + 25, k + 34, Block.wood.blockID);
		world.setBlock(i + 20, j + 25, k + 35, Block.leaves.blockID);
		world.setBlock(i + 20, j + 26, k + 26, Block.leaves.blockID);
		world.setBlock(i + 20, j + 26, k + 27, Block.wood.blockID);
		world.setBlock(i + 20, j + 26, k + 33, Block.wood.blockID);
		world.setBlock(i + 20, j + 26, k + 34, Block.leaves.blockID);
		world.setBlock(i + 20, j + 27, k + 25, Block.leaves.blockID);
		world.setBlock(i + 20, j + 27, k + 26, Block.leaves.blockID);
		world.setBlock(i + 20, j + 27, k + 27, Block.leaves.blockID);
		world.setBlock(i + 20, j + 27, k + 28, Block.wood.blockID);
		world.setBlock(i + 20, j + 27, k + 29, Block.wood.blockID);
		world.setBlock(i + 20, j + 27, k + 30, Block.wood.blockID);
		world.setBlock(i + 20, j + 27, k + 31, Block.wood.blockID);
		world.setBlock(i + 20, j + 27, k + 32, Block.wood.blockID);
		world.setBlock(i + 20, j + 27, k + 33, Block.leaves.blockID);
		world.setBlock(i + 20, j + 28, k + 27, Block.leaves.blockID);
		world.setBlock(i + 20, j + 28, k + 28, Block.leaves.blockID);
		world.setBlock(i + 20, j + 28, k + 29, Block.leaves.blockID);
		world.setBlock(i + 20, j + 28, k + 30, Block.wood.blockID);
		world.setBlock(i + 20, j + 28, k + 31, Block.leaves.blockID);
		world.setBlock(i + 20, j + 28, k + 32, Block.leaves.blockID);
		world.setBlock(i + 20, j + 28, k + 33, Block.leaves.blockID);
		world.setBlock(i + 20, j + 29, k + 28, Block.leaves.blockID);
		world.setBlock(i + 20, j + 29, k + 29, Block.leaves.blockID);
		world.setBlock(i + 20, j + 29, k + 30, Block.leaves.blockID);
		world.setBlock(i + 20, j + 29, k + 31, Block.leaves.blockID);
		world.setBlock(i + 20, j + 29, k + 33, Block.leaves.blockID);
		world.setBlock(i + 20, j + 29, k + 34, Block.leaves.blockID);
		world.setBlock(i + 20, j + 30, k + 22, Block.leaves.blockID);
		world.setBlock(i + 20, j + 30, k + 34, Block.leaves.blockID);
		world.setBlock(i + 20, j + 30, k + 35, Block.leaves.blockID);
		world.setBlock(i + 20, j + 31, k + 21, Block.leaves.blockID);
		world.setBlock(i + 20, j + 31, k + 22, Block.leaves.blockID);
		world.setBlock(i + 20, j + 31, k + 23, Block.leaves.blockID);
		world.setBlock(i + 20, j + 31, k + 34, Block.leaves.blockID);
		world.setBlock(i + 20, j + 31, k + 35, Block.leaves.blockID);
		world.setBlock(i + 20, j + 31, k + 36, Block.leaves.blockID);
		world.setBlock(i + 20, j + 32, k + 19, Block.leaves.blockID);
		world.setBlock(i + 20, j + 32, k + 20, Block.leaves.blockID);
		world.setBlock(i + 20, j + 32, k + 21, Block.leaves.blockID);
		world.setBlock(i + 20, j + 32, k + 22, Block.leaves.blockID);
		world.setBlock(i + 20, j + 32, k + 23, Block.leaves.blockID);
		world.setBlock(i + 20, j + 32, k + 24, Block.leaves.blockID);
		world.setBlock(i + 20, j + 32, k + 34, Block.leaves.blockID);
		world.setBlock(i + 20, j + 32, k + 35, Block.leaves.blockID);
		world.setBlock(i + 20, j + 33, k + 18, Block.leaves.blockID);
		world.setBlock(i + 20, j + 33, k + 19, Block.leaves.blockID);
		world.setBlock(i + 20, j + 33, k + 20, Block.leaves.blockID);
		world.setBlock(i + 20, j + 33, k + 21, Block.leaves.blockID);
		world.setBlock(i + 20, j + 33, k + 22, Block.wood.blockID);
		world.setBlock(i + 20, j + 33, k + 23, Block.leaves.blockID);
		world.setBlock(i + 20, j + 33, k + 35, Block.leaves.blockID);
		world.setBlock(i + 20, j + 34, k + 19, Block.leaves.blockID);
		world.setBlock(i + 20, j + 34, k + 20, Block.leaves.blockID);
		world.setBlock(i + 20, j + 34, k + 21, Block.leaves.blockID);
		world.setBlock(i + 20, j + 34, k + 22, Block.wood.blockID);
		world.setBlock(i + 20, j + 34, k + 23, Block.leaves.blockID);
		world.setBlock(i + 20, j + 34, k + 24, Block.leaves.blockID);
		world.setBlock(i + 20, j + 34, k + 31, Block.leaves.blockID);
		world.setBlock(i + 20, j + 34, k + 32, Block.leaves.blockID);
		world.setBlock(i + 20, j + 34, k + 35, Block.leaves.blockID);
		world.setBlock(i + 20, j + 35, k + 19, Block.leaves.blockID);
		world.setBlock(i + 20, j + 35, k + 20, Block.leaves.blockID);
		world.setBlock(i + 20, j + 35, k + 21, Block.leaves.blockID);
		world.setBlock(i + 20, j + 35, k + 22, Block.leaves.blockID);
		world.setBlock(i + 20, j + 35, k + 23, Block.leaves.blockID);
		world.setBlock(i + 20, j + 35, k + 28, Block.leaves.blockID);
		world.setBlock(i + 20, j + 35, k + 29, Block.leaves.blockID);
		world.setBlock(i + 20, j + 35, k + 30, Block.leaves.blockID);
		world.setBlock(i + 20, j + 35, k + 31, Block.wood.blockID);
		world.setBlock(i + 20, j + 35, k + 32, Block.leaves.blockID);
		world.setBlock(i + 20, j + 35, k + 33, Block.leaves.blockID);
		world.setBlock(i + 20, j + 35, k + 34, Block.leaves.blockID);
		world.setBlock(i + 20, j + 35, k + 35, Block.leaves.blockID);
		world.setBlock(i + 20, j + 36, k + 22, Block.leaves.blockID);
		world.setBlock(i + 20, j + 36, k + 27, Block.leaves.blockID);
		world.setBlock(i + 20, j + 36, k + 28, Block.wood.blockID);
		world.setBlock(i + 20, j + 36, k + 29, Block.wood.blockID);
		world.setBlock(i + 20, j + 36, k + 30, Block.wood.blockID);
		world.setBlock(i + 20, j + 36, k + 31, Block.wood.blockID);
		world.setBlock(i + 20, j + 36, k + 32, Block.wood.blockID);
		world.setBlock(i + 20, j + 36, k + 33, Block.wood.blockID);
		world.setBlock(i + 20, j + 36, k + 34, Block.wood.blockID);
		world.setBlock(i + 20, j + 36, k + 35, Block.wood.blockID);
		world.setBlock(i + 20, j + 36, k + 36, Block.leaves.blockID);
		world.setBlock(i + 20, j + 37, k + 26, Block.leaves.blockID);
		world.setBlock(i + 20, j + 37, k + 27, Block.leaves.blockID);
		world.setBlock(i + 20, j + 37, k + 28, Block.leaves.blockID);
		world.setBlock(i + 20, j + 37, k + 29, Block.leaves.blockID);
		world.setBlock(i + 20, j + 37, k + 30, Block.leaves.blockID);
		world.setBlock(i + 20, j + 37, k + 31, Block.leaves.blockID);
		world.setBlock(i + 20, j + 37, k + 32, Block.leaves.blockID);
		world.setBlock(i + 20, j + 37, k + 33, Block.leaves.blockID);
		world.setBlock(i + 20, j + 37, k + 34, Block.leaves.blockID);
		world.setBlock(i + 20, j + 37, k + 35, Block.wood.blockID);
		world.setBlock(i + 20, j + 37, k + 36, Block.leaves.blockID);
		world.setBlock(i + 20, j + 38, k + 27, Block.leaves.blockID);
		world.setBlock(i + 20, j + 38, k + 28, Block.leaves.blockID);
		world.setBlock(i + 20, j + 38, k + 29, Block.leaves.blockID);
		world.setBlock(i + 20, j + 38, k + 31, Block.leaves.blockID);
		world.setBlock(i + 20, j + 38, k + 32, Block.leaves.blockID);
		world.setBlock(i + 20, j + 38, k + 33, Block.leaves.blockID);
		world.setBlock(i + 20, j + 38, k + 34, Block.leaves.blockID);
		world.setBlock(i + 20, j + 38, k + 35, Block.wood.blockID);
		world.setBlock(i + 20, j + 38, k + 36, Block.leaves.blockID);
		world.setBlock(i + 20, j + 38, k + 37, Block.leaves.blockID);
		world.setBlock(i + 20, j + 39, k + 26, Block.leaves.blockID);
		world.setBlock(i + 20, j + 39, k + 27, Block.leaves.blockID);
		world.setBlock(i + 20, j + 39, k + 28, Block.leaves.blockID);
		world.setBlock(i + 20, j + 39, k + 29, Block.leaves.blockID);
		world.setBlock(i + 20, j + 39, k + 35, Block.leaves.blockID);
		world.setBlock(i + 20, j + 39, k + 36, Block.leaves.blockID);
		world.setBlock(i + 20, j + 40, k + 21, Block.leaves.blockID);
		world.setBlock(i + 20, j + 40, k + 22, Block.leaves.blockID);
		world.setBlock(i + 20, j + 40, k + 24, Block.leaves.blockID);
		world.setBlock(i + 20, j + 40, k + 25, Block.leaves.blockID);
		world.setBlock(i + 20, j + 40, k + 26, Block.leaves.blockID);
		world.setBlock(i + 20, j + 40, k + 27, Block.leaves.blockID);
		world.setBlock(i + 20, j + 40, k + 28, Block.leaves.blockID);
		world.setBlock(i + 20, j + 40, k + 29, Block.leaves.blockID);
		world.setBlock(i + 20, j + 40, k + 34, Block.leaves.blockID);
		world.setBlock(i + 20, j + 40, k + 35, Block.leaves.blockID);
		world.setBlock(i + 20, j + 41, k + 22, Block.leaves.blockID);
		world.setBlock(i + 20, j + 41, k + 23, Block.leaves.blockID);
		world.setBlock(i + 20, j + 41, k + 24, Block.wood.blockID);
		world.setBlock(i + 20, j + 41, k + 25, Block.wood.blockID);
		world.setBlock(i + 20, j + 41, k + 26, Block.leaves.blockID);
		world.setBlock(i + 20, j + 41, k + 27, Block.leaves.blockID);
		world.setBlock(i + 20, j + 41, k + 28, Block.leaves.blockID);
		world.setBlock(i + 20, j + 41, k + 29, Block.leaves.blockID);
		world.setBlock(i + 20, j + 41, k + 31, Block.leaves.blockID);
		world.setBlock(i + 20, j + 41, k + 32, Block.leaves.blockID);
		world.setBlock(i + 20, j + 41, k + 33, Block.leaves.blockID);
		world.setBlock(i + 20, j + 41, k + 34, Block.leaves.blockID);
		world.setBlock(i + 20, j + 41, k + 35, Block.leaves.blockID);
		world.setBlock(i + 20, j + 42, k + 24, Block.leaves.blockID);
		world.setBlock(i + 20, j + 42, k + 25, Block.leaves.blockID);
		world.setBlock(i + 20, j + 42, k + 26, Block.leaves.blockID);
		world.setBlock(i + 20, j + 42, k + 27, Block.leaves.blockID);
		world.setBlock(i + 20, j + 42, k + 29, Block.leaves.blockID);
		world.setBlock(i + 20, j + 42, k + 32, Block.leaves.blockID);
		world.setBlock(i + 20, j + 43, k + 25, Block.leaves.blockID);
		world.setBlock(i + 20, j + 43, k + 26, Block.leaves.blockID);
		world.setBlock(i + 20, j + 43, k + 27, Block.leaves.blockID);
		world.setBlock(i + 20, j + 44, k + 25, Block.leaves.blockID);
		world.setBlock(i + 20, j + 44, k + 26, Block.leaves.blockID);
		world.setBlock(i + 20, j + 44, k + 27, Block.leaves.blockID);
		world.setBlock(i + 20, j + 45, k + 28, Block.leaves.blockID);
		world.setBlock(i + 20, j + 46, k + 28, Block.leaves.blockID);
		world.setBlock(i + 21, j + 0, k + 13, Block.wood.blockID);
		world.setBlock(i + 21, j + 0, k + 18, Block.wood.blockID);
		world.setBlock(i + 21, j + 0, k + 19, Block.wood.blockID);
		world.setBlock(i + 21, j + 0, k + 26, Block.sandStone.blockID);
		world.setBlock(i + 21, j + 0, k + 27, Block.sandStone.blockID);
		world.setBlock(i + 21, j + 0, k + 29, Block.stone.blockID);
		world.setBlock(i + 21, j + 0, k + 30, Block.stone.blockID);
		world.setBlock(i + 21, j + 0, k + 31, Block.stone.blockID);
		world.setBlock(i + 21, j + 0, k + 32, Block.sandStone.blockID);
		world.setBlock(i + 21, j + 0, k + 33, Block.sandStone.blockID);
		world.setBlock(i + 21, j + 0, k + 34, Block.sandStone.blockID);
		world.setBlock(i + 21, j + 0, k + 36, Block.sandStone.blockID);
		world.setBlock(i + 21, j + 1, k + 19, Block.wood.blockID);
		world.setBlock(i + 21, j + 1, k + 20, Block.wood.blockID);
		world.setBlock(i + 21, j + 1, k + 28, Block.stone.blockID);
		world.setBlock(i + 21, j + 1, k + 29, Block.stone.blockID);
		world.setBlock(i + 21, j + 1, k + 30, Block.stone.blockID);
		world.setBlock(i + 21, j + 1, k + 31, Block.stone.blockID);
		world.setBlock(i + 21, j + 1, k + 32, Block.sandStone.blockID);
		world.setBlock(i + 21, j + 1, k + 33, Block.sandStone.blockID);
		world.setBlock(i + 21, j + 5, k + 27, Block.wood.blockID);
		world.setBlock(i + 21, j + 5, k + 28, Block.wood.blockID);
		world.setBlock(i + 21, j + 5, k + 29, Block.wood.blockID);
		world.setBlock(i + 21, j + 6, k + 29, Block.wood.blockID);
		world.setBlock(i + 21, j + 20, k + 27, Block.leaves.blockID);
		world.setBlock(i + 21, j + 20, k + 28, Block.leaves.blockID);
		world.setBlock(i + 21, j + 20, k + 29, Block.leaves.blockID);
		world.setBlock(i + 21, j + 20, k + 30, Block.leaves.blockID);
		world.setBlock(i + 21, j + 21, k + 26, Block.leaves.blockID);
		world.setBlock(i + 21, j + 21, k + 27, Block.wood.blockID);
		world.setBlock(i + 21, j + 21, k + 28, Block.wood.blockID);
		world.setBlock(i + 21, j + 21, k + 29, Block.wood.blockID);
		world.setBlock(i + 21, j + 21, k + 30, Block.wood.blockID);
		world.setBlock(i + 21, j + 21, k + 31, Block.leaves.blockID);
		world.setBlock(i + 21, j + 21, k + 32, Block.leaves.blockID);
		world.setBlock(i + 21, j + 21, k + 33, Block.leaves.blockID);
		world.setBlock(i + 21, j + 21, k + 34, Block.leaves.blockID);
		world.setBlock(i + 21, j + 22, k + 24, Block.leaves.blockID);
		world.setBlock(i + 21, j + 22, k + 25, Block.leaves.blockID);
		world.setBlock(i + 21, j + 22, k + 26, Block.wood.blockID);
		world.setBlock(i + 21, j + 22, k + 27, Block.wood.blockID);
		world.setBlock(i + 21, j + 22, k + 28, Block.wood.blockID);
		world.setBlockAndMetadata(i + 21, j + 22, k + 29, Block.stoneSingleSlab.blockID, 2);
		world.setBlockAndMetadata(i + 21, j + 22, k + 30, Block.stoneSingleSlab.blockID, 2);
		world.setBlockAndMetadata(i + 21, j + 22, k + 31, Block.stoneSingleSlab.blockID, 2);
		world.setBlock(i + 21, j + 22, k + 32, Block.wood.blockID);
		world.setBlock(i + 21, j + 22, k + 33, Block.wood.blockID);
		world.setBlock(i + 21, j + 22, k + 34, Block.wood.blockID);
		world.setBlock(i + 21, j + 22, k + 35, Block.leaves.blockID);
		world.setBlock(i + 21, j + 23, k + 24, Block.leaves.blockID);
		world.setBlock(i + 21, j + 23, k + 25, Block.leaves.blockID);
		world.setBlock(i + 21, j + 23, k + 26, Block.wood.blockID);
		world.setBlock(i + 21, j + 23, k + 27, Block.workbench.blockID);
		world.setBlockAndMetadata(i + 21, j + 23, k + 32, Block.jukebox.blockID, 2);
		world.setBlockAndMetadata(i + 21, j + 23, k + 33, Block.stoneOvenIdle.blockID, 2);
		world.setBlock(i + 21, j + 23, k + 34, Block.wood.blockID);
		world.setBlock(i + 21, j + 23, k + 35, Block.leaves.blockID);
		world.setBlock(i + 21, j + 23, k + 36, Block.leaves.blockID);
		world.setBlock(i + 21, j + 25, k + 25, Block.leaves.blockID);
		world.setBlock(i + 21, j + 25, k + 26, Block.wood.blockID);
		world.setBlock(i + 21, j + 25, k + 34, Block.wood.blockID);
		world.setBlock(i + 21, j + 25, k + 35, Block.leaves.blockID);
		world.setBlock(i + 21, j + 26, k + 26, Block.leaves.blockID);
		world.setBlock(i + 21, j + 26, k + 27, Block.wood.blockID);
		world.setBlock(i + 21, j + 26, k + 28, Block.wood.blockID);
		world.setBlock(i + 21, j + 26, k + 29, Block.wood.blockID);
		world.setBlock(i + 21, j + 26, k + 30, Block.wood.blockID);
		world.setBlock(i + 21, j + 26, k + 31, Block.wood.blockID);
		world.setBlock(i + 21, j + 26, k + 32, Block.wood.blockID);
		world.setBlock(i + 21, j + 26, k + 33, Block.wood.blockID);
		world.setBlock(i + 21, j + 26, k + 34, Block.leaves.blockID);
		world.setBlock(i + 21, j + 27, k + 26, Block.leaves.blockID);
		world.setBlock(i + 21, j + 27, k + 27, Block.leaves.blockID);
		world.setBlock(i + 21, j + 27, k + 28, Block.leaves.blockID);
		world.setBlock(i + 21, j + 27, k + 29, Block.leaves.blockID);
		world.setBlock(i + 21, j + 27, k + 30, Block.leaves.blockID);
		world.setBlock(i + 21, j + 27, k + 31, Block.leaves.blockID);
		world.setBlock(i + 21, j + 27, k + 32, Block.leaves.blockID);
		world.setBlock(i + 21, j + 27, k + 33, Block.leaves.blockID);
		world.setBlock(i + 21, j + 28, k + 27, Block.leaves.blockID);
		world.setBlock(i + 21, j + 28, k + 28, Block.leaves.blockID);
		world.setBlock(i + 21, j + 28, k + 29, Block.leaves.blockID);
		world.setBlock(i + 21, j + 28, k + 30, Block.leaves.blockID);
		world.setBlock(i + 21, j + 28, k + 31, Block.leaves.blockID);
		world.setBlock(i + 21, j + 29, k + 28, Block.leaves.blockID);
		world.setBlock(i + 21, j + 29, k + 29, Block.leaves.blockID);
		world.setBlock(i + 21, j + 29, k + 30, Block.leaves.blockID);
		world.setBlock(i + 21, j + 30, k + 22, Block.leaves.blockID);
		world.setBlock(i + 21, j + 31, k + 21, Block.leaves.blockID);
		world.setBlock(i + 21, j + 31, k + 22, Block.leaves.blockID);
		world.setBlock(i + 21, j + 31, k + 23, Block.leaves.blockID);
		world.setBlock(i + 21, j + 31, k + 35, Block.leaves.blockID);
		world.setBlock(i + 21, j + 32, k + 19, Block.leaves.blockID);
		world.setBlock(i + 21, j + 32, k + 20, Block.leaves.blockID);
		world.setBlock(i + 21, j + 32, k + 21, Block.leaves.blockID);
		world.setBlock(i + 21, j + 32, k + 22, Block.leaves.blockID);

		generate2(world, rand, i, j, k);
		return true;
	}

	public boolean generate2(World world, Random rand, int i, int j, int k) {
		world.setBlock(i + 21, j + 32, k + 23, Block.leaves.blockID);
		world.setBlock(i + 21, j + 32, k + 24, Block.leaves.blockID);
		world.setBlock(i + 21, j + 33, k + 19, Block.leaves.blockID);
		world.setBlock(i + 21, j + 33, k + 20, Block.leaves.blockID);
		world.setBlock(i + 21, j + 33, k + 21, Block.leaves.blockID);
		world.setBlock(i + 21, j + 33, k + 22, Block.wood.blockID);
		world.setBlock(i + 21, j + 33, k + 23, Block.leaves.blockID);
		world.setBlock(i + 21, j + 33, k + 24, Block.leaves.blockID);
		world.setBlock(i + 21, j + 33, k + 35, Block.leaves.blockID);
		world.setBlock(i + 21, j + 34, k + 18, Block.leaves.blockID);
		world.setBlock(i + 21, j + 34, k + 19, Block.leaves.blockID);
		world.setBlock(i + 21, j + 34, k + 20, Block.leaves.blockID);
		world.setBlock(i + 21, j + 34, k + 21, Block.leaves.blockID);
		world.setBlock(i + 21, j + 34, k + 22, Block.leaves.blockID);
		world.setBlock(i + 21, j + 34, k + 23, Block.leaves.blockID);
		world.setBlock(i + 21, j + 34, k + 31, Block.leaves.blockID);
		world.setBlock(i + 21, j + 34, k + 32, Block.leaves.blockID);
		world.setBlock(i + 21, j + 34, k + 35, Block.leaves.blockID);
		world.setBlock(i + 21, j + 35, k + 20, Block.leaves.blockID);
		world.setBlock(i + 21, j + 35, k + 21, Block.leaves.blockID);
		world.setBlock(i + 21, j + 35, k + 22, Block.leaves.blockID);
		world.setBlock(i + 21, j + 35, k + 23, Block.leaves.blockID);
		world.setBlock(i + 21, j + 35, k + 24, Block.leaves.blockID);
		world.setBlock(i + 21, j + 35, k + 30, Block.leaves.blockID);
		world.setBlock(i + 21, j + 35, k + 31, Block.wood.blockID);
		world.setBlock(i + 21, j + 35, k + 32, Block.leaves.blockID);
		world.setBlock(i + 21, j + 35, k + 33, Block.leaves.blockID);
		world.setBlock(i + 21, j + 35, k + 34, Block.leaves.blockID);
		world.setBlock(i + 21, j + 35, k + 35, Block.leaves.blockID);
		world.setBlock(i + 21, j + 36, k + 20, Block.leaves.blockID);
		world.setBlock(i + 21, j + 36, k + 24, Block.leaves.blockID);
		world.setBlock(i + 21, j + 36, k + 27, Block.leaves.blockID);
		world.setBlock(i + 21, j + 36, k + 28, Block.leaves.blockID);
		world.setBlock(i + 21, j + 36, k + 29, Block.leaves.blockID);
		world.setBlock(i + 21, j + 36, k + 30, Block.leaves.blockID);
		world.setBlock(i + 21, j + 36, k + 31, Block.leaves.blockID);
		world.setBlock(i + 21, j + 36, k + 32, Block.leaves.blockID);
		world.setBlock(i + 21, j + 36, k + 33, Block.leaves.blockID);
		world.setBlock(i + 21, j + 36, k + 34, Block.leaves.blockID);
		world.setBlock(i + 21, j + 36, k + 35, Block.leaves.blockID);
		world.setBlock(i + 21, j + 37, k + 26, Block.leaves.blockID);
		world.setBlock(i + 21, j + 37, k + 27, Block.leaves.blockID);
		world.setBlock(i + 21, j + 37, k + 28, Block.leaves.blockID);
		world.setBlock(i + 21, j + 37, k + 30, Block.leaves.blockID);
		world.setBlock(i + 21, j + 37, k + 31, Block.leaves.blockID);
		world.setBlock(i + 21, j + 37, k + 32, Block.leaves.blockID);
		world.setBlock(i + 21, j + 37, k + 35, Block.leaves.blockID);
		world.setBlock(i + 21, j + 38, k + 27, Block.leaves.blockID);
		world.setBlock(i + 21, j + 38, k + 28, Block.leaves.blockID);
		world.setBlock(i + 21, j + 38, k + 29, Block.leaves.blockID);
		world.setBlock(i + 21, j + 38, k + 34, Block.leaves.blockID);
		world.setBlock(i + 21, j + 38, k + 35, Block.leaves.blockID);
		world.setBlock(i + 21, j + 38, k + 36, Block.leaves.blockID);
		world.setBlock(i + 21, j + 39, k + 25, Block.leaves.blockID);
		world.setBlock(i + 21, j + 39, k + 26, Block.leaves.blockID);
		world.setBlock(i + 21, j + 39, k + 27, Block.leaves.blockID);
		world.setBlock(i + 21, j + 39, k + 28, Block.leaves.blockID);
		world.setBlock(i + 21, j + 39, k + 29, Block.leaves.blockID);
		world.setBlock(i + 21, j + 39, k + 34, Block.leaves.blockID);
		world.setBlock(i + 21, j + 39, k + 35, Block.leaves.blockID);
		world.setBlock(i + 21, j + 40, k + 24, Block.leaves.blockID);
		world.setBlock(i + 21, j + 40, k + 25, Block.leaves.blockID);
		world.setBlock(i + 21, j + 40, k + 26, Block.leaves.blockID);
		world.setBlock(i + 21, j + 40, k + 27, Block.leaves.blockID);
		world.setBlock(i + 21, j + 40, k + 28, Block.leaves.blockID);
		world.setBlock(i + 21, j + 40, k + 29, Block.leaves.blockID);
