package microjunk.trees.common.worldgentrees;

import java.util.Random;

import microjunk.trees.common.Trees;
import net.minecraft.block.Block;
import net.minecraft.world.World;
import net.minecraft.world.gen.feature.WorldGenerator;

public class WorldGenJATree extends WorldGenerator
{
	protected int[] GetValidSpawnBlocks() {
		return new int[] {
			Block.grass.blockID
		};
	}

	public boolean LocationIsValidSpawn(World world, int i, int j, int k){
		int distanceToAir = 0;
		int checkID = world.getBlockId(i, j, k);

		while (checkID != 0){
			distanceToAir++;
			checkID = world.getBlockId(i, j + distanceToAir, k);
		}

		if (distanceToAir > 3){
			return false;
		}
		j += distanceToAir - 1;

		int blockID = world.getBlockId(i, j, k);
		int blockIDAbove = world.getBlockId(i, j+1, k);
		int blockIDBelow = world.getBlockId(i, j-1, k);
		for (int x : GetValidSpawnBlocks()){
			if (blockIDAbove != 0){
				return false;
			}
			if (blockID == x){
				return true;
			}else if (blockID == Block.snow.blockID && blockIDBelow == x){
				return true;
			}
		}
		return false;
	}

	public WorldGenJATree() { }

	public boolean generate(World world, Random rand, int i, int j, int k) {
		//check that each corner is one of the valid spawn blocks
		if(!LocationIsValidSpawn(world, i, j, k) || !LocationIsValidSpawn(world, i + 18, j, k) || !LocationIsValidSpawn(world, i + 18, j, k + 15) || !LocationIsValidSpawn(world, i, j, k + 15))
		{
			return false;
		}

		world.setBlock(i + 0, j + 0, k + 2, Trees.japaneseApricotLog.blockID);
		world.setBlock(i + 0, j + 0, k + 3, Trees.japaneseApricotLog.blockID);
		world.setBlock(i + 0, j + 0, k + 4, Trees.japaneseApricotLog.blockID);
		world.setBlock(i + 0, j + 1, k + 2, Trees.japaneseApricotLog.blockID);
		world.setBlock(i + 0, j + 1, k + 3, Trees.japaneseApricotLog.blockID);
		world.setBlock(i + 0, j + 1, k + 4, Trees.japaneseApricotLog.blockID);
		world.setBlock(i + 0, j + 2, k + 3, Trees.japaneseApricotLog.blockID);
		world.setBlock(i + 0, j + 6, k + 4, Trees.japaneseApricotLeaves.blockID);
		world.setBlock(i + 0, j + 6, k + 5, Trees.japaneseApricotLeaves.blockID);
		world.setBlock(i + 0, j + 6, k + 6, Trees.japaneseApricotLeaves.blockID);
		world.setBlock(i + 0, j + 6, k + 8, Trees.japaneseApricotLeaves.blockID);
		world.setBlock(i + 1, j + 0, k + 1, Trees.japaneseApricotLog.blockID);
		world.setBlock(i + 1, j + 0, k + 2, Trees.japaneseApricotLog.blockID);
		world.setBlock(i + 1, j + 0, k + 3, Trees.japaneseApricotLog.blockID);
		world.setBlock(i + 1, j + 0, k + 4, Trees.japaneseApricotLog.blockID);
		world.setBlock(i + 1, j + 0, k + 5, Trees.japaneseApricotLog.blockID);
		world.setBlock(i + 1, j + 1, k + 1, Trees.japaneseApricotLog.blockID);
		world.setBlock(i + 1, j + 1, k + 2, Trees.japaneseApricotLog.blockID);
		world.setBlock(i + 1, j + 1, k + 3, Trees.japaneseApricotLog.blockID);
		world.setBlock(i + 1, j + 1, k + 4, Trees.japaneseApricotLog.blockID);
		world.setBlock(i + 1, j + 2, k + 2, Trees.japaneseApricotLog.blockID);
		world.setBlock(i + 1, j + 2, k + 3, Trees.japaneseApricotLog.blockID);
		world.setBlock(i + 1, j + 2, k + 4, Trees.japaneseApricotLog.blockID);
		world.setBlock(i + 1, j + 3, k + 2, Trees.japaneseApricotLog.blockID);
		world.setBlock(i + 1, j + 3, k + 3, Trees.japaneseApricotLog.blockID);
		world.setBlock(i + 1, j + 6, k + 2, Trees.japaneseApricotLeaves.blockID);
		world.setBlock(i + 1, j + 6, k + 5, Trees.japaneseApricotLeaves.blockID);
		world.setBlock(i + 1, j + 6, k + 8, Trees.japaneseApricotLeaves.blockID);
		world.setBlock(i + 1, j + 6, k + 9, Trees.japaneseApricotLeaves.blockID);
		world.setBlock(i + 2, j + 0, k + 0, Trees.japaneseApricotLog.blockID);
		world.setBlock(i + 2, j + 0, k + 1, Trees.japaneseApricotLog.blockID);
		world.setBlock(i + 2, j + 0, k + 2, Trees.japaneseApricotLog.blockID);
		world.setBlock(i + 2, j + 0, k + 3, Trees.japaneseApricotLog.blockID);
		world.setBlock(i + 2, j + 0, k + 4, Trees.japaneseApricotLog.blockID);
		world.setBlock(i + 2, j + 0, k + 5, Trees.japaneseApricotLog.blockID);
		world.setBlock(i + 2, j + 1, k + 1, Trees.japaneseApricotLog.blockID);
		world.setBlock(i + 2, j + 1, k + 2, Trees.japaneseApricotLog.blockID);
		world.setBlock(i + 2, j + 1, k + 3, Trees.japaneseApricotLog.blockID);
		world.setBlock(i + 2, j + 1, k + 4, Trees.japaneseApricotLog.blockID);
		world.setBlock(i + 2, j + 1, k + 5, Trees.japaneseApricotLog.blockID);
		world.setBlock(i + 2, j + 2, k + 1, Trees.japaneseApricotLog.blockID);
		world.setBlock(i + 2, j + 2, k + 2, Trees.japaneseApricotLog.blockID);
		world.setBlock(i + 2, j + 2, k + 3, Trees.japaneseApricotLog.blockID);
		world.setBlock(i + 2, j + 2, k + 4, Trees.japaneseApricotLog.blockID);
		world.setBlock(i + 2, j + 3, k + 1, Trees.japaneseApricotLog.blockID);
		world.setBlock(i + 2, j + 3, k + 2, Trees.japaneseApricotLog.blockID);
		world.setBlock(i + 2, j + 3, k + 3, Trees.japaneseApricotLog.blockID);
		world.setBlock(i + 2, j + 3, k + 4, Trees.japaneseApricotLog.blockID);
		world.setBlock(i + 2, j + 4, k + 2, Trees.japaneseApricotLog.blockID);
		world.setBlock(i + 2, j + 4, k + 3, Trees.japaneseApricotLog.blockID);
		world.setBlock(i + 2, j + 5, k + 7, Trees.japaneseApricotLeaves.blockID);
		world.setBlock(i + 2, j + 6, k + 1, Trees.japaneseApricotLeaves.blockID);
		world.setBlock(i + 2, j + 6, k + 3, Trees.japaneseApricotLeaves.blockID);
		world.setBlock(i + 2, j + 6, k + 6, Trees.japaneseApricotLeaves.blockID);
		world.setBlock(i + 2, j + 6, k + 9, Trees.japaneseApricotLeaves.blockID);
		world.setBlock(i + 2, j + 6, k + 10, Trees.japaneseApricotLeaves.blockID);
		world.setBlock(i + 2, j + 6, k + 11, Trees.japaneseApricotLeaves.blockID);
		world.setBlock(i + 3, j + 0, k + 1, Trees.japaneseApricotLog.blockID);
		world.setBlock(i + 3, j + 0, k + 2, Trees.japaneseApricotLog.blockID);
		world.setBlock(i + 3, j + 0, k + 3, Trees.japaneseApricotLog.blockID);
		world.setBlock(i + 3, j + 0, k + 4, Trees.japaneseApricotLog.blockID);
		world.setBlock(i + 3, j + 1, k + 0, Trees.japaneseApricotLog.blockID);
		world.setBlock(i + 3, j + 1, k + 1, Trees.japaneseApricotLog.blockID);
		world.setBlock(i + 3, j + 1, k + 2, Trees.japaneseApricotLog.blockID);
		world.setBlock(i + 3, j + 1, k + 3, Trees.japaneseApricotLog.blockID);
		world.setBlock(i + 3, j + 1, k + 4, Trees.japaneseApricotLog.blockID);
		world.setBlock(i + 3, j + 1, k + 5, Trees.japaneseApricotLog.blockID);
		world.setBlock(i + 3, j + 2, k + 0, Trees.japaneseApricotLog.blockID);
		world.setBlock(i + 3, j + 2, k + 1, Trees.japaneseApricotLog.blockID);
		world.setBlock(i + 3, j + 2, k + 2, Trees.japaneseApricotLog.blockID);
		world.setBlock(i + 3, j + 2, k + 3, Trees.japaneseApricotLog.blockID);
		world.setBlock(i + 3, j + 2, k + 4, Trees.japaneseApricotLog.blockID);
		world.setBlock(i + 3, j + 2, k + 5, Trees.japaneseApricotLog.blockID);
		world.setBlock(i + 3, j + 3, k + 1, Trees.japaneseApricotLog.blockID);
		world.setBlock(i + 3, j + 3, k + 2, Trees.japaneseApricotLog.blockID);
		world.setBlock(i + 3, j + 3, k + 3, Trees.japaneseApricotLog.blockID);
		world.setBlock(i + 3, j + 3, k + 4, Trees.japaneseApricotLog.blockID);
		world.setBlock(i + 3, j + 3, k + 5, Trees.japaneseApricotLog.blockID);
		world.setBlock(i + 3, j + 4, k + 2, Trees.japaneseApricotLog.blockID);
		world.setBlock(i + 3, j + 4, k + 3, Trees.japaneseApricotLog.blockID);
		world.setBlock(i + 3, j + 4, k + 4, Trees.japaneseApricotLog.blockID);
		world.setBlock(i + 3, j + 4, k + 5, Trees.japaneseApricotLog.blockID);
		world.setBlock(i + 3, j + 5, k + 8, Trees.japaneseApricotLeaves.blockID);
		world.setBlock(i + 3, j + 6, k + 2, Trees.japaneseApricotLeaves.blockID);
		world.setBlock(i + 3, j + 6, k + 3, Trees.japaneseApricotLeaves.blockID);
		world.setBlock(i + 3, j + 6, k + 6, Trees.japaneseApricotLeaves.blockID);
		world.setBlock(i + 4, j + 0, k + 1, Trees.japaneseApricotLog.blockID);
		world.setBlock(i + 4, j + 0, k + 2, Trees.japaneseApricotLog.blockID);
		world.setBlock(i + 4, j + 0, k + 3, Trees.japaneseApricotLog.blockID);
		world.setBlock(i + 4, j + 1, k + 1, Trees.japaneseApricotLog.blockID);
		world.setBlock(i + 4, j + 1, k + 2, Trees.japaneseApricotLog.blockID);
		world.setBlock(i + 4, j + 1, k + 3, Trees.japaneseApricotLog.blockID);
		world.setBlock(i + 4, j + 1, k + 4, Trees.japaneseApricotLog.blockID);
		world.setBlock(i + 4, j + 2, k + 1, Trees.japaneseApricotLog.blockID);
		world.setBlock(i + 4, j + 2, k + 2, Trees.japaneseApricotLog.blockID);
		world.setBlock(i + 4, j + 2, k + 3, Trees.japaneseApricotLog.blockID);
		world.setBlock(i + 4, j + 2, k + 4, Trees.japaneseApricotLog.blockID);
		world.setBlock(i + 4, j + 2, k + 5, Trees.japaneseApricotLog.blockID);
		world.setBlock(i + 4, j + 3, k + 2, Trees.japaneseApricotLog.blockID);
		world.setBlock(i + 4, j + 3, k + 3, Trees.japaneseApricotLog.blockID);
		world.setBlock(i + 4, j + 3, k + 4, Trees.japaneseApricotLog.blockID);
		world.setBlock(i + 4, j + 3, k + 5, Trees.japaneseApricotLog.blockID);
		world.setBlock(i + 4, j + 4, k + 3, Trees.japaneseApricotLog.blockID);
		world.setBlock(i + 4, j + 4, k + 4, Trees.japaneseApricotLog.blockID);
		world.setBlock(i + 4, j + 4, k + 5, Trees.japaneseApricotLog.blockID);
		world.setBlock(i + 4, j + 4, k + 6, Trees.japaneseApricotLog.blockID);
		world.setBlock(i + 4, j + 4, k + 7, Trees.japaneseApricotLeaves.blockID);
		world.setBlock(i + 4, j + 4, k + 8, Trees.japaneseApricotLeaves.blockID);
		world.setBlock(i + 4, j + 4, k + 10, Trees.japaneseApricotLeaves.blockID);
		world.setBlock(i + 4, j + 5, k + 2, Trees.japaneseApricotLeaves.blockID);
		world.setBlock(i + 4, j + 5, k + 4, Trees.japaneseApricotLog.blockID);
		world.setBlock(i + 4, j + 5, k + 5, Trees.japaneseApricotLog.blockID);
		world.setBlock(i + 4, j + 5, k + 6, Trees.japaneseApricotLeaves.blockID);
		world.setBlock(i + 5, j + 0, k + 2, Trees.japaneseApricotLog.blockID);
		world.setBlock(i + 5, j + 1, k + 3, Trees.japaneseApricotLog.blockID);
		world.setBlock(i + 5, j + 2, k + 3, Trees.japaneseApricotLog.blockID);
		world.setBlock(i + 5, j + 2, k + 4, Trees.japaneseApricotLog.blockID);
		world.setBlock(i + 5, j + 3, k + 3, Trees.japaneseApricotLog.blockID);
		world.setBlock(i + 5, j + 3, k + 4, Trees.japaneseApricotLog.blockID);
		world.setBlock(i + 5, j + 3, k + 5, Trees.japaneseApricotLog.blockID);
		world.setBlock(i + 5, j + 3, k + 6, Trees.japaneseApricotLeaves.blockID);
		world.setBlock(i + 5, j + 3, k + 8, Trees.japaneseApricotLeaves.blockID);
		world.setBlock(i + 5, j + 4, k + 3, Trees.japaneseApricotLog.blockID);
		world.setBlock(i + 5, j + 4, k + 4, Trees.japaneseApricotLog.blockID);
		world.setBlock(i + 5, j + 4, k + 5, Trees.japaneseApricotLog.blockID);
		world.setBlock(i + 5, j + 4, k + 6, Trees.japaneseApricotLog.blockID);
		world.setBlock(i + 5, j + 4, k + 8, Trees.japaneseApricotLeaves.blockID);
		world.setBlock(i + 5, j + 4, k + 11, Trees.japaneseApricotLeaves.blockID);
		world.setBlock(i + 5, j + 5, k + 4, Trees.japaneseApricotLog.blockID);
		world.setBlock(i + 5, j + 5, k + 5, Trees.japaneseApricotLog.blockID);
		world.setBlock(i + 5, j + 5, k + 6, Trees.japaneseApricotLog.blockID);
		world.setBlock(i + 5, j + 5, k + 10, Trees.japaneseApricotLeaves.blockID);
		world.setBlock(i + 5, j + 6, k + 0, Trees.japaneseApricotLeaves.blockID);
		world.setBlock(i + 5, j + 6, k + 5, Trees.japaneseApricotLeaves.blockID);
		world.setBlock(i + 5, j + 6, k + 6, Trees.japaneseApricotLeaves.blockID);
		world.setBlock(i + 5, j + 6, k + 7, Trees.japaneseApricotLeaves.blockID);
		world.setBlock(i + 5, j + 6, k + 11, Trees.japaneseApricotLeaves.blockID);
		world.setBlock(i + 6, j + 2, k + 8, Trees.japaneseApricotLeaves.blockID);
		world.setBlock(i + 6, j + 2, k + 9, Trees.japaneseApricotLeaves.blockID);
		world.setBlock(i + 6, j + 2, k + 11, Trees.japaneseApricotLeaves.blockID);
		world.setBlock(i + 6, j + 3, k + 6, Trees.japaneseApricotLeaves.blockID);
		world.setBlock(i + 6, j + 3, k + 7, Trees.japaneseApricotLeaves.blockID);
		world.setBlock(i + 6, j + 3, k + 11, Trees.japaneseApricotLeaves.blockID);
		world.setBlock(i + 6, j + 4, k + 5, Trees.japaneseApricotLog.blockID);
		world.setBlock(i + 6, j + 4, k + 6, Trees.japaneseApricotLog.blockID);
		world.setBlock(i + 6, j + 4, k + 7, Trees.japaneseApricotLeaves.blockID);
		world.setBlock(i + 6, j + 4, k + 8, Trees.japaneseApricotLeaves.blockID);
		world.setBlock(i + 6, j + 5, k + 3, Trees.japaneseApricotLeaves.blockID);
		world.setBlock(i + 6, j + 5, k + 5, Trees.japaneseApricotLog.blockID);
		world.setBlock(i + 6, j + 5, k + 6, Trees.japaneseApricotLog.blockID);
		world.setBlock(i + 6, j + 5, k + 7, Trees.japaneseApricotLog.blockID);
		world.setBlock(i + 6, j + 5, k + 8, Trees.japaneseApricotLeaves.blockID);
		world.setBlock(i + 6, j + 5, k + 9, Trees.japaneseApricotLeaves.blockID);
		world.setBlock(i + 6, j + 6, k + 0, Trees.japaneseApricotLeaves.blockID);
		world.setBlock(i + 6, j + 6, k + 1, Trees.japaneseApricotLeaves.blockID);
		world.setBlock(i + 6, j + 6, k + 3, Trees.japaneseApricotLeaves.blockID);
		world.setBlock(i + 6, j + 6, k + 4, Trees.japaneseApricotLeaves.blockID);
		world.setBlock(i + 6, j + 6, k + 6, Trees.japaneseApricotLog.blockID);
		world.setBlock(i + 6, j + 6, k + 7, Trees.japaneseApricotLeaves.blockID);
		world.setBlock(i + 6, j + 6, k + 8, Trees.japaneseApricotLeaves.blockID);
		world.setBlock(i + 6, j + 6, k + 9, Trees.japaneseApricotLeaves.blockID);
		world.setBlock(i + 6, j + 6, k + 10, Trees.japaneseApricotLeaves.blockID);
		world.setBlock(i + 6, j + 6, k + 12, Trees.japaneseApricotLeaves.blockID);
		world.setBlock(i + 7, j + 2, k + 8, Trees.japaneseApricotLeaves.blockID);
		world.setBlock(i + 7, j + 2, k + 9, Trees.japaneseApricotLeaves.blockID);
		world.setBlock(i + 7, j + 2, k + 12, Trees.japaneseApricotLeaves.blockID);
		world.setBlock(i + 7, j + 2, k + 13, Trees.japaneseApricotLeaves.blockID);
		world.setBlock(i + 7, j + 3, k + 5, Trees.japaneseApricotLeaves.blockID);
		world.setBlock(i + 7, j + 3, k + 6, Trees.japaneseApricotLeaves.blockID);
		world.setBlock(i + 7, j + 3, k + 7, Trees.japaneseApricotLeaves.blockID);
		world.setBlock(i + 7, j + 3, k + 10, Trees.japaneseApricotLeaves.blockID);
		world.setBlock(i + 7, j + 3, k + 12, Trees.japaneseApricotLeaves.blockID);
		world.setBlock(i + 7, j + 4, k + 6, Trees.japaneseApricotLog.blockID);
		world.setBlock(i + 7, j + 4, k + 8, Trees.japaneseApricotLeaves.blockID);
		world.setBlock(i + 7, j + 4, k + 11, Trees.japaneseApricotLeaves.blockID);
		world.setBlock(i + 7, j + 4, k + 12, Trees.japaneseApricotLeaves.blockID);
		world.setBlock(i + 7, j + 5, k + 3, Trees.japaneseApricotLeaves.blockID);
		world.setBlock(i + 7, j + 5, k + 4, Trees.japaneseApricotLeaves.blockID);
		world.setBlock(i + 7, j + 5, k + 5, Trees.japaneseApricotLeaves.blockID);
		world.setBlock(i + 7, j + 5, k + 6, Trees.japaneseApricotLog.blockID);
		world.setBlock(i + 7, j + 5, k + 7, Trees.japaneseApricotLog.blockID);
		world.setBlock(i + 7, j + 5, k + 11, Trees.japaneseApricotLeaves.blockID);
		world.setBlock(i + 7, j + 5, k + 12, Trees.japaneseApricotLeaves.blockID);
		world.setBlock(i + 7, j + 5, k + 13, Trees.japaneseApricotLeaves.blockID);
		world.setBlock(i + 7, j + 6, k + 0, Trees.japaneseApricotLeaves.blockID);
		world.setBlock(i + 7, j + 6, k + 1, Trees.japaneseApricotLeaves.blockID);
		world.setBlock(i + 7, j + 6, k + 2, Trees.japaneseApricotLeaves.blockID);
		world.setBlock(i + 7, j + 6, k + 4, Trees.japaneseApricotLeaves.blockID);
		world.setBlock(i + 7, j + 6, k + 5, Trees.japaneseApricotLeaves.blockID);
		world.setBlock(i + 7, j + 6, k + 6, Trees.japaneseApricotLeaves.blockID);
		world.setBlock(i + 7, j + 6, k + 7, Trees.japaneseApricotLeaves.blockID);
		world.setBlock(i + 7, j + 6, k + 10, Trees.japaneseApricotLeaves.blockID);
		world.setBlock(i + 7, j + 6, k + 11, Trees.japaneseApricotLeaves.blockID);
		world.setBlock(i + 8, j + 2, k + 4, Trees.japaneseApricotLeaves.blockID);
		world.setBlock(i + 8, j + 2, k + 6, Trees.japaneseApricotLeaves.blockID);
		world.setBlock(i + 8, j + 2, k + 9, Trees.japaneseApricotLeaves.blockID);
		world.setBlock(i + 8, j + 3, k + 6, Trees.japaneseApricotLeaves.blockID);
		world.setBlock(i + 8, j + 3, k + 12, Trees.japaneseApricotLeaves.blockID);
		world.setBlock(i + 8, j + 4, k + 2, Trees.japaneseApricotLeaves.blockID);
		world.setBlock(i + 8, j + 4, k + 3, Trees.japaneseApricotLeaves.blockID);
		world.setBlock(i + 8, j + 4, k + 7, Trees.japaneseApricotLog.blockID);
		world.setBlock(i + 8, j + 4, k + 8, Trees.japaneseApricotLeaves.blockID);
		world.setBlock(i + 8, j + 5, k + 1, Trees.japaneseApricotLeaves.blockID);
		world.setBlock(i + 8, j + 5, k + 2, Trees.japaneseApricotLeaves.blockID);
		world.setBlock(i + 8, j + 5, k + 4, Trees.japaneseApricotLeaves.blockID);
		world.setBlock(i + 8, j + 5, k + 5, Trees.japaneseApricotLeaves.blockID);
		world.setBlock(i + 8, j + 5, k + 7, Trees.japaneseApricotLog.blockID);
		world.setBlock(i + 8, j + 5, k + 9, Trees.japaneseApricotLeaves.blockID);
		world.setBlock(i + 8, j + 5, k + 13, Trees.japaneseApricotLeaves.blockID);
		world.setBlock(i + 8, j + 6, k + 8, Trees.japaneseApricotLeaves.blockID);
		world.setBlock(i + 8, j + 6, k + 10, Trees.japaneseApricotLeaves.blockID);
		world.setBlock(i + 8, j + 6, k + 11, Trees.japaneseApricotLeaves.blockID);
		world.setBlock(i + 9, j + 2, k + 4, Trees.japaneseApricotLeaves.blockID);
		world.setBlock(i + 9, j + 2, k + 8, Trees.japaneseApricotLeaves.blockID);
		world.setBlock(i + 9, j + 2, k + 9, Trees.japaneseApricotLeaves.blockID);
		world.setBlock(i + 9, j + 2, k + 12, Trees.japaneseApricotLeaves.blockID);
		world.setBlock(i + 9, j + 3, k + 8, Trees.japaneseApricotLeaves.blockID);
		world.setBlock(i + 9, j + 3, k + 11, Trees.japaneseApricotLeaves.blockID);
		world.setBlock(i + 9, j + 3, k + 13, Trees.japaneseApricotLeaves.blockID);
		world.setBlock(i + 9, j + 4, k + 4, Trees.japaneseApricotLeaves.blockID);
		world.setBlock(i + 9, j + 4, k + 6, Trees.japaneseApricotLeaves.blockID);
		world.setBlock(i + 9, j + 4, k + 8, Trees.japaneseApricotLog.blockID);
		world.setBlock(i + 9, j + 4, k + 10, Trees.japaneseApricotLeaves.blockID);
		world.setBlock(i + 9, j + 5, k + 1, Trees.japaneseApricotLeaves.blockID);
		world.setBlock(i + 9, j + 5, k + 5, Trees.japaneseApricotLeaves.blockID);
		world.setBlock(i + 9, j + 5, k + 7, Trees.japaneseApricotLeaves.blockID);
		world.setBlock(i + 9, j + 5, k + 11, Trees.japaneseApricotLeaves.blockID);
		world.setBlock(i + 9, j + 5, k + 13, Trees.japaneseApricotLeaves.blockID);
		world.setBlock(i + 9, j + 6, k + 2, Trees.japaneseApricotLeaves.blockID);
		world.setBlock(i + 9, j + 6, k + 4, Trees.japaneseApricotLeaves.blockID);
		world.setBlock(i + 9, j + 6, k + 5, Trees.japaneseApricotLeaves.blockID);
		world.setBlock(i + 9, j + 6, k + 10, Trees.japaneseApricotLeaves.blockID);
		world.setBlock(i + 10, j + 2, k + 4, Trees.japaneseApricotLeaves.blockID);
		world.setBlock(i + 10, j + 2, k + 7, Trees.japaneseApricotLeaves.blockID);
		world.setBlock(i + 10, j + 2, k + 10, Trees.japaneseApricotLeaves.blockID);
		world.setBlock(i + 10, j + 2, k + 11, Trees.japaneseApricotLeaves.blockID);
		world.setBlock(i + 10, j + 2, k + 12, Trees.japaneseApricotLeaves.blockID);
		world.setBlock(i + 10, j + 2, k + 13, Trees.japaneseApricotLeaves.blockID);
		world.setBlock(i + 10, j + 2, k + 15, Trees.japaneseApricotLeaves.blockID);
		world.setBlock(i + 10, j + 3, k + 4, Trees.japaneseApricotLeaves.blockID);
		world.setBlock(i + 10, j + 3, k + 5, Trees.japaneseApricotLeaves.blockID);
		world.setBlock(i + 10, j + 3, k + 7, Trees.japaneseApricotLeaves.blockID);
		world.setBlock(i + 10, j + 3, k + 8, Trees.japaneseApricotLog.blockID);
		world.setBlock(i + 10, j + 3, k + 10, Trees.japaneseApricotLeaves.blockID);
		world.setBlock(i + 10, j + 3, k + 14, Trees.japaneseApricotLeaves.blockID);
		world.setBlock(i + 10, j + 4, k + 2, Trees.japaneseApricotLeaves.blockID);
		world.setBlock(i + 10, j + 4, k + 7, Trees.japaneseApricotLeaves.blockID);
		world.setBlock(i + 10, j + 4, k + 8, Trees.japaneseApricotLog.blockID);
		world.setBlock(i + 10, j + 4, k + 9, Trees.japaneseApricotLeaves.blockID);
		world.setBlock(i + 10, j + 4, k + 10, Trees.japaneseApricotLeaves.blockID);
		world.setBlock(i + 10, j + 4, k + 12, Trees.japaneseApricotLeaves.blockID);
		world.setBlock(i + 10, j + 4, k + 13, Trees.japaneseApricotLeaves.blockID);
		world.setBlock(i + 10, j + 4, k + 14, Trees.japaneseApricotLeaves.blockID);
		world.setBlock(i + 10, j + 5, k + 7, Trees.japaneseApricotLeaves.blockID);
		world.setBlock(i + 10, j + 6, k + 4, Trees.japaneseApricotLeaves.blockID);
		world.setBlock(i + 10, j + 6, k + 7, Trees.japaneseApricotLeaves.blockID);
		world.setBlock(i + 10, j + 6, k + 8, Trees.japaneseApricotLeaves.blockID);
		world.setBlock(i + 10, j + 6, k + 9, Trees.japaneseApricotLeaves.blockID);
		world.setBlock(i + 10, j + 6, k + 10, Trees.japaneseApricotLeaves.blockID);
		world.setBlock(i + 11, j + 2, k + 4, Trees.japaneseApricotLeaves.blockID);
		world.setBlock(i + 11, j + 2, k + 11, Trees.japaneseApricotLeaves.blockID);
		world.setBlock(i + 11, j + 2, k + 13, Trees.japaneseApricotLeaves.blockID);
		world.setBlock(i + 11, j + 2, k + 14, Trees.japaneseApricotLeaves.blockID);
		world.setBlock(i + 11, j + 3, k + 2, Trees.japaneseApricotLeaves.blockID);
		world.setBlock(i + 11, j + 3, k + 3, Trees.japaneseApricotLeaves.blockID);
		world.setBlock(i + 11, j + 3, k + 4, Trees.japaneseApricotLeaves.blockID);
		world.setBlock(i + 11, j + 3, k + 5, Trees.japaneseApricotLeaves.blockID);
		world.setBlock(i + 11, j + 3, k + 7, Trees.japaneseApricotLeaves.blockID);
		world.setBlock(i + 11, j + 3, k + 8, Trees.japaneseApricotLog.blockID);
		world.setBlock(i + 11, j + 3, k + 9, Trees.japaneseApricotLog.blockID);
		world.setBlock(i + 11, j + 3, k + 10, Trees.japaneseApricotLeaves.blockID);
		world.setBlock(i + 11, j + 3, k + 11, Trees.japaneseApricotLeaves.blockID);
		world.setBlock(i + 11, j + 3, k + 13, Trees.japaneseApricotLeaves.blockID);
		world.setBlock(i + 11, j + 4, k + 4, Trees.japaneseApricotLeaves.blockID);
		world.setBlock(i + 11, j + 4, k + 8, Trees.japaneseApricotLeaves.blockID);
		world.setBlock(i + 11, j + 4, k + 9, Trees.japaneseApricotLeaves.blockID);
		world.setBlock(i + 11, j + 4, k + 12, Trees.japaneseApricotLeaves.blockID);
		world.setBlock(i + 11, j + 5, k + 8, Trees.japaneseApricotLeaves.blockID);
		world.setBlock(i + 11, j + 5, k + 12, Trees.japaneseApricotLeaves.blockID);
		world.setBlock(i + 11, j + 6, k + 6, Trees.japaneseApricotLeaves.blockID);
		world.setBlock(i + 11, j + 6, k + 7, Trees.japaneseApricotLeaves.blockID);
		world.setBlock(i + 12, j + 2, k + 3, Trees.japaneseApricotLeaves.blockID);
		world.setBlock(i + 12, j + 2, k + 4, Trees.japaneseApricotLeaves.blockID);
		world.setBlock(i + 12, j + 2, k + 7, Trees.japaneseApricotLeaves.blockID);
		world.setBlock(i + 12, j + 2, k + 8, Trees.japaneseApricotLeaves.blockID);
		world.setBlock(i + 12, j + 2, k + 9, Trees.japaneseApricotLog.blockID);
		world.setBlock(i + 12, j + 2, k + 10, Trees.japaneseApricotLeaves.blockID);
		world.setBlock(i + 12, j + 2, k + 11, Trees.japaneseApricotLeaves.blockID);
		world.setBlock(i + 12, j + 2, k + 15, Trees.japaneseApricotLeaves.blockID);
		world.setBlock(i + 12, j + 3, k + 2, Trees.japaneseApricotLeaves.blockID);
		world.setBlock(i + 12, j + 3, k + 6, Trees.japaneseApricotLeaves.blockID);
		world.setBlock(i + 12, j + 3, k + 9, Trees.japaneseApricotLeaves.blockID);
		world.setBlock(i + 12, j + 3, k + 12, Trees.japaneseApricotLeaves.blockID);
		world.setBlock(i + 12, j + 3, k + 13, Trees.japaneseApricotLeaves.blockID);
		world.setBlock(i + 12, j + 4, k + 3, Trees.japaneseApricotLeaves.blockID);
		world.setBlock(i + 12, j + 4, k + 4, Trees.japaneseApricotLeaves.blockID);
		world.setBlock(i + 12, j + 4, k + 8, Trees.japaneseApricotLeaves.blockID);
		world.setBlock(i + 12, j + 4, k + 11, Trees.japaneseApricotLeaves.blockID);
		world.setBlock(i + 12, j + 5, k + 7, Trees.japaneseApricotLeaves.blockID);
		world.setBlock(i + 12, j + 5, k + 12, Trees.japaneseApricotLeaves.blockID);
		world.setBlock(i + 12, j + 6, k + 4, Trees.japaneseApricotLeaves.blockID);
		world.setBlock(i + 12, j + 6, k + 7, Trees.japaneseApricotLeaves.blockID);
		world.setBlock(i + 13, j + 2, k + 3, Trees.japaneseApricotLeaves.blockID);
		world.setBlock(i + 13, j + 2, k + 7, Trees.japaneseApricotLeaves.blockID);
		world.setBlock(i + 13, j + 2, k + 9, Trees.japaneseApricotLeaves.blockID);
		world.setBlock(i + 13, j + 2, k + 11, Trees.japaneseApricotLeaves.blockID);
		world.setBlock(i + 13, j + 3, k + 3, Trees.japaneseApricotLeaves.blockID);
		world.setBlock(i + 13, j + 3, k + 4, Trees.japaneseApricotLeaves.blockID);
		world.setBlock(i + 13, j + 3, k + 7, Trees.japaneseApricotLeaves.blockID);
		world.setBlock(i + 13, j + 3, k + 8, Trees.japaneseApricotLeaves.blockID);
		world.setBlock(i + 13, j + 3, k + 10, Trees.japaneseApricotLeaves.blockID);
		world.setBlock(i + 13, j + 3, k + 12, Trees.japaneseApricotLeaves.blockID);
		world.setBlock(i + 13, j + 3, k + 14, Trees.japaneseApricotLeaves.blockID);
		world.setBlock(i + 13, j + 4, k + 6, Trees.japaneseApricotLeaves.blockID);
		world.setBlock(i + 13, j + 4, k + 8, Trees.japaneseApricotLeaves.blockID);
		world.setBlock(i + 13, j + 4, k + 11, Trees.japaneseApricotLeaves.blockID);
		world.setBlock(i + 13, j + 4, k + 12, Trees.japaneseApricotLeaves.blockID);
		world.setBlock(i + 13, j + 5, k + 3, Trees.japaneseApricotLeaves.blockID);
		world.setBlock(i + 13, j + 5, k + 5, Trees.japaneseApricotLeaves.blockID);
		world.setBlock(i + 13, j + 5, k + 7, Trees.japaneseApricotLeaves.blockID);
		world.setBlock(i + 13, j + 5, k + 8, Trees.japaneseApricotLeaves.blockID);
		world.setBlock(i + 14, j + 2, k + 3, Trees.japaneseApricotLeaves.blockID);
		world.setBlock(i + 14, j + 2, k + 8, Trees.japaneseApricotLeaves.blockID);
		world.setBlock(i + 14, j + 2, k + 9, Trees.japaneseApricotLeaves.blockID);
		world.setBlock(i + 14, j + 2, k + 13, Trees.japaneseApricotLeaves.blockID);
		world.setBlock(i + 14, j + 2, k + 15, Trees.japaneseApricotLeaves.blockID);
		world.setBlock(i + 14, j + 3, k + 7, Trees.japaneseApricotLeaves.blockID);
		world.setBlock(i + 14, j + 3, k + 8, Trees.japaneseApricotLeaves.blockID);
		world.setBlock(i + 14, j + 3, k + 11, Trees.japaneseApricotLeaves.blockID);
		world.setBlock(i + 14, j + 3, k + 12, Trees.japaneseApricotLeaves.blockID);
		world.setBlock(i + 14, j + 4, k + 3, Trees.japaneseApricotLeaves.blockID);
		world.setBlock(i + 14, j + 4, k + 5, Trees.japaneseApricotLeaves.blockID);
		world.setBlock(i + 14, j + 4, k + 8, Trees.japaneseApricotLeaves.blockID);
		world.setBlock(i + 14, j + 4, k + 10, Trees.japaneseApricotLeaves.blockID);
		world.setBlock(i + 14, j + 5, k + 5, Trees.japaneseApricotLeaves.blockID);
		world.setBlock(i + 15, j + 2, k + 9, Trees.japaneseApricotLeaves.blockID);
		world.setBlock(i + 15, j + 2, k + 12, Trees.japaneseApricotLeaves.blockID);
		world.setBlock(i + 15, j + 2, k + 13, Trees.japaneseApricotLeaves.blockID);
		world.setBlock(i + 15, j + 3, k + 3, Trees.japaneseApricotLeaves.blockID);
		world.setBlock(i + 15, j + 3, k + 4, Trees.japaneseApricotLeaves.blockID);
		world.setBlock(i + 15, j + 3, k + 8, Trees.japaneseApricotLeaves.blockID);
		world.setBlock(i + 15, j + 3, k + 10, Trees.japaneseApricotLeaves.blockID);
		world.setBlock(i + 15, j + 3, k + 12, Trees.japaneseApricotLeaves.blockID);
		world.setBlock(i + 15, j + 4, k + 6, Trees.japaneseApricotLeaves.blockID);
		world.setBlock(i + 15, j + 4, k + 8, Trees.japaneseApricotLeaves.blockID);
		world.setBlock(i + 15, j + 4, k + 9, Trees.japaneseApricotLeaves.blockID);
		world.setBlock(i + 16, j + 2, k + 6, Trees.japaneseApricotLeaves.blockID);
		world.setBlock(i + 16, j + 2, k + 8, Trees.japaneseApricotLeaves.blockID);
		world.setBlock(i + 16, j + 2, k + 13, Trees.japaneseApricotLeaves.blockID);
		world.setBlock(i + 16, j + 3, k + 4, Trees.japaneseApricotLeaves.blockID);
		world.setBlock(i + 16, j + 3, k + 5, Trees.japaneseApricotLeaves.blockID);
		world.setBlock(i + 16, j + 3, k + 6, Trees.japaneseApricotLeaves.blockID);
		world.setBlock(i + 16, j + 3, k + 12, Trees.japaneseApricotLeaves.blockID);
		world.setBlock(i + 16, j + 4, k + 6, Trees.japaneseApricotLeaves.blockID);
		world.setBlock(i + 16, j + 4, k + 7, Trees.japaneseApricotLeaves.blockID);
		world.setBlock(i + 16, j + 4, k + 8, Trees.japaneseApricotLeaves.blockID);
		world.setBlock(i + 16, j + 4, k + 10, Trees.japaneseApricotLeaves.blockID);
		world.setBlock(i + 17, j + 2, k + 6, Trees.japaneseApricotLeaves.blockID);
		world.setBlock(i + 17, j + 2, k + 8, Trees.japaneseApricotLeaves.blockID);
		world.setBlock(i + 17, j + 2, k + 9, Trees.japaneseApricotLeaves.blockID);
		world.setBlock(i + 17, j + 2, k + 10, Trees.japaneseApricotLeaves.blockID);
		world.setBlock(i + 17, j + 2, k + 11, Trees.japaneseApricotLeaves.blockID);
		world.setBlock(i + 17, j + 3, k + 7, Trees.japaneseApricotLeaves.blockID);
		world.setBlock(i + 17, j + 3, k + 8, Trees.japaneseApricotLeaves.blockID);
		world.setBlock(i + 18, j + 2, k + 9, Trees.japaneseApricotLeaves.blockID);
		world.setBlock(i + 18, j + 2, k + 10, Trees.japaneseApricotLeaves.blockID);
		world.setBlock(i + 18, j + 2, k + 11, Trees.japaneseApricotLeaves.blockID);

		return true;
	}
}